Workbook

Sheet Menu
A1: USINA PETRIBÚ — PLANEJAMENTO INTEGRADO DE MANUTENÇÃO · AgroVector v1.1
A2: Clique no módulo para navegar (⌂ MENU em cada aba retorna aqui). Status: DADO REAL = fonte cliente/histórico · ESTIMATIVA = validar (células amarelas) · PENDENTE = falta dado do cliente.
B4: ENTRADAS
B5: 📐 Premissas | C5: Índices por oficina (calibrados por 97.307 OS), disponibilidade MO, calendário, sazonalidade, gatilhos S/A/B/C e uso semanal por classe. | D5: REAL + ESTIMATIVA
B6: 🚛 Frota | C6: 384 ativos "Em Uso" no escopo garagem, com classe, setor e unidade de medição. | D6: DADO REAL
B7: 👷 Pessoas | C7: Equipe por oficina com custo mensal e custo/hora automáticos. | D7: PENDENTE (Evandro)
B8: ✅ Checklist | C8: HH incremental por classe × tipo, derivado dos gatilhos do cliente. | D8: REAL + ESTIMATIVA
B9: MOTOR / PROGRAMAÇÃO
B10: 📅 Cronograma por Classe | C10: Padrão de disparo S/A/B/C por classe × 52 semanas. | D10: CALCULADO
B11: 🗓 Cronograma por Ativo | C11: Grade completa: 384 ativos × 52 semanas, com filtro por classe. | D11: CALCULADO
B12: 📆 Agenda | C12: 2.101 preventivas em datas reais por ativo, com responsável automático. Veja também Mapa_Preventivas (classe × mês). Todos os 384 ativos têm agenda — pico dez–mar (1.026 eventos, igual ao app). | D12: CALCULADO
B13: RESULTADOS
B14: 📊 Plano de Preventivas | C14: HH preventiva por oficina × mês. | D14: CALCULADO
B15: 🔧 Plano de Corretivas | C15: HH corretiva esperada (mix real × deflator × sazonalidade calibrada). | D15: CALCULADO
B16: ⚖️ Disponibilidade | C16: Capacidade vs. demanda e saldo com semáforo. | D16: ZERADO até Pessoas
B17: 👥 Recursos | C17: Headcount necessário vs. atual (gap) por oficina × mês. | D17: ZERADO até Pessoas
B18: 🛢 Insumos & Peças | C18: Execuções/ano por classe × tipo — base para vincular os 5.171 itens. | D18: PENDENTE vínculo
B19: 💰 Saving | C19: Corretiva evitada (Δ HH) e R$ quando houver custo/hora. | D19: PARCIAL
B20: 📋 Resumo | C20: KPIs executivos: preventivas por tipo, HH por classe, custo MO, saving. | D20: CALCULADO
B21: APOIO
B22: 📈 Calibração OS | C22: Mix prev/corr por oficina e sazonalidade extraídos do histórico. | D22: DADO REAL
B23: ℹ️ Leia-me | C23: Instruções, modelagem por classe, o que validar e pendências. | D23: —

Sheet Leia-me
A1: PLANEJAMENTO DE MANUTENÇÃO — USINA PETRIBÚ v1.0 · VALIDAÇÃO DOS CONSULTORES | E1: ⌂ MENU
A3: 1 | B3: Objetivo | C3: Versão Petribú da planilha funcional (mesmo motor do app agrovector_manutencao_Petribu_v1.0). Consultores devem VALIDAR premissas, gatilhos, HH e uso semanal por classe — os resultados recalculam em tempo real.
A4: 2 | B4: O que já é dado real | C4: Frota: 384 ativos "Em Uso" no escopo garagem (aba Frota, fonte template_frota_Dados) · Sazonalidade e mix prev/corr por oficina: calibrados com 97.307 OS de ago/23 a mai/26 (aba Calibração_OS) · Gatilhos S/A/B/C: template preenchido pelo cliente · Safra: set–mar (calendário PE).
A5: 3 | B5: Modelagem por classe | C5: Como os horímetros atuais não foram informados (3 de 625) e o uso semanal é estimado por classe, o cronograma é calculado POR CLASSE e multiplicado pela quantidade de ativos — matematicamente idêntico ao cálculo ativo a ativo nessas condições. Quando os horímetros chegarem, migra-se para o modelo por ativo.
A6: 4 | B6: O que validar (células amarelas = estimativa) | C6: Uso semanal safra/entressafra por classe · HH incremental dos checklists (Carregadeira e Veículo Leve foram assumidos) · Deflator e % terceiros por oficina · Disponibilidade de MO · Distribuição das preventivas entre oficinas (hoje 100% em Central-Taisa).
A7: 5 | B7: Pendências que zeram resultados | C7: PESSOAS: não recebido — Disponibilidade, Recursos, custo/HH e Saving ficam zerados/vermelhos até preencher a aba Pessoas. Insumos: 5.171 itens sem vínculo com atividades — aba não incluída nesta versão.
A8: 6 | B8: Referência de conferência | C8: O app Petribú v1.0 com os mesmos dados calcula: 2.102 preventivas/ano · 7.988 HH preventiva/ano · 22.783 HH corretiva/ano. O Resumo desta planilha deve bater com esses números.
A9: 7 | B9: Cores Fabio | C9: VERDE OK · AMARELO atenção/estimativa · VERMELHO crítico (fonte branca). Cronograma: S verde · A amarelo · B/C vermelho.

Sheet Calibração_OS
A1: CALIBRAÇÃO PELO HISTÓRICO DE OS — 97.307 OS · ago/2023 a mai/2026 (template_OS_Dados.xlsx) | H1: ⌂ MENU
A3: MIX PREVENTIVA × CORRETIVA POR OFICINA (por contagem de OS)
A4: Oficina | B4: % Prev | C4: % Corr | D4: Nº OS
A5: Oficina Volante-Socorro | B5: 9 | C5: 91 | D5: 56813
A6: Oficina Mecânica Central-Taisa | B6: 28 | C6: 72 | D6: 26024
A7: Oficina Implementos Rodoviários | B7: 67 | C7: 33 | D7: 8682
A8: Oficina Mecânica Externa | B8: 5 | C8: 95 | D8: 3128
A9: Oficina Mecânica Central - Pátio Externo | B9: 37 | C9: 63 | D9: 1311
A10: PitStop | B10: 14 | C10: 86 | D10: 759
A12: SAZONALIDADE DE CORRETIVAS (fator normalizado, média = 1,0)
A13: Mês | B13: Jan | C13: Fev | D13: Mar | E13: Abr | F13: Mai | G13: Jun | H13: Jul | I13: Ago | J13: Set | K13: Out | L13: Nov | M13: Dez
A14: Fator | B14: 1.24 | C14: 1.2 | D14: 1.09 | E14: 0.69 | F14: 0.5 | G14: 0.36 | H14: 0.46 | I14: 1.06 | J14: 1.25 | K14: 1.42 | L14: 1.4 | M14: 1.33
A16: Leitura: setembro–março (safra) concentra corretivas (pico 1,42 em outubro); abril–julho é a janela de folga (vale 0,36 em junho) — ideal para preventivas pesadas e reformas. Campo hh_executadas está 0% preenchido nas OS: HH corretiva será calibrada por custo ÷ custo/HH quando Pessoas chegar.

Sheet Premissas
A1: PREMISSAS — USINA PETRIBÚ (índices calibrados pelo histórico; amarelo = estimativa a validar) | M1: ⌂ MENU
A3: ÍNDICES POR OFICINA
A4: Oficina | B4: % Preventiva | C4: % Corretiva | D4: Check % | E4: Deflator (% a.a.) | F4: % Terceiros
A5: Oficina Mecânica Central-Taisa | B5: 28 | C5: 72 | D5: =IF(B5+C5=100,"OK","≠100") -> OK | E5: 5 | F5: 10
A6: Oficina Volante-Socorro | B6: 9 | C6: 91 | D6: =IF(B6+C6=100,"OK","≠100") -> OK | E6: 8 | F6: 5
A7: Oficina Implementos Rodoviários | B7: 67 | C7: 33 | D7: =IF(B7+C7=100,"OK","≠100") -> OK | E7: 3 | F7: 10
A8: Oficina Mecânica Externa | B8: 5 | C8: 95 | D8: =IF(B8+C8=100,"OK","≠100") -> OK | E8: 8 | F8: 20
A9: Oficina Implementos Agrícolas | B9: 50 | C9: 50 | D9: =IF(B9+C9=100,"OK","≠100") -> OK | E9: 5 | F9: 10
A10: PitStop | B10: 14 | C10: 86 | D10: =IF(B10+C10=100,"OK","≠100") -> OK | E10: 5 | F10: 0
A12: DISPONIBILIDADE DE MÃO DE OBRA (default Vector — validar com turnos reais)
A13: Oficina | B13: H.Brutas/dia | C13: Almoço (h) | D13: Café (h) | E13: Abertura OS (h) | F13: Produtividade % | G13: Absenteísmo % | H13: Férias % | I13: Trein. (h/ano) | J13: H.Efetivas/dia | K13: H.Líquidas/dia
A14: Oficina Mecânica Central-Taisa | B14: 8.8 | C14: 1.2 | D14: 0.17 | E14: 0.25 | F14: 80 | G14: 5 | H14: 8.33 | I14: 16 | J14: =MAX(0,B14-C14-D14-E14) -> 7.18 | K14: =ROUND(J14*(1-MIN(G14/100+H14/100/12+I14/MAX(1,252*J14),0.99))*(F14/100),2) -> 5.37
A15: Oficina Volante-Socorro | B15: 8.8 | C15: 1.2 | D15: 0.17 | E15: 0.25 | F15: 80 | G15: 5 | H15: 8.33 | I15: 16 | J15: =MAX(0,B15-C15-D15-E15) -> 7.18 | K15: =ROUND(J15*(1-MIN(G15/100+H15/100/12+I15/MAX(1,252*J15),0.99))*(F15/100),2) -> 5.37
A16: Oficina Implementos Rodoviários | B16: 8.8 | C16: 1.2 | D16: 0.17 | E16: 0.25 | F16: 80 | G16: 5 | H16: 8.33 | I16: 16 | J16: =MAX(0,B16-C16-D16-E16) -> 7.18 | K16: =ROUND(J16*(1-MIN(G16/100+H16/100/12+I16/MAX(1,252*J16),0.99))*(F16/100),2) -> 5.37
A17: Oficina Mecânica Externa | B17: 8.8 | C17: 1.2 | D17: 0.17 | E17: 0.25 | F17: 80 | G17: 5 | H17: 8.33 | I17: 16 | J17: =MAX(0,B17-C17-D17-E17) -> 7.18 | K17: =ROUND(J17*(1-MIN(G17/100+H17/100/12+I17/MAX(1,252*J17),0.99))*(F17/100),2) -> 5.37
A18: Oficina Implementos Agrícolas | B18: 8.8 | C18: 1.2 | D18: 0.17 | E18: 0.25 | F18: 80 | G18: 5 | H18: 8.33 | I18: 16 | J18: =MAX(0,B18-C18-D18-E18) -> 7.18 | K18: =ROUND(J18*(1-MIN(G18/100+H18/100/12+I18/MAX(1,252*J18),0.99))*(F18/100),2) -> 5.37
A19: PitStop | B19: 8.8 | C19: 1.2 | D19: 0.17 | E19: 0.25 | F19: 80 | G19: 5 | H19: 8.33 | I19: 16 | J19: =MAX(0,B19-C19-D19-E19) -> 7.18 | K19: =ROUND(J19*(1-MIN(G19/100+H19/100/12+I19/MAX(1,252*J19),0.99))*(F19/100),2) -> 5.37
A21: CALENDÁRIO E SAZONALIDADE (sazonal = calibrada pelo histórico) | F21: Início da safra | G21: 2026-09-01
A22: Mês | B22: Dias úteis | C22: Fator sazonal corretivas | D22: Safra (informativo) | F22: Fim da safra | G22: 2027-03-31
A23: Jan | B23: 22 | C23: 1.24 | D23: Sim
A24: Fev | B24: 20 | C24: 1.2 | D24: Sim
A25: Mar | B25: 22 | C25: 1.09 | D25: Sim
A26: Abr | B26: 20 | C26: 0.69 | D26: Não
A27: Mai | B27: 20 | C27: 0.5 | D27: Não
A28: Jun | B28: 22 | C28: 0.36 | D28: Não
A29: Jul | B29: 21 | C29: 0.46 | D29: Não
A30: Ago | B30: 20 | C30: 1.06 | D30: Não
A31: Set | B31: 23 | C31: 1.25 | D31: Sim
A32: Out | B32: 22 | C32: 1.42 | D32: Sim
A33: Nov | B33: 21 | C33: 1.4 | D33: Sim
A34: Dez | B34: 23 | C34: 1.33 | D34: Sim
A35: TOTAL/MÉDIA | B35: =SUM(B23:B34) -> 256 | C35: =ROUND(AVERAGE(C23:C34),2) -> 1
A37: CLASSES — GATILHOS (do template do cliente) · USO SEMANAL ESTIMADO (amarelo = validar) · QTD DA FROTA
A38: Classe | B38: Unidade | C38: Int. S | D38: Int. A | E38: Int. B | F38: Int. C | G38: Uso sem. SAFRA | H38: Uso sem. ENTRESSAFRA | I38: Qtd ativos | J38: Uso inicial
A39: Colhedora | B39: Horas | C39: 150 | D39: 300 | E39: 600 | F39: 1200 | G39: 60 | H39: 5 | I39: =COUNTIF(Frota!$C$5:$C$388,$A39) -> 8 | J39: 0
A40: Trator | B40: Horas | C40: 250 | D40: 500 | E40: 1000 | F40: 2000 | G40: 40 | H40: 15 | I40: =COUNTIF(Frota!$C$5:$C$388,$A40) -> 102 | J40: 0
A41: Caminhão | B41: KM | C41: 10000 | D41: 20000 | E41: 40000 | F41: 80000 | G41: 1500 | H41: 400 | I41: =COUNTIF(Frota!$C$5:$C$388,$A41) -> 121 | J41: 0
A42: Carregadeira/Pesada | B42: Horas | C42: 250 | D42: 500 | E42: 1000 | F42: 2000 | G42: 45 | H42: 10 | I42: =COUNTIF(Frota!$C$5:$C$388,$A42) -> 73 | J42: 0
A43: Veículo Leve | B43: KM | C43: 10000 | D43: 20000 | E43: 40000 | G43: 700 | H43: 500 | I43: =COUNTIF(Frota!$C$5:$C$388,$A43) -> 50 | J43: 0
A44: Pulverizador | B44: Horas | C44: 100 | D44: 200 | G44: 20 | H44: 20 | I44: =COUNTIF(Frota!$C$5:$C$388,$A44) -> 12 | J44: 0
...

Sheet Frota
A1: FROTA PETRIBÚ — 384 ativos "Em Uso" no escopo garagem (fonte: template_frota_Dados.xlsx · 240 ativos fora do escopo: irrigação, motos, motores) | J1: ⌂ MENU
A4: id_ativo | B4: Descrição | C4: Classe (app) | D4: Classe Operacional | E4: Setor | F4: Unidade | G4: Ano | H4: Placa/Série
A5: 101005 | B5: MB 1725 Atego | C5: Caminhão | D5: Cam. Comboio Abs. | E5: Transporte | F5: km | G5: 2007 | H5: KKA-8897
A6: 101006 | B6: MB 710 4X2 | C6: Caminhão | D6: Cam. Oficina | E6: Transporte | F6: km | G6: 2001 | H6: KKM-6051
A7: 101011 | B7: MB 1720 6x6 | C7: Caminhão | D7: Cam. Oficina | E7: Transporte | F7: km | G7: 2002 | H7: KKU-6541
A8: 101014 | B8: MB 1113 4x2 | C8: Caminhão | D8: Carga Seca | E8: Transporte | F8: km | G8: 1977 | H8: KJE-0688
A9: 101016 | B9: MB 2423 6x4 | C9: Caminhão | D9: Cam. Oficina | E9: Transporte | F9: km | G9: 2005 | H9: KJM-0447
A10: 101028 | B10: MB 2423 6x4 | C10: Caminhão | D10: Cam. Oficina | E10: Transporte | F10: km | G10: 2007 | H10: KKN-9637
A11: 101047 | B11: VW 31-320 | C11: Caminhão | D11: Cam. Basculante | E11: Transporte | F11: km | G11: 2011 | H11: PFL-3208
A12: 101048 | B12: MB 3344 6x4 | C12: Caminhão | D12: Cam. Canavieiro | E12: Colheita | F12: km | G12: 2011 | H12: PFL-3638
A13: 101050 | B13: MB 2729 6x4 | C13: Caminhão | D13: Cam. Prancha | E13: Transporte | F13: km | G13: 2014 | H13: OYZ-1570
A14: 101051 | B14: MB 2729 6x4 | C14: Caminhão | D14: Cam. Pipa | E14: Transporte | F14: km | G14: 2014 | H14: OYZ-4380
A15: 101052 | B15: MB 2729 6x4 | C15: Caminhão | D15: Cam. Pipa | E15: Transporte | F15: km | G15: 2014 | H15: OYZ-4F10
A16: 101053 | B16: MB 2729 6x4 | C16: Caminhão | D16: Cam. Pipa | E16: Transporte | F16: km | G16: 2014 | H16: OYZ-4420
... A388: 580002 | B388: Chinesa | C388: Implemento | D388: Cortadeira Cana | E388: Agrícola | F388: h | G388: 2026 | H388: 0

Sheet Pessoas
A1: PESSOAS — PENDENTE: solicitar ao cliente (Evandro). Sem esta aba, Disponibilidade, Recursos e Saving ficam zerados. | K1: ⌂ MENU
A4: Nome | B4: Cargo | C4: Oficina | D4: Turno | E4: Salário | F4: Encargos % | G4: Status | H4: Custo Mensal (R$) | I4: Custo/Hora (R$)
H5: =IF($A5="","",ROUND(E5*(1+F5/100),2)) | I5: =IF($A5="","",ROUND(H5/MAX(1,(Premissas!$B$35/12)*VLOOKUP(C5,Premissas!$A$14:$K$19,11,0)),2))
H6: =IF($A6="","",ROUND(E6*(1+F6/100),2)) | I6: =IF($A6="","",ROUND(H6/MAX(1,(Premissas!$B$35/12)*VLOOKUP(C6,Premissas!$A$14:$K$19,11,0)),2))
H7: =IF($A7="","",ROUND(E7*(1+F7/100),2)) | I7: =IF($A7="","",ROUND(H7/MAX(1,(Premissas!$B$35/12)*VLOOKUP(C7,Premissas!$A$14:$K$19,11,0)),2))
H8: =IF($A8="","",ROUND(E8*(1+F8/100),2)) | I8: =IF($A8="","",ROUND(H8/MAX(1,(Premissas!$B$35/12)*VLOOKUP(C8,Premissas!$A$14:$K$19,11,0)),2))
H9: =IF($A9="","",ROUND(E9*(1+F9/100),2)) | I9: =IF($A9="","",ROUND(H9/MAX(1,(Premissas!$B$35/12)*VLOOKUP(C9,Premissas!$A$14:$K$19,11,0)),2))
H10: =IF($A10="","",ROUND(E10*(1+F10/100),2)) | I10: =IF($A10="","",ROUND(H10/MAX(1,(Premissas!$B$35/12)*VLOOKUP(C10,Premissas!$A$14:$K$19,11,0)),2))
H11: =IF($A11="","",ROUND(E11*(1+F11/100),2)) | I11: =IF($A11="","",ROUND(H11/MAX(1,(Premissas!$B$35/12)*VLOOKUP(C11,Premissas!$A$14:$K$19,11,0)),2))
H12: =IF($A12="","",ROUND(E12*(1+F12/100),2)) | I12: =IF($A12="","",ROUND(H12/MAX(1,(Premissas!$B$35/12)*VLOOKUP(C12,Premissas!$A$14:$K$19,11,0)),2))
H13: =IF($A13="","",ROUND(E13*(1+F13/100),2)) | I13: =IF($A13="","",ROUND(H13/MAX(1,(Premissas!$B$35/12)*VLOOKUP(C13,Premissas!$A$14:$K$19,11,0)),2))
H14: =IF($A14="","",ROUND(E14*(1+F14/100),2)) | I14: =IF($A14="","",ROUND(H14/MAX(1,(Premissas!$B$35/12)*VLOOKUP(C14,Premissas!$A$14:$K$19,11,0)),2))
H15: =IF($A15="","",ROUND(E15*(1+F15/100),2)) | I15: =IF($A15="","",ROUND(H15/MAX(1,(Premissas!$B$35/12)*VLOOKUP(C15,Premissas!$A$14:$K$19,11,0)),2))
H16: =IF($A16="","",ROUND(E16*(1+F16/100),2)) | I16: =IF($A16="","",ROUND(H16/MAX(1,(Premissas!$B$35/12)*VLOOKUP(C16,Premissas!$A$14:$K$19,11,0)),2))
... H44: =IF($A44="","",ROUND(E44*(1+F44/100),2)) | I44: =IF($A44="","",ROUND(H44/MAX(1,(Premissas!$B$35/12)*VLOOKUP(C44,Premissas!$A$14:$K$19,11,0)),2))

Sheet Checklist
A1: CHECKLIST — HH INCREMENTAL por classe × tipo (dos gatilhos do cliente; herança reconstrói o total). Amarelo = HH assumido, validar. | O1: ⌂ MENU
A4: Checklist | B4: Tipo Prev | C4: Classe | D4: Oficina | E4: Atividade | F4: Cargo | G4: Tipo Ativ | H4: HH | I4: Insumo | J4: Qtd | K4: Un | L4: Peça | M4: Qtd
A5: Rev. S — Trator | B5: S | C5: Trator | D5: Oficina Mecânica Central-Taisa | E5: Revisão S — itens incrementais (Trator) | F5: Mecânico | G5: Troca | H5: 2.5 | J5: 0 | M5: 0
A6: Rev. A — Trator | B6: A | C6: Trator | D6: Oficina Mecânica Central-Taisa | E6: Revisão A — itens incrementais (Trator) | F6: Mecânico | G6: Troca | H6: 2 | J6: 0 | M6: 0
A7: Rev. B — Trator | B7: B | C7: Trator | D7: Oficina Mecânica Central-Taisa | E7: Revisão B — itens incrementais (Trator) | F7: Mecânico | G7: Troca | H7: 3.5 | J7: 0 | M7: 0
A8: Rev. C — Trator | B8: C | C8: Trator | D8: Oficina Mecânica Central-Taisa | E8: Revisão C — itens incrementais (Trator) | F8: Mecânico | G8: Troca | H8: 8 | J8: 0 | M8: 0
A9: Rev. S — Colhedora | B9: S | C9: Colhedora | D9: Oficina Mecânica Central-Taisa | E9: Revisão S — itens incrementais (Colhedora) | F9: Mecânico | G9: Troca | H9: 3 | J9: 0 | M9: 0
A10: Rev. A — Colhedora | B10: A | C10: Colhedora | D10: Oficina Mecânica Central-Taisa | E10: Revisão A — itens incrementais (Colhedora) | F10: Mecânico | G10: Troca | H10: 3 | J10: 0 | M10: 0
A11: Rev. B — Colhedora | B11: B | C11: Colhedora | D11: Oficina Mecânica Central-Taisa | E11: Revisão B — itens incrementais (Colhedora) | F11: Mecânico | G11: Troca | H11: 6 | J11: 0 | M11: 0
A12: Rev. C — Colhedora | B12: C | C12: Colhedora | D12: Oficina Mecânica Central-Taisa | E12: Revisão C — itens incrementais (Colhedora) | F12: Mecânico | G12: Troca | H12: 12 | J12: 0 | M12: 0
A13: Rev. S — Caminhão | B13: S | C13: Caminhão | D13: Oficina Mecânica Central-Taisa | E13: Revisão S — itens incrementais (Caminhão) | F13: Mecânico | G13: Troca | H13: 2 | J13: 0 | M13: 0
A14: Rev. A — Caminhão | B14: A | C14: Caminhão | D14: Oficina Mecânica Central-Taisa | E14: Revisão A — itens incrementais (Caminhão) | F14: Mecânico | G14: Troca | H14: 2 | J14: 0 | M14: 0
A15: Rev. B — Caminhão | B15: B | C15: Caminhão | D15: Oficina Mecânica Central-Taisa | E15: Revisão B — itens incrementais (Caminhão) | F15: Mecânico | G15: Troca | H15: 4 | J15: 0 | M15: 0
A16: Rev. C — Caminhão | B16: C | C16: Caminhão | D16: Oficina Mecânica Central-Taisa | E16: Revisão C — itens incrementais (Caminhão) | F16: Mecânico | G16: Troca | H16: 8 | J16: 0 | M16: 0
... A27: Rev. A — Implemento | B27: A | C27: Implemento | D27: Oficina Mecânica Central-Taisa | E27: Revisão A — itens incrementais (Implemento) | F27: Mecânico | G27: Troca | H27: 1.5 | J27: 0 | M27: 0

Sheet Cronograma
A1: CRONOGRAMA — CLASSE × 52 semanas (todos os ativos da classe seguem este padrão; × Qtd no plano) | BD1: ⌂ MENU
A2: S verde · A amarelo · B/C vermelho (cores Fabio). Uso inicial = 0 até receber horímetros do cliente.
A4: Classe (× qtd ativos) | B4: S01 | C4: S02 | D4: S03 | E4: S04 | F4: S05 | G4: S06 | H4: S07 | I4: S08 | J4: S09 | K4: S10 | L4: S11 | M4: S12 | N4: S13 | O4: S14 | P4: S15 | Q4: S16 | R4: S17 | S4: S18 | T4: S19 | U4: S20 | V4: S21 | W4: S22 | X4: S23 | Y4: S24 | Z4: S25 | AA4: S26 | AB4: S27 | AC4: S28 | AD4: S29 | AE4: S30 | AF4: S31 | AG4: S32 | AH4: S33 | AI4: S34 | AJ4: S35 | AK4: S36 | AL4: S37 | AM4: S38 | AN4: S39 | AO4: S40 | AP4: S41 | AQ4: S42 | AR4: S43 | AS4: S44 | AT4: S45 | AU4: S46 | AV4: S47 | AW4: S48 | AX4: S49 | AY4: S50 | AZ4: S51 | BA4: S52
A5: =Premissas!$A$39&" (×"&Premissas!$I$39&")" -> Colhedora (×8) | B5: =IF(INT(Cron_Uso!B5/Premissas!$C$39)>INT(Premissas!$J$39/Premissas!$C$39),IF(N(Premissas!$F$39)>0,IF(MOD(INT(Cron_Uso!B5/Premissas!$C$39)*Premissas!$C$39,N(Premissas!$F$39))=0,"C",IF(N(Premissas!$E$39)>0,IF(MOD(INT(Cron_Uso!B5/Premissas!$C$39)*Premissas!$C$39,N(Premissas!$E$39))=0,"B",IF(N(Premissas!$D$39)>0,IF(MOD(INT(Cron_Uso!B5/Premissas!$C$39)*Premissas!$C$39,N(Premissas!$D$39))=0,"A","S"),"S")),IF(N(Premissas!$D$39)>0,IF(MOD(INT(Cron_Uso!B5/Premissas!$C$39)*Premissas!$C$39,N(Premissas!$D$39))=0,"A","S"),"S"))),IF(N(Premissas!$E$39)>0,IF(MOD(INT(Cron_Uso!B5/Premissas!$C$39)*Premissas!$C$39,N(Premissas!$E$39))=0,"B",IF(N(Premissas!$D$39)>0,IF(MOD(INT(Cron_Uso!B5/Premissas!$C$39)*Premissas!$C$39,N(Premissas!$D$39))=0,"A","S"),"S")),IF(N(Premissas!$D$39)>0,IF(MOD(INT(Cron_Uso!B5/Premissas!$C$39)*Premissas!$C$39,N(Premissas!$D$39))=0,"A","S"),"S"))),"") | C5: =IF(INT(Cron_Uso!C5/Premissas!$C$39)>INT(Cron_Uso!B5/Premissas!$C$39),IF(N(Premissas!$F$39)>0,IF(MOD(INT(Cron_Uso!C5/Premissas!$C$39)*Premissas!$C$39,N(Premissas!$F$39))=0,"C",IF(N(Premissas!$E$39)>0,IF(MOD(INT(Cron_Uso!C5/Premissas!$C$39)*Premissas!$C$39,N(Premissas!$E$39))=0,"B",IF(N(Premissas!$D$39)>0,IF(MOD(INT(Cron_Uso!C5/Premissas!$C$39)*Premissas!$C$39,N(Premissas!$D$39))=0,"A","S"),"S")),IF(N(Premissas!$D$39)>0,IF(MOD(INT(Cron_Uso!C5/Premissas!$C$39)*Premissas!$C$39,N(Premissas!$D$39))=0,"A","S"),"S"))),IF(N(Premissas!$E$39)>0,IF(MOD(INT(Cron_Uso!C5/Premissas!$C$39)*Premissas!$C$39,N(Premissas!$E$39))=0,"B",IF(N(Premissas!$D$39)>0,IF(MOD(INT(Cron_Uso!C5/Premissas!$C$39)*Premissas!$C$39,N(Premissas!$D$39))=0,"A","S"),"S")),IF(N(Premissas!$D$39)>0,IF(MOD(INT(Cron_Uso!C5/Premissas!$C$39)*Premissas!$C$39,N(Premissas!$D$39))=0,"A","S"),"S"))),"") | D5: =IF(INT(Cron_Uso!D5/Premissas!$C$39)>INT(Cron_Uso!C5/Premissas!$C$39),IF(N(Premissas!$F$39)>0,IF(MOD(INT(Cron_Uso!D5/Premissas!$C$39)*Premissas!$C$39,N(Premissas!$F$39))=0,"C",IF(N(Premissas!$E$39)>0,IF(MOD(INT(Cron_Uso!D5/Premissas!$C$39)*Premissas!$C$39,N(Premissas!$E$39))=0,"B",IF(N(Premissas!$D$39)>0,IF(MOD(INT(Cron_Uso!D5/Premissas!$C$39)*Premissas!$C$39,N(Premissas!$D$39))=0,"A","S"),"S")),IF(N(Premissas!$D$39)>0,IF(MOD(INT(Cron_Uso!D5/Premissas!$C$39)*Premissas!$C$39,N(Premissas!$D$39))=0,"A","S"),"S"))),IF(N(Premissas!$E$39)>0,IF(MOD(INT(Cron_Uso!D5/Premissas!$C$39)*Premissas!$C$39,N(Premissas!$E$39))=0,"B",IF(N(Premissas!$D$39)>0,IF(MOD(INT(Cron_Uso!D5/Premissas!$C$39)*Premissas!$C$39,N(Premissas!$D$39))=0,"A","S"),"S")),IF(N(Premissas!$D$39)>0,IF(MOD(INT(Cron_Uso!D5/Premissas!$C$39)*Premissas!$C$39,N(Premissas!$D$39))=0,"A","S"),"S"))),"") -> S | E5: =IF(INT(Cron_Uso!E5/Premissas!$C$39)>INT(Cron_Uso!D5/Premissas!$C$39),IF(N(Premissas!$F$39)>0,IF(MOD(INT(Cron_Uso!E5/Premissas!$C$39)*Premissas!$C$39,N(Premissas!$F$39))=0,"C",IF(N(Premissas!$E$39)>0,IF(MOD(INT(Cron_Uso!E5/Premissas!$C$39)*Premissas!$C$39,N(Premissas!$E$39))=0,"B",IF(N(Premissas!$D$39)>0,IF(MOD(INT(Cron_Uso!E5/Premissas!$C$39)*Premissas!$C$39,N(Premissas!$D$39))=0,"A","S"),"S")),IF(N(Premissas!$D$39)>0,IF(MOD(INT(Cron_Uso!E5/Premissas!$C$39)*Premissas!$C$39,N(Premissas!$D$39))=0,"A","S"),"S"))),IF(N(Premissas!$E$39)>0,IF(MOD(INT(Cron_Uso!E5/Premissas!$C$39)*Premissas!$C$39,N(Premissas!$E$39))=0,"B",IF(N(Premissas!$D$39)>0,IF(MOD(INT(Cron_Uso!E5/Premissas!$C$39)*Premissas!$C$39,N(Premissas!$D$39))=0,"A","S"),"S")),IF(N(Premissas!$D$39)>0,IF(MOD(INT(Cron_Uso!E5/Premissas!$C$39)*Premissas!$C$39,N(Premissas!$D$39))=0,"A","S"),"S"))),"") | F5: =IF(INT(Cron_Uso!F5/Premissas!$C$39)>INT(Cron_Uso!E5/Premissas!$C$39),IF(N(Premissas!$F$39)>0,IF(MOD(INT(Cron_Uso!F5/Premissas!$C$39)*Premissas!$C$39,N(Premissas!$F$39))=0,"C",IF(N(Premissas!$E$39)>0,IF(MOD(INT(Cron_Uso!F5/Premissas!$C$39)*Premissas!$C$39,N(Premissas!$E$39))=0,"B",IF(N(Premissas!$D$39)>0,IF(MOD(INT(Cron_Uso!F5/Premissas!$C$39)*Premissas!$C$39,N(Premissas!$D$39))=0,"A","S"),"S")),IF(N(Premissas!$D$39)>0,IF(MOD(INT(Cron_Uso!F5/Premissas!$C$39)*Premissas!$C$39,N(Premissas!$D$39))=0,"A","S"),"S"))),IF(N(Premissas!$E$39)>0,IF(MOD(INT(Cron_Uso!F5/Premissas!$C$39)*Premissas!$C$39,N(Premissas!$E$39))=0,"B",IF(N(Premissas!$D$39)>0,IF(MOD(INT(Cron_Uso!F5/Premissas!$C$39)*Premissas!$C$39,N(Premissas!$D$39))=0,"A","S"),"S")),IF(N(Premissas!$D$39)>0,IF(MOD(INT(Cron_Uso!F5/Premissas!$C$39)*Premissas!$C$39,N(Premissas!$D$39))=0,"A","S"),"S"))),"") -> A | G5: =IF(INT(Cron_Uso!G5/Premissas!$C$39)>INT(Cron_Uso!F5/Premissas!$C$39),IF(N(Premissas!$F$39)>0,IF(MOD(INT(Cron_Uso!G5/Premissas!$C$39)*Premissas!$C$39,N(Premissas!$F$39))=0,"C",IF(N(Premissas!$E$39)>0,IF(MOD(INT(Cron_Uso!G5/Premissas!$C$39)*Premissas!$C$39,N(Premissas!$E$39))=0,"B",IF(N(Premissas!$D$39)>0,IF(MOD(INT(Cron_Uso!G5/Premissas!$C$39)*Premissas!$C$39,N(Premissas!$D$39))=0,"A","S"),"S")),IF(N(Premissas!$D$39)>0,IF(MOD(INT(Cron_Uso!G5/Premissas!$C$39)*Premissas!$C$39,N(Premissas!$D$39))=0,"A","S"),"S"))),IF(N(Premissas!$E$39)>0,IF(MOD(INT(Cron_Uso!G5/Premissas!$C$39)*Premissas!$C$39,N(Premissas!$E$39))=0,"B",IF(N(Premissas!$D$39)>0,IF(MOD(INT(Cron_Uso!G5/Premissas!$C$39)*Premissas!$C$39,N(Premissas!$D$39))=0,"A","S"),"S")),IF(N(Premissas!$D$39)>0,IF(MOD(INT(Cron_Uso!G5/Premissas!$C$39)*Premissas!$C$39,N(Premissas!$D$39))=0,"A","S"),"S"))),"") | H5: =IF(INT(Cron_Uso!H5/Premissas!$C$39)>INT(Cron_Uso!G5/Premissas!$C$39),IF(N(Premissas!$F$39)>0,IF(MOD(INT(Cron_Uso!H5/Premissas!$C$39)*Premissas!$C$39,N(Premissas!$F$39))=0,"C",IF(N(Premissas!$E$39)>0,IF(MOD(INT(Cron_Uso!H5/Premissas!$C$39)*Premissas!$C$39,N(Premissas!$E$39))=0,"B",IF(N(Premissas!$D$39)>0,IF(MOD(INT(Cron_Uso!H5/Premissas!$C$39)*Premissas!$C$39,N(Premissas!$D$39))=0,"A","S"),"S")),IF(N(Premissas!$D$39)>0,IF(MOD(INT(Cron_Uso!H5/Premissas!$C$39)*Premissas!$C$39,N(Premissas!$D$39))=0,"A","S"),"S"))),IF(N(Premissas!$E$39)>0,IF(MOD(INT(Cron_Uso!H5/Premissas!$C$39)*Premissas!$C$39,N(Premissas!$E$39))=0,"B",IF(N(Premissas!$D$39)>0,IF(MOD(INT(Cron_Uso!H5/Premissas!$C$39)*Premissas!$C$39,N(Premissas!$D$39))=0,"A","S"),"S")),IF(N(Premissas!$D$39)>0,IF(MOD(INT(Cron_Uso!H5/Premissas!$C$39)*Premissas!$C$39,N(Premissas!$D$39))=0,"A","S"),"S"))),"") | I5: =IF(INT(Cron_Uso!I5/Premissas!$C$39)>INT(Cron_Uso!H5/Premissas!$C$39),IF(N(Premissas!$F$39)>0,IF(MOD(INT(Cron_Uso!I5/Premissas!$C$39)*Premissas!$C$39,N(Premissas!$F$39))=0,"C",IF(N(Premissas!$E$39)>0,IF(MOD(INT(Cron_Uso!I5/Premissas!$C$39)*Premissas!$C$39,N(Premissas!$E$39))=0,"B",IF(N(Premissas!$D$39)>0,IF(MOD(INT(Cron_Uso!I5/Premissas!$C$39)*Premissas!$C$39,N(Premissas!$D$39))=0,"A","S"),"S")),IF(N(Premissas!$D$39)>0,IF(MOD(INT(Cron_Uso!I5/Premissas!$C$39)*Premissas!$C$39,N(Premissas!$D$39))=0,"A","S"),"S"))),IF(N(Premissas!$E$39)>0,IF(MOD(INT(Cron_Uso!I5/Premissas!$C$39)*Premissas!$C$39,N(Premissas!$E$39))=0,"B",IF(N(Premissas!$D$39)>0,IF(MOD(INT(Cron_Uso!I5/Premissas!$C$39)*Premissas!$C$39,N(Premissas!$D$39))=0,"A","S"),"S")),IF(N(Premissas!$D$39)>0,IF(MOD(INT(Cron_Uso!I5/Premissas!$C$39)*Premissas!$C$39,N(Premissas!$D$39))=0,"A","S"),"S"))),"") -> S | J5: =IF(INT(Cron_Uso!J5/Premissas!$C$39)>INT(Cron_Uso!I5/Premissas!$C$39),IF(N(Premissas!$F$39)>0,IF(MOD(INT(Cron_Uso!J5/Premissas!$C$39)*Premissas!$C$39,N(Premissas!$F$39))=0,"C",IF(N(Premissas!$E$39)>0,IF(MOD(INT(Cron_Uso!J5/Premissas!$C$39)*Premissas!$C$39,N(Premissas!$E$39))=0,"B",IF(N(Premissas!$D$39)>0,IF(MOD(INT(Cron_Uso!J5/Premissas!$C$39)*Premissas!$C$39,N(Premissas!$D$39))=0,"A","S"),"S")),IF(N(Premissas!$D$39)>0,IF(MOD(INT(Cron_Uso!J5/Premissas!$C$39)*Premissas!$C$39,N(Premissas!$D$39))=0,"A","S"),"S"))),IF(N(Premissas!$E$39)>0,IF(MOD(INT(Cron_Uso!J5/Premissas!$C$39)*Premissas!$C$39,N(Premissas!$E$39))=0,"B",IF(N(Premissas!$D$39)>0,IF(MOD(INT(Cron_Uso!J5/Premissas!$C$39)*Premissas!$C$39,N(Premissas!$D$39))=0,"A","S"),"S")),IF(N(Premissas!$D$39)>0,IF(MOD(INT(Cron_Uso!J5/Premissas!$C$39)*Premissas!$C$39,N(Premissas!$D$39))=0,"A","S"),"S"))),"") | ... BA5: =IF(INT(Cron_Uso!BA5/Premissas!$C$39)>INT(Cron_Uso!AZ5/Premissas!$C$39),IF(N(Premissas!$F$39)>0,IF(MOD(INT(Cron_Uso!BA5/Premissas!$C$39)*Premissas!$C$39,N(Premissas!$F$39))=0,"C",IF(N(Premissas!$E$39)>0,IF(MOD(INT(Cron_Uso!BA5/Premissas!$C$39)*Premissas!$C$39,N(Premissas!$E$39))=0,"B",IF(N(Premissas!$D$39)>0,IF(MOD(INT(Cron_Uso!BA5/Premissas!$C$39)*Premissas!$C$39,N(Premissas!$D$39))=0,"A","S"),"S")),IF(N(Premissas!$D$39)>0,IF(MOD(INT(Cron_Uso!BA5/Premissas!$C$39)*Premissas!$C$39,N(Premissas!$D$39))=0,"A","S"),"S"))),IF(N(Premissas!$E$39)>0,IF(MOD(INT(Cron_Uso!BA5/Premissas!$C$39)*Premissas!$C$39,N(Premissas!$E$39))=0,"B",IF(N(Premissas!$D$39)>0,IF(MOD(INT(Cron_Uso!BA5/Premissas!$C$39)*Premissas!$C$39,N(Premissas!$D$39))=0,"A","S"),"S")),IF(N(Premissas!$D$39)>0,IF(MOD(INT(Cron_Uso!BA5/Premissas!$C$39)*Premissas!$C$39,N(Premissas!$D$39))=0,"A","S"),"S"))),"")
A6: =Premissas!$A$40&" (×"&Premissas!$I$40&")" -> Trator (×102) | B6: =IF(INT(Cron_Uso!B6/Premissas!$C$40)>INT(Premissas!$J$40/Premissas!$C$40),IF(N(Premissas!$F$40)>0,IF(MOD(INT(Cron_Uso!B6/Premissas!$C$40)*Premissas!$C$40,N(Premissas!$F$40))=0,"C",IF(N(Premissas!$E$40)>0,IF(MOD(INT(Cron_Uso!B6/Premissas!$C$40)*Premissas!$C$40,N(Premissas!$E$40))=0,"B",IF(N(Premissas!$D$40)>0,IF(MOD(INT(Cron_Uso!B6/Premissas!$C$40)*Premissas!$C$40,N(Premissas!$D$40))=0,"A","S"),"S")),IF(N(Premissas!$D$40)>0,IF(MOD(INT(Cron_Uso!B6/Premissas!$C$40)*Premissas!$C$40,N(Premissas!$D$40))=0,"A","S"),"S"))),IF(N(Premissas!$E$40)>0,IF(MOD(INT(Cron_Uso!B6/Premissas!$C$40)*Premissas!$C$40,N(Premissas!$E$40))=0,"B",IF(N(Premissas!$D$40)>0,IF(MOD(INT(Cron_Uso!B6/Premissas!$C$40)*Premissas!$C$40,N(Premissas!$D$40))=0,"A","S"),"S")),IF(N(Premissas!$D$40)>0,IF(MOD(INT(Cron_Uso!B6/Premissas!$C$40)*Premissas!$C$40,N(Premissas!$D$40))=0,"A","S"),"S"))),"") | C6: =IF(INT(Cron_Uso!C6/Premissas!$C$40)>INT(Cron_Uso!B6/Premissas!$C$40),IF(N(Premissas!$F$40)>0,IF(MOD(INT(Cron_Uso!C6/Premissas!$C$40)*Premissas!$C$40,N(Premissas!$F$40))=0,"C",IF(N(Premissas!$E$40)>0,IF(MOD(INT(Cron_Uso!C6/Premissas!$C$40)*Premissas!$C$40,N(Premissas!$E$40))=0,"B",IF(N(Premissas!$D$40)>0,IF(MOD(INT(Cron_Uso!C6/Premissas!$C$40)*Premissas!$C$40,N(Premissas!$D$40))=0,"A","S"),"S")),IF(N(Premissas!$D$40)>0,IF(MOD(INT(Cron_Uso!C6/Premissas!$C$40)*Premissas!$C$40,N(Premissas!$D$40))=0,"A","S"),"S"))),IF(N(Premissas!$E$40)>0,IF(MOD(INT(Cron_Uso!C6/Premissas!$C$40)*Premissas!$C$40,N(Premissas!$E$40))=0,"B",IF(N(Premissas!$D$40)>0,IF(MOD(INT(Cron_Uso!C6/Premissas!$C$40)*Premissas!$C$40,N(Premissas!$D$40))=0,"A","S"),"S")),IF(N(Premissas!$D$40)>0,IF(MOD(INT(Cron_Uso!C6/Premissas!$C$40)*Premissas!$C$40,N(Premissas!$D$40))=0,"A","S"),"S"))),"") | D6: =IF(INT(Cron_Uso!D6/Premissas!$C$40)>INT(Cron_Uso!C6/Premissas!$C$40),IF(N(Premissas!$F$40)>0,IF(MOD(INT(Cron_Uso!D6/Premissas!$C$40)*Premissas!$C$40,N(Premissas!$F$40))=0,"C",IF(N(Premissas!$E$40)>0,IF(MOD(INT(Cron_Uso!D6/Premissas!$C$40)*Premissas!$C$40,N(Premissas!$E$40))=0,"B",IF(N(Premissas!$D$40)>0,IF(MOD(INT(Cron_Uso!D6/Premissas!$C$40)*Premissas!$C$40,N(Premissas!$D$40))=0,"A","S"),"S")),IF(N(Premissas!$D$40)>0,IF(MOD(INT(Cron_Uso!D6/Premissas!$C$40)*Premissas!$C$40,N(Premissas!$D$40))=0,"A","S"),"S"))),IF(N(Premissas!$E$40)>0,IF(MOD(INT(Cron_Uso!D6/Premissas!$C$40)*Premissas!$C$40,N(Premissas!$E$40))=0,"B",IF(N(Premissas!$D$40)>0,IF(MOD(INT(Cron_Uso!D6/Premissas!$C$40)*Premissas!$C$40,N(Premissas!$D$40))=0,"A","S"),"S")),IF(N(Premissas!$D$40)>0,IF(MOD(INT(Cron_Uso!D6/Premissas!$C$40)*Premissas!$C$40,N(Premissas!$D$40))=0,"A","S"),"S"))),"") | E6: =IF(INT(Cron_Uso!E6/Premissas!$C$40)>INT(Cron_Uso!D6/Premissas!$C$40),IF(N(Premissas!$F$40)>0,IF(MOD(INT(Cron_Uso!E6/Premissas!$C$40)*Premissas!$C$40,N(Premissas!$F$40))=0,"C",IF(N(Premissas!$E$40)>0,IF(MOD(INT(Cron_Uso!E6/Premissas!$C$40)*Premissas!$C$40,N(Premissas!$E$40))=0,"B",IF(N(Premissas!$D$40)>0,IF(MOD(INT(Cron_Uso!E6/Premissas!$C$40)*Premissas!$C$40,N(Premissas!$D$40))=0,"A","S"),"S")),IF(N(Premissas!$D$40)>0,IF(MOD(INT(Cron_Uso!E6/Premissas!$C$40)*Premissas!$C$40,N(Premissas!$D$40))=0,"A","S"),"S"))),IF(N(Premissas!$E$40)>0,IF(MOD(INT(Cron_Uso!E6/Premissas!$C$40)*Premissas!$C$40,N(Premissas!$E$40))=0,"B",IF(N(Premissas!$D$40)>0,IF(MOD(INT(Cron_Uso!E6/Premissas!$C$40)*Premissas!$C$40,N(Premissas!$D$40))=0,"A","S"),"S")),IF(N(Premissas!$D$40)>0,IF(MOD(INT(Cron_Uso!E6/Premissas!$C$40)*Premissas!$C$40,N(Premissas!$D$40))=0,"A","S"),"S"))),"") | F6: =IF(INT(Cron_Uso!F6/Premissas!$C$40)>INT(Cron_Uso!E6/Premissas!$C$40),IF(N(Premissas!$F$40)>0,IF(MOD(INT(Cron_Uso!F6/Premissas!$C$40)*Premissas!$C$40,N(Premissas!$F$40))=0,"C",IF(N(Premissas!$E$40)>0,IF(MOD(INT(Cron_Uso!F6/Premissas!$C$40)*Premissas!$C$40,N(Premissas!$E$40))=0,"B",IF(N(Premissas!$D$40)>0,IF(MOD(INT(Cron_Uso!F6/Premissas!$C$40)*Premissas!$C$40,N(Premissas!$D$40))=0,"A","S"),"S")),IF(N(Premissas!$D$40)>0,IF(MOD(INT(Cron_Uso!F6/Premissas!$C$40)*Premissas!$C$40,N(Premissas!$D$40))=0,"A","S"),"S"))),IF(N(Premissas!$E$40)>0,IF(MOD(INT(Cron_Uso!F6/Premissas!$C$40)*Premissas!$C$40,N(Premissas!$E$40))=0,"B",IF(N(Premissas!$D$40)>0,IF(MOD(INT(Cron_Uso!F6/Premissas!$C$40)*Premissas!$C$40,N(Premissas!$D$40))=0,"A","S"),"S")),IF(N(Premissas!$D$40)>0,IF(MOD(INT(Cron_Uso!F6/Premissas!$C$40)*Premissas!$C$40,N(Premissas!$D$40))=0,"A","S"),"S"))),"") | G6: =IF(INT(Cron_Uso!G6/Premissas!$C$40)>INT(Cron_Uso!F6/Premissas!$C$40),IF(N(Premissas!$F$40)>0,IF(MOD(INT(Cron_Uso!G6/Premissas!$C$40)*Premissas!$C$40,N(Premissas!$F$40))=0,"C",IF(N(Premissas!$E$40)>0,IF(MOD(INT(Cron_Uso!G6/Premissas!$C$40)*Premissas!$C$40,N(Premissas!$E$40))=0,"B",IF(N(Premissas!$D$40)>0,IF(MOD(INT(Cron_Uso!G6/Premissas!$C$40)*Premissas!$C$40,N(Premissas!$D$40))=0,"A","S"),"S")),IF(N(Premissas!$D$40)>0,IF(MOD(INT(Cron_Uso!G6/Premissas!$C$40)*Premissas!$C$40,N(Premissas!$D$40))=0,"A","S"),"S"))),IF(N(Premissas!$E$40)>0,IF(MOD(INT(Cron_Uso!G6/Premissas!$C$40)*Premissas!$C$40,N(Premissas!$E$40))=0,"B",IF(N(Premissas!$D$40)>0,IF(MOD(INT(Cron_Uso!G6/Premissas!$C$40)*Premissas!$C$40,N(Premissas!$D$40))=0,"A","S"),"S")),IF(N(Premissas!$D$40)>0,IF(MOD(INT(Cron_Uso!G6/Premissas!$C$40)*Premissas!$C$40,N(Premissas!$D$40))=0,"A","S"),"S"))),"") | H6: =IF(INT(Cron_Uso!H6/Premissas!$C$40)>INT(Cron_Uso!G6/Premissas!$C$40),IF(N(Premissas!$F$40)>0,IF(MOD(INT(Cron_Uso!H6/Premissas!$C$40)*Premissas!$C$40,N(Premissas!$F$40))=0,"C",IF(N(Premissas!$E$40)>0,IF(MOD(INT(Cron_Uso!H6/Premissas!$C$40)*Premissas!$C$40,N(Premissas!$E$40))=0,"B",IF(N(Premissas!$D$40)>0,IF(MOD(INT(Cron_Uso!H6/Premissas!$C$40)*Premissas!$C$40,N(Premissas!$D$40))=0,"A","S"),"S")),IF(N(Premissas!$D$40)>0,IF(MOD(INT(Cron_Uso!H6/Premissas!$C$40)*Premissas!$C$40,N(Premissas!$D$40))=0,"A","S"),"S"))),IF(N(Premissas!$E$40)>0,IF(MOD(INT(Cron_Uso!H6/Premissas!$C$40)*Premissas!$C$40,N(Premissas!$E$40))=0,"B",IF(N(Premissas!$D$40)>0,IF(MOD(INT(Cron_Uso!H6/Premissas!$C$40)*Premissas!$C$40,N(Premissas!$D$40))=0,"A","S"),"S")),IF(N(Premissas!$D$40)>0,IF(MOD(INT(Cron_Uso!H6/Premissas!$C$40)*Premissas!$C$40,N(Premissas!$D$40))=0,"A","S"),"S"))),"") -> S | I6: =IF(INT(Cron_Uso!I6/Premissas!$C$40)>INT(Cron_Uso!H6/Premissas!$C$40),IF(N(Premissas!$F$40)>0,IF(MOD(INT(Cron_Uso!I6/Premissas!$C$40)*Premissas!$C$40,N(Premissas!$F$40))=0,"C",IF(N(Premissas!$E$40)>0,IF(MOD(INT(Cron_Uso!I6/Premissas!$C$40)*Premissas!$C$40,N(Premissas!$E$40))=0,"B",IF(N(Premissas!$D$40)>0,IF(MOD(INT(Cron_Uso!I6/Premissas!$C$40)*Premissas!$C$40,N(Premissas!$D$40))=0,"A","S"),"S")),IF(N(Premissas!$D$40)>0,IF(MOD(INT(Cron_Uso!I6/Premissas!$C$40)*Premissas!$C$40,N(Premissas!$D$40))=0,"A","S"),"S"))),IF(N(Premissas!$E$40)>0,IF(MOD(INT(Cron_Uso!I6/Premissas!$C$40)*Premissas!$C$40,N(Premissas!$E$40))=0,"B",IF(N(Premissas!$D$40)>0,IF(MOD(INT(Cron_Uso!I6/Premissas!$C$40)*Premissas!$C$40,N(Premissas!$D$40))=0,"A","S"),"S")),IF(N(Premissas!$D$40)>0,IF(MOD(INT(Cron_Uso!I6/Premissas!$C$40)*Premissas!$C$40,N(Premissas!$D$40))=0,"A","S"),"S"))),"") | J6: =IF(INT(Cron_Uso!J6/Premissas!$C$40)>INT(Cron_Uso!I6/Premissas!$C$40),IF(N(Premissas!$F$40)>0,IF(MOD(INT(Cron_Uso!J6/Premissas!$C$40)*Premissas!$C$40,N(Premissas!$F$40))=0,"C",IF(N(Premissas!$E$40)>0,IF(MOD(INT(Cron_Uso!J6/Premissas!$C$40)*Premissas!$C$40,N(Premissas!$E$40))=0,"B",IF(N(Premissas!$D$40)>0,IF(MOD(INT(Cron_Uso!J6/Premissas!$C$40)*Premissas!$C$40,N(Premissas!$D$40))=0,"A","S"),"S")),IF(N(Premissas!$D$40)>0,IF(MOD(INT(Cron_Uso!J6/Premissas!$C$40)*Premissas!$C$40,N(Premissas!$D$40))=0,"A","S"),"S"))),IF(N(Premissas!$E$40)>0,IF(MOD(INT(Cron_Uso!J6/Premissas!$C$40)*Premissas!$C$40,N(Premissas!$E$40))=0,"B",IF(N(Premissas!$D$40)>0,IF(MOD(INT(Cron_Uso!J6/Premissas!$C$40)*Premissas!$C$40,N(Premissas!$D$40))=0,"A","S"),"S")),IF(N(Premissas!$D$40)>0,IF(MOD(INT(Cron_Uso!J6/Premissas!$C$40)*Premissas!$C$40,N(Premissas!$D$40))=0,"A","S"),"S"))),"") | ... BA6: =IF(INT(Cron_Uso!BA6/Premissas!$C$40)>INT(Cron_Uso!AZ6/Premissas!$C$40),IF(N(Premissas!$F$40)>0,IF(MOD(INT(Cron_Uso!BA6/Premissas!$C$40)*Premissas!$C$40,N(Premissas!$F$40))=0,"C",IF(N(Premissas!$E$40)>0,IF(MOD(INT(Cron_Uso!BA6/Premissas!$C$40)*Premissas!$C$40,N(Premissas!$E$40))=0,"B",IF(N(Premissas!$D$40)>0,IF(MOD(INT(Cron_Uso!BA6/Premissas!$C$40)*Premissas!$C$40,N(Premissas!$D$40))=0,"A","S"),"S")),IF(N(Premissas!$D$40)>0,IF(MOD(INT(Cron_Uso!BA6/Premissas!$C$40)*Premissas!$C$40,N(Premissas!$D$40))=0,"A","S"),"S"))),IF(N(Premissas!$E$40)>0,IF(MOD(INT(Cron_Uso!BA6/Premissas!$C$40)*Premissas!$C$40,N(Premissas!$E$40))=0,"B",IF(N(Premissas!$D$40)>0,IF(MOD(INT(Cron_Uso!BA6/Premissas!$C$40)*Premissas!$C$40,N(Premissas!$D$40))=0,"A","S"),"S")),IF(N(Premissas!$D$40)>0,IF(MOD(INT(Cron_Uso!BA6/Premissas!$C$40)*Premissas!$C$40,N(Premissas!$D$40))=0,"A","S"),"S"))),"")
A7: =Premissas!$A$41&" (×"&Premissas!$I$41&")" -> Caminhão (×121) | B7: =IF(INT(Cron_Uso!B7/Premissas!$C$41)>INT(Premissas!$J$41/Premissas!$C$41),IF(N(Premissas!$F$41)>0,IF(MOD(INT(Cron_Uso!B7/Premissas!$C$41)*Premissas!$C$41,N(Premissas!$F$41))=0,"C",IF(N(Premissas!$E$41)>0,IF(MOD(INT(Cron_Uso!B7/Premissas!$C$41)*Premissas!$C$41,N(Premissas!$E$41))=0,"B",IF(N(Premissas!$D$41)>0,IF(MOD(INT(Cron_Uso!B7/Premissas!$C$41)*Premissas!$C$41,N(Premissas!$D$41))=0,"A","S"),"S")),IF(N(Premissas!$D$41)>0,IF(MOD(INT(Cron_Uso!B7/Premissas!$C$41)*Premissas!$C$41,N(Premissas!$D$41))=0,"A","S"),"S"))),IF(N(Premissas!$E$41)>0,IF(MOD(INT(Cron_Uso!B7/Premissas!$C$41)*Premissas!$C$41,N(Premissas!$E$41))=0,"B",IF(N(Premissas!$D$41)>0,IF(MOD(INT(Cron_Uso!B7/Premissas!$C$41)*Premissas!$C$41,N(Premissas!$D$41))=0,"A","S"),"S")),IF(N(Premissas!$D$41)>0,IF(MOD(INT(Cron_Uso!B7/Premissas!$C$41)*Premissas!$C$41,N(Premissas!$D$41))=0,"A","S"),"S"))),"") | C7: =IF(INT(Cron_Uso!C7/Premissas!$C$41)>INT(Cron_Uso!B7/Premissas!$C$41),IF(N(Premissas!$F$41)>0,IF(MOD(INT(Cron_Uso!C7/Premissas!$C$41)*Premissas!$C$41,N(Premissas!$F$41))=0,"C",IF(N(Premissas!$E$41)>0,IF(MOD(INT(Cron_Uso!C7/Premissas!$C$41)*Premissas!$C$41,N(Premissas!$E$41))=0,"B",IF(N(Premissas!$D$41)>0,IF(MOD(INT(Cron_Uso!C7/Premissas!$C$41)*Premissas!$C$41,N(Premissas!$D$41))=0,"A","S"),"S")),IF(N(Premissas!$D$41)>0,IF(MOD(INT(Cron_Uso!C7/Premissas!$C$41)*Premissas!$C$41,N(Premissas!$D$41))=0,"A","S"),"S"))),IF(N(Premissas!$E$41)>0,IF(MOD(INT(Cron_Uso!C7/Premissas!$C$41)*Premissas!$C$41,N(Premissas!$E$41))=0,"B",IF(N(Premissas!$D$41)>0,IF(MOD(INT(Cron_Uso!C7/Premissas!$C$41)*Premissas!$C$41,N(Premissas!$D$41))=0,"A","S"),"S")),IF(N(Premissas!$D$41)>0,IF(MOD(INT(Cron_Uso!C7/Premissas!$C$41)*Premissas!$C$41,N(Premissas!$D$41))=0,"A","S"),"S"))),"") | D7: =IF(INT(Cron_Uso!D7/Premissas!$C$41)>INT(Cron_Uso!C7/Premissas!$C$41),IF(N(Premissas!$F$41)>0,IF(MOD(INT(Cron_Uso!D7/Premissas!$C$41)*Premissas!$C$41,N(Premissas!$F$41))=0,"C",IF(N(Premissas!$E$41)>0,IF(MOD(INT(Cron_Uso!D7/Premissas!$C$41)*Premissas!$C$41,N(Premissas!$E$41))=0,"B",IF(N(Premissas!$D$41)>0,IF(MOD(INT(Cron_Uso!D7/Premissas!$C$41)*Premissas!$C$41,N(Premissas!$D$41))=0,"A","S"),"S")),IF(N(Premissas!$D$41)>0,IF(MOD(INT(Cron_Uso!D7/Premissas!$C$41)*Premissas!$C$41,N(Premissas!$D$41))=0,"A","S"),"S"))),IF(N(Premissas!$E$41)>0,IF(MOD(INT(Cron_Uso!D7/Premissas!$C$41)*Premissas!$C$41,N(Premissas!$E$41))=0,"B",IF(N(Premissas!$D$41)>0,IF(MOD(INT(Cron_Uso!D7/Premissas!$C$41)*Premissas!$C$41,N(Premissas!$D$41))=0,"A","S"),"S")),IF(N(Premissas!$D$41)>0,IF(MOD(INT(Cron_Uso!D7/Premissas!$C$41)*Premissas!$C$41,N(Premissas!$D$41))=0,"A","S"),"S"))),"") | E7: =IF(INT(Cron_Uso!E7/Premissas!$C$41)>INT(Cron_Uso!D7/Premissas!$C$41),IF(N(Premissas!$F$41)>0,IF(MOD(INT(Cron_Uso!E7/Premissas!$C$41)*Premissas!$C$41,N(Premissas!$F$41))=0,"C",IF(N(Premissas!$E$41)>0,IF(MOD(INT(Cron_Uso!E7/Premissas!$C$41)*Premissas!$C$41,N(Premissas!$E$41))=0,"B",IF(N(Premissas!$D$41)>0,IF(MOD(INT(Cron_Uso!E7/Premissas!$C$41)*Premissas!$C$41,N(Premissas!$D$41))=0,"A","S"),"S")),IF(N(Premissas!$D$41)>0,IF(MOD(INT(Cron_Uso!E7/Premissas!$C$41)*Premissas!$C$41,N(Premissas!$D$41))=0,"A","S"),"S"))),IF(N(Premissas!$E$41)>0,IF(MOD(INT(Cron_Uso!E7/Premissas!$C$41)*Premissas!$C$41,N(Premissas!$E$41))=0,"B",IF(N(Premissas!$D$41)>0,IF(MOD(INT(Cron_Uso!E7/Premissas!$C$41)*Premissas!$C$41,N(Premissas!$D$41))=0,"A","S"),"S")),IF(N(Premissas!$D$41)>0,IF(MOD(INT(Cron_Uso!E7/Premissas!$C$41)*Premissas!$C$41,N(Premissas!$D$41))=0,"A","S"),"S"))),"") | F7: =IF(INT(Cron_Uso!F7/Premissas!$C$41)>INT(Cron_Uso!E7/Premissas!$C$41),IF(N(Premissas!$F$41)>0,IF(MOD(INT(Cron_Uso!F7/Premissas!$C$41)*Premissas!$C$41,N(Premissas!$F$41))=0,"C",IF(N(Premissas!$E$41)>0,IF(MOD(INT(Cron_Uso!F7/Premissas!$C$41)*Premissas!$C$41,N(Premissas!$E$41))=0,"B",IF(N(Premissas!$D$41)>0,IF(MOD(INT(Cron_Uso!F7/Premissas!$C$41)*Premissas!$C$41,N(Premissas!$D$41))=0,"A","S"),"S")),IF(N(Premissas!$D$41)>0,IF(MOD(INT(Cron_Uso!F7/Premissas!$C$41)*Premissas!$C$41,N(Premissas!$D$41))=0,"A","S"),"S"))),IF(N(Premissas!$E$41)>0,IF(MOD(INT(Cron_Uso!F7/Premissas!$C$41)*Premissas!$C$41,N(Premissas!$E$41))=0,"B",IF(N(Premissas!$D$41)>0,IF(MOD(INT(Cron_Uso!F7/Premissas!$C$41)*Premissas!$C$41,N(Premissas!$D$41))=0,"A","S"),"S")),IF(N(Premissas!$D$41)>0,IF(MOD(INT(Cron_Uso!F7/Premissas!$C$41)*Premissas!$C$41,N(Premissas!$D$41))=0,"A","S"),"S"))),"") | G7: =IF(INT(Cron_Uso!G7/Premissas!$C$41)>INT(Cron_Uso!F7/Premissas!$C$41),IF(N(Premissas!$F$41)>0,IF(MOD(INT(Cron_Uso!G7/Premissas!$C$41)*Premissas!$C$41,N(Premissas!$F$41))=0,"C",IF(N(Premissas!$E$41)>0,IF(MOD(INT(Cron_Uso!G7/Premissas!$C$41)*Premissas!$C$41,N(Premissas!$E$41))=0,"B",IF(N(Premissas!$D$41)>0,IF(MOD(INT(Cron_Uso!G7/Premissas!$C$41)*Premissas!$C$41,N(Premissas!$D$41))=0,"A","S"),"S")),IF(N(Premissas!$D$41)>0,IF(MOD(INT(Cron_Uso!G7/Premissas!$C$41)*Premissas!$C$41,N(Premissas!$D$41))=0,"A","S"),"S"))),IF(N(Premissas!$E$41)>0,IF(MOD(INT(Cron_Uso!G7/Premissas!$C$41)*Premissas!$C$41,N(Premissas!$E$41))=0,"B",IF(N(Premissas!$D$41)>0,IF(MOD(INT(Cron_Uso!G7/Premissas!$C$41)*Premissas!$C$41,N(Premissas!$D$41))=0,"A","S"),"S")),IF(N(Premissas!$D$41)>0,IF(MOD(INT(Cron_Uso!G7/Premissas!$C$41)*Premissas!$C$41,N(Premissas!$D$41))=0,"A","S"),"S"))),"") | H7: =IF(INT(Cron_Uso!H7/Premissas!$C$41)>INT(Cron_Uso!G7/Premissas!$C$41),IF(N(Premissas!$F$41)>0,IF(MOD(INT(Cron_Uso!H7/Premissas!$C$41)*Premissas!$C$41,N(Premissas!$F$41))=0,"C",IF(N(Premissas!$E$41)>0,IF(MOD(INT(Cron_Uso!H7/Premissas!$C$41)*Premissas!$C$41,N(Premissas!$E$41))=0,"B",IF(N(Premissas!$D$41)>0,IF(MOD(INT(Cron_Uso!H7/Premissas!$C$41)*Premissas!$C$41,N(Premissas!$D$41))=0,"A","S"),"S")),IF(N(Premissas!$D$41)>0,IF(MOD(INT(Cron_Uso!H7/Premissas!$C$41)*Premissas!$C$41,N(Premissas!$D$41))=0,"A","S"),"S"))),IF(N(Premissas!$E$41)>0,IF(MOD(INT(Cron_Uso!H7/Premissas!$C$41)*Premissas!$C$41,N(Premissas!$E$41))=0,"B",IF(N(Premissas!$D$41)>0,IF(MOD(INT(Cron_Uso!H7/Premissas!$C$41)*Premissas!$C$41,N(Premissas!$D$41))=0,"A","S"),"S")),IF(N(Premissas!$D$41)>0,IF(MOD(INT(Cron_Uso!H7/Premissas!$C$41)*Premissas!$C$41,N(Premissas!$D$41))=0,"A","S"),"S"))),"") -> S | I7: =IF(INT(Cron_Uso!I7/Premissas!$C$41)>INT(Cron_Uso!H7/Premissas!$C$41),IF(N(Premissas!$F$41)>0,IF(MOD(INT(Cron_Uso!I7/Premissas!$C$41)*Premissas!$C$41,N(Premissas!$F$41))=0,"C",IF(N(Premissas!$E$41)>0,IF(MOD(INT(Cron_Uso!I7/Premissas!$C$41)*Premissas!$C$41,N(Premissas!$E$41))=0,"B",IF(N(Premissas!$D$41)>0,IF(MOD(INT(Cron_Uso!I7/Premissas!$C$41)*Premissas!$C$41,N(Premissas!$D$41))=0,"A","S"),"S")),IF(N(Premissas!$D$41)>0,IF(MOD(INT(Cron_Uso!I7/Premissas!$C$41)*Premissas!$C$41,N(Premissas!$D$41))=0,"A","S"),"S"))),IF(N(Premissas!$E$41)>0,IF(MOD(INT(Cron_Uso!I7/Premissas!$C$41)*Premissas!$C$41,N(Premissas!$E$41))=0,"B",IF(N(Premissas!$D$41)>0,IF(MOD(INT(Cron_Uso!I7/Premissas!$C$41)*Premissas!$C$41,N(Premissas!$D$41))=0,"A","S"),"S")),IF(N(Premissas!$D$41)>0,IF(MOD(INT(Cron_Uso!I7/Premissas!$C$41)*Premissas!$C$41,N(Premissas!$D$41))=0,"A","S"),"S"))),"") | J7: =IF(INT(Cron_Uso!J7/Premissas!$C$41)>INT(Cron_Uso!I7/Premissas!$C$41),IF(N(Premissas!$F$41)>0,IF(MOD(INT(Cron_Uso!J7/Premissas!$C$41)*Premissas!$C$41,N(Premissas!$F$41))=0,"C",IF(N(Premissas!$E$41)>0,IF(MOD(INT(Cron_Uso!J7/Premissas!$C$41)*Premissas!$C$41,N(Premissas!$E$41))=0,"B",IF(N(Premissas!$D$41)>0,IF(MOD(INT(Cron_Uso!J7/Premissas!$C$41)*Premissas!$C$41,N(Premissas!$D$41))=0,"A","S"),"S")),IF(N(Premissas!$D$41)>0,IF(MOD(INT(Cron_Uso!J7/Premissas!$C$41)*Premissas!$C$41,N(Premissas!$D$41))=0,"A","S"),"S"))),IF(N(Premissas!$E$41)>0,IF(MOD(INT(Cron_Uso!J7/Premissas!$C$41)*Premissas!$C$41,N(Premissas!$E$41))=0,"B",IF(N(Premissas!$D$41)>0,IF(MOD(INT(Cron_Uso!J7/Premissas!$C$41)*Premissas!$C$41,N(Premissas!$D$41))=0,"A","S"),"S")),IF(N(Premissas!$D$41)>0,IF(MOD(INT(Cron_Uso!J7/Premissas!$C$41)*Premissas!$C$41,N(Premissas!$D$41))=0,"A","S"),"S"))),"") | ... BA7: =IF(INT(Cron_Uso!BA7/Premissas!$C$41)>INT(Cron_Uso!AZ7/Premissas!$C$41),IF(N(Premissas!$F$41)>0,IF(MOD(INT(Cron_Uso!BA7/Premissas!$C$41)*Premissas!$C$41,N(Premissas!$F$41))=0,"C",IF(N(Premissas!$E$41)>0,IF(MOD(INT(Cron_Uso!BA7/Premissas!$C$41)*Premissas!$C$41,N(Premissas!$E$41))=0,"B",IF(N(Premissas!$D$41)>0,IF(MOD(INT(Cron_Uso!BA7/Premissas!$C$41)*Premissas!$C$41,N(Premissas!$D$41))=0,"A","S"),"S")),IF(N(Premissas!$D$41)>0,IF(MOD(INT(Cron_Uso!BA7/Premissas!$C$41)*Premissas!$C$41,N(Premissas!$D$41))=0,"A","S"),"S"))),IF(N(Premissas!$E$41)>0,IF(MOD(INT(Cron_Uso!BA7/Premissas!$C$41)*Premissas!$C$41,N(Premissas!$E$41))=0,"B",IF(N(Premissas!$D$41)>0,IF(MOD(INT(Cron_Uso!BA7/Premissas!$C$41)*Premissas!$C$41,N(Premissas!$D$41))=0,"A","S"),"S")),IF(N(Premissas!$D$41)>0,IF(MOD(INT(Cron_Uso!BA7/Premissas!$C$41)*Premissas!$C$41,N(Premissas!$D$41))=0,"A","S"),"S"))),"")
A8: =Premissas!$A$42&" (×"&Premissas!$I$42&")" -> Carregadeira/Pesada (×73) | B8: =IF(INT(Cron_Uso!B8/Premissas!$C$42)>INT(Premissas!$J$42/Premissas!$C$42),IF(N(Premissas!$F$42)>0,IF(MOD(INT(Cron_Uso!B8/Premissas!$C$42)*Premissas!$C$42,N(Premissas!$F$42))=0,"C",IF(N(Premissas!$E$42)>0,IF(MOD(INT(Cron_Uso!B8/Premissas!$C$42)*Premissas!$C$42,N(Premissas!$E$42))=0,"B",IF(N(Premissas!$D$42)>0,IF(MOD(INT(Cron_Uso!B8/Premissas!$C$42)*Premissas!$C$42,N(Premissas!$D$42))=0,"A","S"),"S")),IF(N(Premissas!$D$42)>0,IF(MOD(INT(Cron_Uso!B8/Premissas!$C$42)*Premissas!$C$42,N(Premissas!$D$42))=0,"A","S"),"S"))),IF(N(Premissas!$E$42)>0,IF(MOD(INT(Cron_Uso!B8/Premissas!$C$42)*Premissas!$C$42,N(Premissas!$E$42))=0,"B",IF(N(Premissas!$D$42)>0,IF(MOD(INT(Cron_Uso!B8/Premissas!$C$42)*Premissas!$C$42,N(Premissas!$D$42))=0,"A","S"),"S")),IF(N(Premissas!$D$42)>0,IF(MOD(INT(Cron_Uso!B8/Premissas!$C$42)*Premissas!$C$42,N(Premissas!$D$42))=0,"A","S"),"S"))),"") | C8: =IF(INT(Cron_Uso!C8/Premissas!$C$42)>INT(Cron_Uso!B8/Premissas!$C$42),IF(N(Premissas!$F$42)>0,IF(MOD(INT(Cron_Uso!C8/Premissas!$C$42)*Premissas!$C$42,N(Premissas!$F$42))=0,"C",IF(N(Premissas!$E$42)>0,IF(MOD(INT(Cron_Uso!C8/Premissas!$C$42)*Premissas!$C$42,N(Premissas!$E$42))=0,"B",IF(N(Premissas!$D$42)>0,IF(MOD(INT(Cron_Uso!C8/Premissas!$C$42)*Premissas!$C$42,N(Premissas!$D$42))=0,"A","S"),"S")),IF(N(Premissas!$D$42)>0,IF(MOD(INT(Cron_Uso!C8/Premissas!$C$42)*Premissas!$C$42,N(Premissas!$D$42))=0,"A","S"),"S"))),IF(N(Premissas!$E$42)>0,IF(MOD(INT(Cron_Uso!C8/Premissas!$C$42)*Premissas!$C$42,N(Premissas!$E$42))=0,"B",IF(N(Premissas!$D$42)>0,IF(MOD(INT(Cron_Uso!C8/Premissas!$C$42)*Premissas!$C$42,N(Premissas!$D$42))=0,"A","S"),"S")),IF(N(Premissas!$D$42)>0,IF(MOD(INT(Cron_Uso!C8/Premissas!$C$42)*Premissas!$C$42,N(Premissas!$D$42))=0,"A","S"),"S"))),"") | D8: =IF(INT(Cron_Uso!D8/Premissas!$C$42)>INT(Cron_Uso!C8/Premissas!$C$42),IF(N(Premissas!$F$42)>0,IF(MOD(INT(Cron_Uso!D8/Premissas!$C$42)*Premissas!$C$42,N(Premissas!$F$42))=0,"C",IF(N(Premissas!$E$42)>0,IF(MOD(INT(Cron_Uso!D8/Premissas!$C$42)*Premissas!$C$42,N(Premissas!$E$42))=0,"B",IF(N(Premissas!$D$42)>0,IF(MOD(INT(Cron_Uso!D8/Premissas!$C$42)*Premissas!$C$42,N(Premissas!$D$42))=0,"A","S"),"S")),IF(N(Premissas!$D$42)>0,IF(MOD(INT(Cron_Uso!D8/Premissas!$C$42)*Premissas!$C$42,N(Premissas!$D$42))=0,"A","S"),"S"))),IF(N(Premissas!$E$42)>0,IF(MOD(INT(Cron_Uso!D8/Premissas!$C$42)*Premissas!$C$42,N(Premissas!$E$42))=0,"B",IF(N(Premissas!$D$42)>0,IF(MOD(INT(Cron_Uso!D8/Premissas!$C$42)*Premissas!$C$42,N(Premissas!$D$42))=0,"A","S"),"S")),IF(N(Premissas!$D$42)>0,IF(MOD(INT(Cron_Uso!D8/Premissas!$C$42)*Premissas!$C$42,N(Premissas!$D$42))=0,"A","S"),"S"))),"") | E8: =IF(INT(Cron_Uso!E8/Premissas!$C$42)>INT(Cron_Uso!D8/Premissas!$C$42),IF(N(Premissas!$F$42)>0,IF(MOD(INT(Cron_Uso!E8/Premissas!$C$42)*Premissas!$C$42,N(Premissas!$F$42))=0,"C",IF(N(Premissas!$E$42)>0,IF(MOD(INT(Cron_Uso!E8/Premissas!$C$42)*Premissas!$C$42,N(Premissas!$E$42))=0,"B",IF(N(Premissas!$D$42)>0,IF(MOD(INT(Cron_Uso!E8/Premissas!$C$42)*Premissas!$C$42,N(Premissas!$D$42))=0,"A","S"),"S")),IF(N(Premissas!$D$42)>0,IF(MOD(INT(Cron_Uso!E8/Premissas!$C$42)*Premissas!$C$42,N(Premissas!$D$42))=0,"A","S"),"S"))),IF(N(Premissas!$E$42)>0,IF(MOD(INT(Cron_Uso!E8/Premissas!$C$42)*Premissas!$C$42,N(Premissas!$E$42))=0,"B",IF(N(Premissas!$D$42)>0,IF(MOD(INT(Cron_Uso!E8/Premissas!$C$42)*Premissas!$C$42,N(Premissas!$D$42))=0,"A","S"),"S")),IF(N(Premissas!$D$42)>0,IF(MOD(INT(Cron_Uso!E8/Premissas!$C$42)*Premissas!$C$42,N(Premissas!$D$42))=0,"A","S"),"S"))),"") | F8: =IF(INT(Cron_Uso!F8/Premissas!$C$42)>INT(Cron_Uso!E8/Premissas!$C$42),IF(N(Premissas!$F$42)>0,IF(MOD(INT(Cron_Uso!F8/Premissas!$C$42)*Premissas!$C$42,N(Premissas!$F$42))=0,"C",IF(N(Premissas!$E$42)>0,IF(MOD(INT(Cron_Uso!F8/Premissas!$C$42)*Premissas!$C$42,N(Premissas!$E$42))=0,"B",IF(N(Premissas!$D$42)>0,IF(MOD(INT(Cron_Uso!F8/Premissas!$C$42)*Premissas!$C$42,N(Premissas!$D$42))=0,"A","S"),"S")),IF(N(Premissas!$D$42)>0,IF(MOD(INT(Cron_Uso!F8/Premissas!$C$42)*Premissas!$C$42,N(Premissas!$D$42))=0,"A","S"),"S"))),IF(N(Premissas!$E$42)>0,IF(MOD(INT(Cron_Uso!F8/Premissas!$C$42)*Premissas!$C$42,N(Premissas!$E$42))=0,"B",IF(N(Premissas!$D$42)>0,IF(MOD(INT(Cron_Uso!F8/Premissas!$C$42)*Premissas!$C$42,N(Premissas!$D$42))=0,"A","S"),"S")),IF(N(Premissas!$D$42)>0,IF(MOD(INT(Cron_Uso!F8/Premissas!$C$42)*Premissas!$C$42,N(Premissas!$D$42))=0,"A","S"),"S"))),"") | G8: =IF(INT(Cron_Uso!G8/Premissas!$C$42)>INT(Cron_Uso!F8/Premissas!$C$42),IF(N(Premissas!$F$42)>0,IF(MOD(INT(Cron_Uso!G8/Premissas!$C$42)*Premissas!$C$42,N(Premissas!$F$42))=0,"C",IF(N(Premissas!$E$42)>0,IF(MOD(INT(Cron_Uso!G8/Premissas!$C$42)*Premissas!$C$42,N(Premissas!$E$42))=0,"B",IF(N(Premissas!$D$42)>0,IF(MOD(INT(Cron_Uso!G8/Premissas!$C$42)*Premissas!$C$42,N(Premissas!$D$42))=0,"A","S"),"S")),IF(N(Premissas!$D$42)>0,IF(MOD(INT(Cron_Uso!G8/Premissas!$C$42)*Premissas!$C$42,N(Premissas!$D$42))=0,"A","S"),"S"))),IF(N(Premissas!$E$42)>0,IF(MOD(INT(Cron_Uso!G8/Premissas!$C$42)*Premissas!$C$42,N(Premissas!$E$42))=0,"B",IF(N(Premissas!$D$42)>0,IF(MOD(INT(Cron_Uso!G8/Premissas!$C$42)*Premissas!$C$42,N(Premissas!$D$42))=0,"A","S"),"S")),IF(N(Premissas!$D$42)>0,IF(MOD(INT(Cron_Uso!G8/Premissas!$C$42)*Premissas!$C$42,N(Premissas!$D$42))=0,"A","S"),"S"))),"") -> S | H8: =IF(INT(Cron_Uso!H8/Premissas!$C$42)>INT(Cron_Uso!G8/Premissas!$C$42),IF(N(Premissas!$F$42)>0,IF(MOD(INT(Cron_Uso!H8/Premissas!$C$42)*Premissas!$C$42,N(Premissas!$F$42))=0,"C",IF(N(Premissas!$E$42)>0,IF(MOD(INT(Cron_Uso!H8/Premissas!$C$42)*Premissas!$C$42,N(Premissas!$E$42))=0,"B",IF(N(Premissas!$D$42)>0,IF(MOD(INT(Cron_Uso!H8/Premissas!$C$42)*Premissas!$C$42,N(Premissas!$D$42))=0,"A","S"),"S")),IF(N(Premissas!$D$42)>0,IF(MOD(INT(Cron_Uso!H8/Premissas!$C$42)*Premissas!$C$42,N(Premissas!$D$42))=0,"A","S"),"S"))),IF(N(Premissas!$E$42)>0,IF(MOD(INT(Cron_Uso!H8/Premissas!$C$42)*Premissas!$C$42,N(Premissas!$E$42))=0,"B",IF(N(Premissas!$D$42)>0,IF(MOD(INT(Cron_Uso!H8/Premissas!$C$42)*Premissas!$C$42,N(Premissas!$D$42))=0,"A","S"),"S")),IF(N(Premissas!$D$42)>0,IF(MOD(INT(Cron_Uso!H8/Premissas!$C$42)*Premissas!$C$42,N(Premissas!$D$42))=0,"A","S"),"S"))),"") | I8: =IF(INT(Cron_Uso!I8/Premissas!$C$42)>INT(Cron_Uso!H8/Premissas!$C$42),IF(N(Premissas!$F$42)>0,IF(MOD(INT(Cron_Uso!I8/Premissas!$C$42)*Premissas!$C$42,N(Premissas!$F$42))=0,"C",IF(N(Premissas!$E$42)>0,IF(MOD(INT(Cron_Uso!I8/Premissas!$C$42)*Premissas!$C$42,N(Premissas!$E$42))=0,"B",IF(N(Premissas!$D$42)>0,IF(MOD(INT(Cron_Uso!I8/Premissas!$C$42)*Premissas!$C$42,N(Premissas!$D$42))=0,"A","S"),"S")),IF(N(Premissas!$D$42)>0,IF(MOD(INT(Cron_Uso!I8/Premissas!$C$42)*Premissas!$C$42,N(Premissas!$D$42))=0,"A","S"),"S"))),IF(N(Premissas!$E$42)>0,IF(MOD(INT(Cron_Uso!I8/Premissas!$C$42)*Premissas!$C$42,N(Premissas!$E$42))=0,"B",IF(N(Premissas!$D$42)>0,IF(MOD(INT(Cron_Uso!I8/Premissas!$C$42)*Premissas!$C$42,N(Premissas!$D$42))=0,"A","S"),"S")),IF(N(Premissas!$D$42)>0,IF(MOD(INT(Cron_Uso!I8/Premissas!$C$42)*Premissas!$C$42,N(Premissas!$D$42))=0,"A","S"),"S"))),"") | J8: =IF(INT(Cron_Uso!J8/Premissas!$C$42)>INT(Cron_Uso!I8/Premissas!$C$42),IF(N(Premissas!$F$42)>0,IF(MOD(INT(Cron_Uso!J8/Premissas!$C$42)*Premissas!$C$42,N(Premissas!$F$42))=0,"C",IF(N(Premissas!$E$42)>0,IF(MOD(INT(Cron_Uso!J8/Premissas!$C$42)*Premissas!$C$42,N(Premissas!$E$42))=0,"B",IF(N(Premissas!$D$42)>0,IF(MOD(INT(Cron_Uso!J8/Premissas!$C$42)*Premissas!$C$42,N(Premissas!$D$42))=0,"A","S"),"S")),IF(N(Premissas!$D$42)>0,IF(MOD(INT(Cron_Uso!J8/Premissas!$C$42)*Premissas!$C$42,N(Premissas!$D$42))=0,"A","S"),"S"))),IF(N(Premissas!$E$42)>0,IF(MOD(INT(Cron_Uso!J8/Premissas!$C$42)*Premissas!$C$42,N(Premissas!$E$42))=0,"B",IF(N(Premissas!$D$42)>0,IF(MOD(INT(Cron_Uso!J8/Premissas!$C$42)*Premissas!$C$42,N(Premissas!$D$42))=0,"A","S"),"S")),IF(N(Premissas!$D$42)>0,IF(MOD(INT(Cron_Uso!J8/Premissas!$C$42)*Premissas!$C$42,N(Premissas!$D$42))=0,"A","S"),"S"))),"") | ... BA8: =IF(INT(Cron_Uso!BA8/Premissas!$C$42)>INT(Cron_Uso!AZ8/Premissas!$C$42),IF(N(Premissas!$F$42)>0,IF(MOD(INT(Cron_Uso!BA8/Premissas!$C$42)*Premissas!$C$42,N(Premissas!$F$42))=0,"C",IF(N(Premissas!$E$42)>0,IF(MOD(INT(Cron_Uso!BA8/Premissas!$C$42)*Premissas!$C$42,N(Premissas!$E$42))=0,"B",IF(N(Premissas!$D$42)>0,IF(MOD(INT(Cron_Uso!BA8/Premissas!$C$42)*Premissas!$C$42,N(Premissas!$D$42))=0,"A","S"),"S")),IF(N(Premissas!$D$42)>0,IF(MOD(INT(Cron_Uso!BA8/Premissas!$C$42)*Premissas!$C$42,N(Premissas!$D$42))=0,"A","S"),"S"))),IF(N(Premissas!$E$42)>0,IF(MOD(INT(Cron_Uso!BA8/Premissas!$C$42)*Premissas!$C$42,N(Premissas!$E$42))=0,"B",IF(N(Premissas!$D$42)>0,IF(MOD(INT(Cron_Uso!BA8/Premissas!$C$42)*Premissas!$C$42,N(Premissas!$D$42))=0,"A","S"),"S")),IF(N(Premissas!$D$42)>0,IF(MOD(INT(Cron_Uso!BA8/Premissas!$C$42)*Premissas!$C$42,N(Premissas!$D$42))=0,"A","S"),"S"))),"")
