Workbook

Sheet Capa
B2: VECTOR CONSULTING
B5: DIAGNÓSTICO DE GESTÃO DE MANUTENÇÃO
B6: Gap Analysis vs. Modelo de Referência AgroVector — Fases 1 e 2
B7: Planejamento Integrado de Manutenção · Garagem de Usina · Agronegócio
B10: IDENTIFICAÇÃO DO CLIENTE
B11: Cliente / Razão Social
B12: Unidade / Filial diagnosticada
B13: Localização (cidade / UF)
B14: Cultura(s) principal(is)
B15: Área cultivada (ha)
B16: Frota total (qtd. ativos)
B18: EQUIPE DO DIAGNÓSTICO
... B26: ESCOPO E OBJETIVOS
B27: Escopo avaliado | C27: F1 (Fundamentos): Premissas · Frota · Pessoas · Checklists F2 (Planejamento): Cronograma · Plano Preventivo · Plano Corretivo · Disponibilidade
B28: Objetivo principal | C28: Identificar gaps do modelo atual de manutenção do cliente versus o modelo de referência AgroVector e estruturar plano de fechamento.
B29: Metodologia | C29: Diagnóstico híbrido: Quick-Scan (Tem/Parcial/Não tem) + Avaliação Detalhada de Maturidade (0–5) com evidências, gaps e ações.
B32: Pilares: PROCESSOS · TECNOLOGIA · PESSOAS | www.vectorconsulting.com.br

Sheet Instruções
B2: COMO USAR O TEMPLATE
B4: Fluxo recomendado | C4: 1. Preencha a aba CAPA com identificação do cliente e equipe. 2. Faça primeira passada na aba QUICK-SCAN durante visita inicial (visão macro). 3. Aprofunde na aba DETALHADO_F1 e DETALHADO_F2 com evidências e gaps. 4. Consulte DASHBOARD para visualizar score por módulo e priorizar. 5. Consolide o PLANO DE AÇÃO priorizado para devolutiva ao cliente.
B5: Quick-Scan | C5: Avaliação rápida (Tem / Parcial / Não tem) por item. Útil para visita de 1 dia e calibragem de profundidade da etapa seguinte. Cada item já vincula automaticamente ao módulo correspondente.
B6: Avaliação Detalhada | C6: Maturidade de 0 a 5 por item, com campos para evidência observada, gap identificado, ação corretiva proposta, prioridade (Alta/Média/Baixa) e horizonte (curto/médio/longo prazo).
B7: Escala de maturidade | C7: 0 = Inexistente · não há prática nem intenção 1 = Inicial · prática ad hoc, dependente de pessoa 2 = Definido informalmente · há prática mas sem documentação 3 = Documentado · existe processo, KPI parcial 4 = Gerenciado · processo medido, KPI ativo, ciclo PDCA 5 = Otimizado · benchmark, melhoria contínua, automação
B8: Cores e regras | C8: Score 0–1,9 → VERMELHO (gap crítico) Score 2,0–3,4 → ÂMBAR (gap relevante) Score 3,5–5,0 → VERDE (aderente ou otimizado) Quick-Scan: Tem = 2 pts · Parcial = 1 pt · Não tem = 0 pts.
B9: Dicas de campo | C9: • Sempre pedir evidência (printscreen do sistema, planilha, relatório, OS impressa). • Triangular informação: gerente, líder de oficina e mecânico de chão. • Anotar nome do entrevistado e data na coluna de evidência. • Diferenciar 'existe no papel' de 'é usado na rotina' (segundo é o que vale).
B11: LEGENDA — CORES FABIO (SEMÁFORO)
B12: VERDE (#00FF00) | C12: Aderente — score 3,5–5,0 · Quick-Scan "Tem" · Prioridade Baixa · Status Concluído
B13: AMARELO (#FFFF00) | C13: Gap relevante — score 2,0–3,4 · Quick-Scan "Parcial" · Prioridade Média · Em andamento
B14: VERMELHO (#FF3300) | C14: Gap crítico / precisa melhorar — score 0–1,9 · "Não tem" · Prioridade Alta · Não iniciado

Sheet Quick-Scan
A1: QUICK-SCAN — Avaliação Rápida de Aderência
A2: Para cada item, marque: TEM (prática implementada e em uso) · PARCIAL (existe mas incompleto/intermitente) · NÃO TEM. Use a aba Detalhado para evidências e ações.
A4: Módulo | B4: Item avaliado | C4: Status | D4: Observação rápida | E4: Pontos
A5: F1.1 Premissas | B5: Índice esperado de preventiva vs corretiva definido formalmente por oficina | C5: Não tem | E5: =IF(C5="Tem",2,IF(C5="Parcial",1,IF(C5="Não tem",0,""))) -> 0
A6: F1.1 Premissas | B6: Meta de % de serviços terceirizados definida por oficina | E6: =IF(C6="Tem",2,IF(C6="Parcial",1,IF(C6="Não tem",0,"")))
A7: F1.1 Premissas | B7: Fator de redução de corretivas (deflator a.a.) definido e acompanhado | E7: =IF(C7="Tem",2,IF(C7="Parcial",1,IF(C7="Não tem",0,"")))
A8: F1.1 Premissas | B8: Disponibilidade de MO parametrizada por oficina (horas brutas, descontos, produtividade) | E8: =IF(C8="Tem",2,IF(C8="Parcial",1,IF(C8="Não tem",0,"")))
A9: F1.1 Premissas | B9: Cálculo formal de horas líquidas disponíveis por oficina e por colaborador | E9: =IF(C9="Tem",2,IF(C9="Parcial",1,IF(C9="Não tem",0,"")))
A10: F1.1 Premissas | B10: Calendário de dias úteis estruturado mês a mês | E10: =IF(C10="Tem",2,IF(C10="Parcial",1,IF(C10="Não tem",0,"")))
A11: F1.1 Premissas | B11: Definição clara do período de safra e entressafra | E11: =IF(C11="Tem",2,IF(C11="Parcial",1,IF(C11="Não tem",0,"")))
A12: F1.1 Premissas | B12: Fator de sazonalidade de corretivas aplicado mês a mês | E12: =IF(C12="Tem",2,IF(C12="Parcial",1,IF(C12="Não tem",0,"")))
A13: F1.1 Premissas | B13: Gatilhos de preventiva (horas/km) definidos por classe de ativo | E13: =IF(C13="Tem",2,IF(C13="Parcial",1,IF(C13="Não tem",0,"")))
A14: F1.1 Premissas | B14: Intervalos definidos para tipos de revisão (S/A/B/C/D) | E14: =IF(C14="Tem",2,IF(C14="Parcial",1,IF(C14="Não tem",0,"")))
A15: F1.1 Premissas | B15: Regra de herança cumulativa entre tipos de preventiva estruturada | E15: =IF(C15="Tem",2,IF(C15="Parcial",1,IF(C15="Não tem",0,"")))
A16: F1.2 Frota | B16: Cadastro completo de todos os ativos da operação | E16: =IF(C16="Tem",2,IF(C16="Parcial",1,IF(C16="Não tem",0,"")))
A17: F1.2 Frota | B17: Cadastro contém classe, modelo, fabricante, ano e filial | E17: =IF(C17="Tem",2,IF(C17="Parcial",1,IF(C17="Não tem",0,"")))
... A66: F2.4 Disponibilidade | B66: Plano de ação estruturado para meses com déficit/sobra | E66: =IF(C66="Tem",2,IF(C66="Parcial",1,IF(C66="Não tem",0,"")))
A67: TOTAL QUICK-SCAN | E67: =SUM(E5:E66) -> 0
A68: Aderência % (vs. máximo de 2 pts/item) | E68: =E67/(62*2) -> 0

Sheet Detalhado_F1
A1: DETALHADO F1 — Fundamentos
A2: Maturidade 0–5 por item. Registre evidência observada (sistema/planilha/OS), gap específico, ação corretiva proposta, prioridade e horizonte. Score por módulo é calculado automaticamente e alimenta o Dashboard.
A4: Módulo | B4: Item avaliado | C4: Nível 0–5 | D4: Evidência observada | E4: Gap identificado | F4: Ação corretiva proposta | G4: Prioridade | H4: Horizonte | I4: Responsável proposto
A5: F1.1 Premissas | B5: Índice esperado de preventiva vs corretiva definido formalmente por oficina
A6: F1.1 Premissas | B6: Meta de % de serviços terceirizados definida por oficina
A7: F1.1 Premissas | B7: Fator de redução de corretivas (deflator a.a.) definido e acompanhado
A8: F1.1 Premissas | B8: Disponibilidade de MO parametrizada por oficina (horas brutas, descontos, produtividade)
A9: F1.1 Premissas | B9: Cálculo formal de horas líquidas disponíveis por oficina e por colaborador
A10: F1.1 Premissas | B10: Calendário de dias úteis estruturado mês a mês
A11: F1.1 Premissas | B11: Definição clara do período de safra e entressafra
A12: F1.1 Premissas | B12: Fator de sazonalidade de corretivas aplicado mês a mês
A13: F1.1 Premissas | B13: Gatilhos de preventiva (horas/km) definidos por classe de ativo
A14: F1.1 Premissas | B14: Intervalos definidos para tipos de revisão (S/A/B/C/D)
A15: F1.1 Premissas | B15: Regra de herança cumulativa entre tipos de preventiva estruturada
A16: Score médio · F1.1 Premissas | C16: =IFERROR(AVERAGE(C5:C15),0) -> 0
A17: F1.2 Frota | B17: Cadastro completo de todos os ativos da operação
A18: F1.2 Frota | B18: Cadastro contém classe, modelo, fabricante, ano e filial
A19: F1.2 Frota | B19: Status do ativo registrado (Ativo/Reforma/Inativo/Vendido)
A20: F1.2 Frota | B20: Horímetro/odômetro atual atualizado por ativo
A21: F1.2 Frota | B21: Uso médio mensal calculado por ativo
A22: F1.2 Frota | B22: Uso médio diferenciado entre safra e entressafra
A23: F1.2 Frota | B23: Intervalo de preventiva (horas/km) definido por ativo
A24: F1.2 Frota | B24: Status de garantia controlado por ativo
A25: F1.2 Frota | B25: Cadastro atualizado em rotina (semanal/mensal)
A26: Score médio · F1.2 Frota | C26: =IFERROR(AVERAGE(C17:C25),0) -> 0
A27: F1.3 Pessoas | B27: Cadastro completo de mão de obra de manutenção
A28: F1.3 Pessoas | B28: Estrutura organizada por tipo de oficina
A29: F1.3 Pessoas | B29: Cargo definido para cada colaborador
A30: F1.3 Pessoas | B30: Turno definido (Diurno/Noturno/Safra/5x1)
A31: F1.3 Pessoas | B31: Salário e encargos registrados por colaborador
A32: F1.3 Pessoas | B32: Status atualizado (Ativo/Inativo/Férias/Afastado)
A33: F1.3 Pessoas | B33: Custo/hora calculado por colaborador e oficina
A34: F1.3 Pessoas | B34: Resumo consolidado de HH disponível por oficina
A35: Score médio · F1.3 Pessoas | C35: =IFERROR(AVERAGE(C27:C34),0) -> 0
A36: F1.4 Checklist | B36: Checklists padronizados por tipo de preventiva (S/A/B/C/D)
A37: F1.4 Checklist | B37: Checklists diferenciados por classe de ativo
A38: F1.4 Checklist | B38: Atividades detalhadas dentro de cada checklist
A39: F1.4 Checklist | B39: Cargo executor definido por atividade
A40: F1.4 Checklist | B40: Tipo de atividade categorizado (Troca/Inspeção/Lubrif/Calibragem/etc.)
A41: F1.4 Checklist | B41: Tempo padrão (HH) registrado por atividade
...

Sheet Detalhado_F2
A1: DETALHADO F2 — Planejamento
A2: Maturidade 0–5 por item. Registre evidência observada (sistema/planilha/OS), gap específico, ação corretiva proposta, prioridade e horizonte. Score por módulo é calculado automaticamente e alimenta o Dashboard.
A4: Módulo | B4: Item avaliado | C4: Nível 0–5 | D4: Evidência observada | E4: Gap identificado | F4: Ação corretiva proposta | G4: Prioridade | H4: Horizonte | I4: Responsável proposto
A5: F2.1 Cronograma | B5: Cronograma estruturado em base semanal
A6: F2.1 Cronograma | B6: Cobertura de 52 semanas (ciclo anual completo)
A7: F2.1 Cronograma | B7: Grade Ativo × Semana implementada
A8: F2.1 Cronograma | B8: Tipo de preventiva (S/A/B/C/D) indicado por semana
A9: F2.1 Cronograma | B9: HH preventiva agregada por oficina e por mês
A10: F2.1 Cronograma | B10: Cronograma considera calendário agrícola (safra/entressafra)
A11: F2.1 Cronograma | B11: Replanejamento periódico baseado em uso real do ativo
A12: Score médio · F2.1 Cronograma | C12: =IFERROR(AVERAGE(C5:C11),0) -> 0
A13: F2.2 Plano Preventivo | B13: Plano de preventiva mensal estruturado por oficina
A14: F2.2 Plano Preventivo | B14: Quantidade de preventivas por tipo (S/A/B/C/D) mensal
A15: F2.2 Plano Preventivo | B15: HH preventiva por tipo de oficina × mês
A16: F2.2 Plano Preventivo | B16: Lançamento de insumos e peças por preventiva planejada
A17: F2.2 Plano Preventivo | B17: Aderência preventiva planejada vs realizada medida
A18: F2.2 Plano Preventivo | B18: Indicador de cumprimento mensal acompanhado pela gestão
A19: Score médio · F2.2 Plano Preventivo | C19: =IFERROR(AVERAGE(C13:C18),0) -> 0
A20: F2.3 Plano Corretivo | B20: Plano de corretivas esperadas mês a mês
A21: F2.3 Plano Corretivo | B21: Sazonalidade aplicada ao cálculo de corretivas
A22: F2.3 Plano Corretivo | B22: HH corretiva por oficina × mês dimensionada
A23: F2.3 Plano Corretivo | B23: Histórico de corretivas usado para calibrar previsões
A24: F2.3 Plano Corretivo | B24: Deflator de corretivas (redução a.a.) monitorado
A25: F2.3 Plano Corretivo | B25: Análise de causa raiz das corretivas recorrentes
A26: Score médio · F2.3 Plano Corretivo | C26: =IFERROR(AVERAGE(C20:C25),0) -> 0
A27: F2.4 Disponibilidade | B27: Comparativo HH disponível vs HH necessária por oficina × mês
A28: F2.4 Disponibilidade | B28: Identificação de gargalos (HH necessária > disponível)
A29: F2.4 Disponibilidade | B29: Identificação de ociosidade (HH disponível >> necessária)
A30: F2.4 Disponibilidade | B30: Consolidado geral por oficina × mês implementado
A31: F2.4 Disponibilidade | B31: Dimensionamento de horas extras ou terceiros para déficit
A32: F2.4 Disponibilidade | B32: Plano de ação estruturado para meses com déficit/sobra
A33: Score médio · F2.4 Disponibilidade | C33: =IFERROR(AVERAGE(C27:C32),0) -> 0

Sheet Dashboard
B2: DASHBOARD DE GAPS — Modelo Atual vs. AgroVector
B3: Score consolidado por módulo (calculado automaticamente a partir das abas detalhadas). Use como base para a devolutiva ao cliente.
B5: Módulo | C5: Score (0–5) | D5: Gap (%) | E5: Classificação | F5: Itens críticos (score ≤ 2) | H5: KPI executivo | I5: Valor
B6: F1.1 Premissas | C6: =IFERROR(AVERAGE(Detalhado_F1!C5:C15),0) -> 0 | D6: =IFERROR(1-C6/5,0) -> 1 | E6: =IF(C6=0,"—",IF(C6<2,"Crítico",IF(C6<3.5,"Relevante","Aderente"))) -> — | F6: =COUNTIFS(Detalhado_F1!C5:C15,"<=2",Detalhado_F1!C5:C15,">0")+COUNTIF(Detalhado_F1!C5:C15,0) -> 0 | H6: Quick-Scan — total de pontos | I6: ='Quick-Scan'!E67 -> 0
B7: F1.2 Frota | C7: =IFERROR(AVERAGE(Detalhado_F1!C17:C25),0) -> 0 | D7: =IFERROR(1-C7/5,0) -> 1 | E7: =IF(C7=0,"—",IF(C7<2,"Crítico",IF(C7<3.5,"Relevante","Aderente"))) -> — | F7: =COUNTIFS(Detalhado_F1!C17:C25,"<=2",Detalhado_F1!C17:C25,">0")+COUNTIF(Detalhado_F1!C17:C25,0) -> 0 | H7: Quick-Scan — aderência (%) | I7: ='Quick-Scan'!E68 -> 0
B8: F1.3 Pessoas | C8: =IFERROR(AVERAGE(Detalhado_F1!C27:C34),0) -> 0 | D8: =IFERROR(1-C8/5,0) -> 1 | E8: =IF(C8=0,"—",IF(C8<2,"Crítico",IF(C8<3.5,"Relevante","Aderente"))) -> — | F8: =COUNTIFS(Detalhado_F1!C27:C34,"<=2",Detalhado_F1!C27:C34,">0")+COUNTIF(Detalhado_F1!C27:C34,0) -> 0 | H8: Total de itens avaliados | I8: =62 -> 62
B9: F1.4 Checklist | C9: =IFERROR(AVERAGE(Detalhado_F1!C36:C44),0) -> 0 | D9: =IFERROR(1-C9/5,0) -> 1 | E9: =IF(C9=0,"—",IF(C9<2,"Crítico",IF(C9<3.5,"Relevante","Aderente"))) -> — | F9: =COUNTIFS(Detalhado_F1!C36:C44,"<=2",Detalhado_F1!C36:C44,">0")+COUNTIF(Detalhado_F1!C36:C44,0) -> 0 | H9: Itens em estado crítico (≤2) | I9: =SUM(F6:F13) -> 0
B10: F2.1 Cronograma | C10: =IFERROR(AVERAGE(Detalhado_F2!C5:C11),0) -> 0 | D10: =IFERROR(1-C10/5,0) -> 1 | E10: =IF(C10=0,"—",IF(C10<2,"Crítico",IF(C10<3.5,"Relevante","Aderente"))) -> — | F10: =COUNTIFS(Detalhado_F2!C5:C11,"<=2",Detalhado_F2!C5:C11,">0")+COUNTIF(Detalhado_F2!C5:C11,0) -> 0 | H10: Módulos com gap relevante (>30%) | I10: =COUNTIF(D6:D13,">=0.3") -> 8
B11: F2.2 Plano Preventivo | C11: =IFERROR(AVERAGE(Detalhado_F2!C13:C18),0) -> 0 | D11: =IFERROR(1-C11/5,0) -> 1 | E11: =IF(C11=0,"—",IF(C11<2,"Crítico",IF(C11<3.5,"Relevante","Aderente"))) -> — | F11: =COUNTIFS(Detalhado_F2!C13:C18,"<=2",Detalhado_F2!C13:C18,">0")+COUNTIF(Detalhado_F2!C13:C18,0) -> 0 | H11: Módulo de maior gap | I11: =INDEX(B6:B13,MATCH(MAX(D6:D13),D6:D13,0)) -> F1.1 Premissas
B12: F2.3 Plano Corretivo | C12: =IFERROR(AVERAGE(Detalhado_F2!C20:C25),0) -> 0 | D12: =IFERROR(1-C12/5,0) -> 1 | E12: =IF(C12=0,"—",IF(C12<2,"Crítico",IF(C12<3.5,"Relevante","Aderente"))) -> — | F12: =COUNTIFS(Detalhado_F2!C20:C25,"<=2",Detalhado_F2!C20:C25,">0")+COUNTIF(Detalhado_F2!C20:C25,0) -> 0 | H12: Score do módulo de maior gap | I12: =INDEX(C6:C13,MATCH(MAX(D6:D13),D6:D13,0)) -> 0
B13: F2.4 Disponibilidade | C13: =IFERROR(AVERAGE(Detalhado_F2!C27:C32),0) -> 0 | D13: =IFERROR(1-C13/5,0) -> 1 | E13: =IF(C13=0,"—",IF(C13<2,"Crítico",IF(C13<3.5,"Relevante","Aderente"))) -> — | F13: =COUNTIFS(Detalhado_F2!C27:C32,"<=2",Detalhado_F2!C27:C32,">0")+COUNTIF(Detalhado_F2!C27:C32,0) -> 0
B14: MÉDIA GERAL DO DIAGNÓSTICO | C14: =AVERAGE(C6:C13) -> 0 | D14: =1-C14/5 -> 1 | E14: =IF(C14<2,"Crítico",IF(C14<3.5,"Relevante","Aderente")) -> Crítico | F14: =SUM(F6:F13) -> 0

Sheet Plano_Ação
A1: PLANO DE AÇÃO PRIORIZADO — Fechamento de Gaps
A2: Consolide aqui os gaps prioritários (priorize itens com score 0–2 e Alta prioridade). Use como base para a apresentação executiva da devolutiva.
A4: # | B4: Módulo | C4: Gap (descrição) | D4: Ação proposta | E4: Prioridade | F4: Horizonte | G4: Responsável | H4: Custo estimado | I4: Status
A5: 1
A6: 2
A7: 3
A8: 4
A9: 5
A10: 6
A11: 7
A12: 8
A13: 9
A14: 10
A15: 11
A16: 12
... A24: 20
A25: Investimento total estimado | H25: =SUM(H5:H24) -> 0
