Workbook

Sheet Leia-me
A1: PLANEJAMENTO DE MANUTENÇÃO — RÉPLICA FUNCIONAL DO APP AGROVECTOR v4.2
A3: 1 | B3: O que é | C3: Réplica em Excel do motor de cálculo do app (agrovector_manutencao_v4.2). Altere Premissas, Frota, Pessoas ou Checklist — Cronograma, Planos, Disponibilidade, Recursos, Insumos, Saving e Resumo recalculam automaticamente, com as MESMAS fórmulas do app.
A4: 2 | B4: Abas de entrada (editar) | C4: Premissas · Frota · Pessoas · Checklist. Preencha apenas células brancas; use os menus suspensos. Dados atuais = demonstração do app (substituir pelos do cliente).
A5: 3 | B5: Abas de resultado (não editar) | C5: Cronograma · Plan_Prev · Plan_Corr · Disponibilidade · Recursos · Insumos · Saving · Resumo — 100% fórmulas.
A6: 4 | B6: Abas auxiliares (não mexer) | C6: Semanas, Cron_Uso, Eventos e Aux_HH são o motor de cálculo (uso acumulado semanal, herança de checklists, contagem de eventos).
A7: 5 | B7: Lógica do motor | C7: 52 semanas a partir do Início da Safra; uso acumulado semanal (safra/entressafra) dispara preventiva ao cruzar múltiplo do intervalo; tipo S/A/B pelo maior gatilho divisível; HH com herança cumulativa (B executa S+A+B); corretiva = preventiva × (corr/prev) × deflator progressivo × sazonalidade mensal; disponibilidade = pessoas ativas × dias úteis × horas líquidas; saving = corretiva sem deflator (baseline) − corretiva com plano, valorizada pelo custo/HH médio da oficina.
A8: 6 | B8: Simplificações | C8: Máx. 1 preventiva por ativo/semana (válido quando uso semanal << intervalo) · Tipos S/A/B (C/D podem ser acrescentados nos gatilhos e checklists) · Capacidade: 30 ativos, 40 pessoas, 100 atividades de checklist (linhas já formatadas).
A9: 7 | B9: Carga no app | C9: Após validar aqui, use a planilha Parametrizacao_AgroVector_v4.2.xlsx (abas Frota/Pessoas/Checklist → CSV UTF-8 → botões 📥 Importar do app). Premissas são digitadas na aba 📐 do app.
A10: 8 | B10: Cores Fabio | C10: VERDE #00FF00 = OK · AMARELO #FFFF00 = atenção · VERMELHO #FF3300 = crítico (fonte branca). Aplicadas nos saldos, gaps e no cronograma (S=verde, A=amarelo, B=vermelho).

Sheet Premissas
A1: PREMISSAS — ponto de partida de todos os cálculos
A3: ÍNDICES POR OFICINA
A4: Oficina | B4: % Preventiva | C4: % Corretiva | D4: Check % | E4: Deflator (% a.a.) | F4: % Terceiros
A5: Mec. Oficina | B5: 60 | C5: 40 | D5: =IF(B5+C5=100,"OK","≠100") -> OK | E5: 5 | F5: 10
A6: Mec. Campo | B6: 40 | C6: 60 | D6: =IF(B6+C6=100,"OK","≠100") -> OK | E6: 8 | F6: 5
A7: Elétrica | B7: 55 | C7: 45 | D7: =IF(B7+C7=100,"OK","≠100") -> OK | E7: 5 | F7: 15
A8: Lubrificação | B8: 100 | C8: 0 | D8: =IF(B8+C8=100,"OK","≠100") -> OK | E8: 0 | F8: 0
A9: Borracharia | B9: 30 | C9: 70 | D9: =IF(B9+C9=100,"OK","≠100") -> OK | E9: 5 | F9: 20
A10: Caldeiraria | B10: 20 | C10: 80 | D10: =IF(B10+C10=100,"OK","≠100") -> OK | E10: 3 | F10: 30
A12: DISPONIBILIDADE DE MÃO DE OBRA (fórmula idêntica ao app)
A13: Oficina | B13: H.Brutas/dia | C13: Almoço (h) | D13: Café (h) | E13: Abertura OS (h) | F13: Produtividade % | G13: Absenteísmo % | H13: Férias % | I13: Trein. (h/ano) | J13: H.Efetivas/dia | K13: H.Líquidas/dia
A14: Mec. Oficina | B14: 8.8 | C14: 1.2 | D14: 0.17 | E14: 0.25 | F14: 80 | G14: 5 | H14: 8.33 | I14: 16 | J14: =MAX(0,B14-C14-D14-E14) -> 7.18 | K14: =ROUND(J14*(1-MIN(G14/100+H14/100/12+I14/MAX(1,252*J14),0.99))*(F14/100),2) -> 5.37
A15: Mec. Campo | B15: 9 | C15: 1 | D15: 0.17 | E15: 0.17 | F15: 75 | G15: 6 | H15: 8.33 | I15: 12 | J15: =MAX(0,B15-C15-D15-E15) -> 7.66 | K15: =ROUND(J15*(1-MIN(G15/100+H15/100/12+I15/MAX(1,252*J15),0.99))*(F15/100),2) -> 5.32
A16: Elétrica | B16: 8.8 | C16: 1.2 | D16: 0.17 | E16: 0.25 | F16: 80 | G16: 5 | H16: 8.33 | I16: 16 | J16: =MAX(0,B16-C16-D16-E16) -> 7.18 | K16: =ROUND(J16*(1-MIN(G16/100+H16/100/12+I16/MAX(1,252*J16),0.99))*(F16/100),2) -> 5.37
A17: Lubrificação | B17: 8.8 | C17: 1 | D17: 0.17 | E17: 0.17 | F17: 85 | G17: 4 | H17: 8.33 | I17: 8 | J17: =MAX(0,B17-C17-D17-E17) -> 7.46 | K17: =ROUND(J17*(1-MIN(G17/100+H17/100/12+I17/MAX(1,252*J17),0.99))*(F17/100),2) -> 6.02
A18: Borracharia | B18: 8.8 | C18: 1 | D18: 0.17 | E18: 0.17 | F18: 82 | G18: 5 | H18: 8.33 | I18: 8 | J18: =MAX(0,B18-C18-D18-E18) -> 7.46 | K18: =ROUND(J18*(1-MIN(G18/100+H18/100/12+I18/MAX(1,252*J18),0.99))*(F18/100),2) -> 5.74
A19: Caldeiraria | B19: 8.8 | C19: 1.2 | D19: 0.17 | E19: 0.25 | F19: 78 | G19: 5 | H19: 8.33 | I19: 16 | J19: =MAX(0,B19-C19-D19-E19) -> 7.18 | K19: =ROUND(J19*(1-MIN(G19/100+H19/100/12+I19/MAX(1,252*J19),0.99))*(F19/100),2) -> 5.23
A21: CALENDÁRIO E SAZONALIDADE | F21: Início da safra | G21: 2025-04-01
A22: Mês | B22: Dias úteis | C22: Fator sazonal corretivas | D22: Safra (informativo) | F22: Fim da safra | G22: 2025-11-30
A23: Jan | B23: 22 | C23: 1.8 | D23: Sim
A24: Fev | B24: 20 | C24: 1.5 | D24: Sim
A25: Mar | B25: 22 | C25: 1.3 | D25: Sim
A26: Abr | B26: 20 | C26: 1.2 | D26: Sim
A27: Mai | B27: 20 | C27: 1.1 | D27: Sim
A28: Jun | B28: 22 | C28: 1 | D28: Sim
A29: Jul | B29: 21 | C29: 0.7 | D29: Não
A30: Ago | B30: 20 | C30: 0.6 | D30: Não
A31: Set | B31: 23 | C31: 0.7 | D31: Não
A32: Out | B32: 22 | C32: 0.9 | D32: Não
A33: Nov | B33: 21 | C33: 1 | D33: Não
A34: Dez | B34: 23 | C34: 1.4 | D34: Sim
A35: TOTAL/MÉDIA | B35: =SUM(B23:B34) -> 256 | C35: =ROUND(AVERAGE(C23:C34),2) -> 1.1
A37: GATILHOS DE PREVENTIVA POR CLASSE (herança cumulativa S ⊂ A ⊂ B)
A38: Classe | B38: Tipo gatilho | C38: Intervalo S | D38: Intervalo A | E38: Intervalo B
A39: Colhedora | B39: Horas | C39: 250 | D39: 500 | E39: 1000
A40: Trator | B40: Horas | C40: 250 | D40: 500 | E40: 1000
A41: Caminhão | B41: KM | C41: 10000 | D41: 20000 | E41: 40000
A42: Implemento | B42: Horas | C42: 300 | D42: 600
A43: Veículo Leve | B43: KM | C43: 10000 | D43: 20000

Sheet Frota
A1: FROTA — cadastro de ativos (motor usa: Status=Ativo, Uso Atual, Uso Semanal Safra/Entressafra, Intervalo)
A2: Uso semanal na unidade do gatilho (Horas ou KM). Intervalo = gatilho S do ativo. Linhas em branco são ignoradas.
A4: Nome | B4: Classe | C4: Modelo | D4: Fabricante | E4: Ano | F4: Filial | G4: Status | H4: Tipo Gatilho | I4: Uso Atual | J4: Uso Semanal Safra | K4: Uso Semanal Entressafra | L4: Intervalo Preventiva | M4: Garantia
A5: Colhedora CASE A8810 — 1035 | B5: Colhedora | C5: CASE A8810 | D5: CASE | E5: 2018 | F5: Sede | G5: Ativo | H5: Horas | I5: 5780 | J5: 45 | K5: 8 | L5: 250 | M5: false
A6: Colhedora CASE A8810 — 1036 | B6: Colhedora | C6: CASE A8810 | D6: CASE | E6: 2019 | F6: Sede | G6: Ativo | H6: Horas | I6: 4490 | J6: 44 | K6: 8 | L6: 250 | M6: false
A7: Colhedora JD CH570 — 1027 | B7: Colhedora | C7: JD CH570 | D7: John Deere | E7: 2017 | F7: Sede | G7: Ativo | H7: Horas | I7: 8860 | J7: 41 | K7: 8 | L7: 250 | M7: false
A8: Colhedora CASE A9000 — 1043 | B8: Colhedora | C8: CASE A9000 | D8: CASE | E8: 2021 | F8: Sede | G8: Ativo | H8: Horas | I8: 1200 | J8: 48 | K8: 8 | L8: 250 | M8: true
A9: Trator NH T7.315 — 401 | B9: Trator | C9: NH T7.315 | D9: New Holland | E9: 2020 | F9: Sede | G9: Ativo | H9: Horas | I9: 3200 | J9: 50 | K9: 12 | L9: 250 | M9: false
A10: Trator NH T7.315 — 402 | B10: Trator | C10: NH T7.315 | D10: New Holland | E10: 2021 | F10: Sede | G10: Ativo | H10: Horas | I10: 2100 | J10: 49 | K10: 12 | L10: 250 | M10: true
A11: Trator Case Puma 175 — 403 | B11: Trator | C11: Case Puma 175 | D11: CASE | E11: 2019 | F11: Sede | G11: Ativo | H11: Horas | I11: 4100 | J11: 46 | K11: 12 | L11: 250 | M11: false
A12: Caminhão Scania G480 — 2748 | B12: Caminhão | C12: Scania G 480 | D12: Scania | E12: 2015 | F12: Sede | G12: Ativo | H12: KM | I12: 304000 | J12: 1400 | K12: 500 | L12: 10000 | M12: false
A13: Caminhão Scania G540 — 2763 | B13: Caminhão | C13: Scania G 540 | D13: Scania | E13: 2020 | F13: Sede | G13: Ativo | H13: KM | I13: 85000 | J13: 1350 | K13: 480 | L13: 10000 | M13: true
A14: Transbordo Mambra 20t — 801 | B14: Implemento | C14: Transbordo 20t | D14: Mambra | E14: 2018 | F14: Sede | G14: Ativo | H14: Horas | I14: 4200 | J14: 40 | K14: 8 | L14: 300 | M14: false
A15: Implemento Distribuidor — 802 | B15: Implemento | C15: Dist. Calcário | D15: Siltres | E15: 2019 | F15: Sede | G15: Ativo | H15: Horas | I15: 2800 | J15: 32 | K15: 6 | L15: 300 | M15: false
A16: Fiat Toro — 5001 | B16: Veículo Leve | C16: Toro Endurance | D16: Fiat | E16: 2022 | F16: Sede | G16: Ativo | H16: KM | I16: 32000 | J16: 700 | K16: 400 | L16: 10000 | M16: true
A17: Toyota Hilux — 5002 | B17: Veículo Leve | C17: Hilux SR | D17: Toyota | E17: 2021 | F17: Sede | G17: Ativo | H17: KM | I17: 48000 | J17: 850 | K17: 450 | L17: 10000 | M17: false

Sheet Pessoas
A1: PESSOAS — equipe de manutenção (custo mensal e custo/hora idênticos ao app)
A4: Nome | B4: Cargo | C4: Oficina | D4: Turno | E4: Salário | F4: Encargos % | G4: Status | H4: Custo Mensal (R$) | I4: Custo/Hora (R$)
A5: Eduardo Lima | B5: Líder de Manutenção | C5: Mec. Oficina | D5: Diurno | E5: 7500 | F5: 72 | G5: Ativo | H5: =IF($A5="","",ROUND(E5*(1+F5/100),2)) -> 12900 | I5: =IF($A5="","",ROUND(H5/MAX(1,(Premissas!$B$35/12)*VLOOKUP(C5,Premissas!$A$14:$K$19,11,0)),2)) -> 112.6
A6: Carlos Rodrigues | B6: Mecânico Sênior | C6: Mec. Oficina | D6: Diurno | E6: 4500 | F6: 72 | G6: Ativo | H6: =IF($A6="","",ROUND(E6*(1+F6/100),2)) -> 7740 | I6: =IF($A6="","",ROUND(H6/MAX(1,(Premissas!$B$35/12)*VLOOKUP(C6,Premissas!$A$14:$K$19,11,0)),2)) -> 67.56
A7: Marcos Ferreira | B7: Mecânico Pleno | C7: Mec. Oficina | D7: Diurno | E7: 3800 | F7: 72 | G7: Ativo | H7: =IF($A7="","",ROUND(E7*(1+F7/100),2)) -> 6536 | I7: =IF($A7="","",ROUND(H7/MAX(1,(Premissas!$B$35/12)*VLOOKUP(C7,Premissas!$A$14:$K$19,11,0)),2)) -> 57.05
A8: João Alves | B8: Mecânico Júnior | C8: Mec. Oficina | D8: Noturno | E8: 3200 | F8: 72 | G8: Ativo | H8: =IF($A8="","",ROUND(E8*(1+F8/100),2)) -> 5504 | I8: =IF($A8="","",ROUND(H8/MAX(1,(Premissas!$B$35/12)*VLOOKUP(C8,Premissas!$A$14:$K$19,11,0)),2)) -> 48.04
A9: André Souza | B9: Mecânico Socorrista | C9: Mec. Campo | D9: Safra | E9: 3800 | F9: 72 | G9: Ativo | H9: =IF($A9="","",ROUND(E9*(1+F9/100),2)) -> 6536 | I9: =IF($A9="","",ROUND(H9/MAX(1,(Premissas!$B$35/12)*VLOOKUP(C9,Premissas!$A$14:$K$19,11,0)),2)) -> 57.59
A10: Paulo Carvalho | B10: Mecânico Socorrista | C10: Mec. Campo | D10: Safra | E10: 3800 | F10: 72 | G10: Ativo | H10: =IF($A10="","",ROUND(E10*(1+F10/100),2)) -> 6536 | I10: =IF($A10="","",ROUND(H10/MAX(1,(Premissas!$B$35/12)*VLOOKUP(C10,Premissas!$A$14:$K$19,11,0)),2)) -> 57.59
A11: Roberto Santos | B11: Eletricista Sênior | C11: Elétrica | D11: Diurno | E11: 5000 | F11: 72 | G11: Ativo | H11: =IF($A11="","",ROUND(E11*(1+F11/100),2)) -> 8600 | I11: =IF($A11="","",ROUND(H11/MAX(1,(Premissas!$B$35/12)*VLOOKUP(C11,Premissas!$A$14:$K$19,11,0)),2)) -> 75.07
A12: Diego Costa | B12: Eletricista Pleno | C12: Elétrica | D12: Diurno | E12: 4200 | F12: 72 | G12: Ativo | H12: =IF($A12="","",ROUND(E12*(1+F12/100),2)) -> 7224 | I12: =IF($A12="","",ROUND(H12/MAX(1,(Premissas!$B$35/12)*VLOOKUP(C12,Premissas!$A$14:$K$19,11,0)),2)) -> 63.06
A13: Marcos Vieira | B13: Lubrificador | C13: Lubrificação | D13: Diurno | E13: 2800 | F13: 72 | G13: Ativo | H13: =IF($A13="","",ROUND(E13*(1+F13/100),2)) -> 4816 | I13: =IF($A13="","",ROUND(H13/MAX(1,(Premissas!$B$35/12)*VLOOKUP(C13,Premissas!$A$14:$K$19,11,0)),2)) -> 37.5
A14: Fábio Nascimento | B14: Lubrificador | C14: Lubrificação | D14: Noturno | E14: 2800 | F14: 72 | G14: Ativo | H14: =IF($A14="","",ROUND(E14*(1+F14/100),2)) -> 4816 | I14: =IF($A14="","",ROUND(H14/MAX(1,(Premissas!$B$35/12)*VLOOKUP(C14,Premissas!$A$14:$K$19,11,0)),2)) -> 37.5
A15: João Borges | B15: Borracheiro | C15: Borracharia | D15: Diurno | E15: 3100 | F15: 72 | G15: Ativo | H15: =IF($A15="","",ROUND(E15*(1+F15/100),2)) -> 5332 | I15: =IF($A15="","",ROUND(H15/MAX(1,(Premissas!$B$35/12)*VLOOKUP(C15,Premissas!$A$14:$K$19,11,0)),2)) -> 43.54
A16: Sérgio Monteiro | B16: Soldador/Caldeireiro Sr. | C16: Caldeiraria | D16: Diurno | E16: 4200 | F16: 72 | G16: Ativo | H16: =IF($A16="","",ROUND(E16*(1+F16/100),2)) -> 7224 | I16: =IF($A16="","",ROUND(H16/MAX(1,(Premissas!$B$35/12)*VLOOKUP(C16,Premissas!$A$14:$K$19,11,0)),2)) -> 64.75
A17: Antônio Silva | B17: Soldador Pleno | C17: Caldeiraria | D17: Diurno | E17: 3500 | F17: 72 | G17: Ativo | H17: =IF($A17="","",ROUND(E17*(1+F17/100),2)) -> 6020 | I17: =IF($A17="","",ROUND(H17/MAX(1,(Premissas!$B$35/12)*VLOOKUP(C17,Premissas!$A$14:$K$19,11,0)),2)) -> 53.96
H18: =IF($A18="","",ROUND(E18*(1+F18/100),2)) | I18: =IF($A18="","",ROUND(H18/MAX(1,(Premissas!$B$35/12)*VLOOKUP(C18,Premissas!$A$14:$K$19,11,0)),2))
H19: =IF($A19="","",ROUND(E19*(1+F19/100),2)) | I19: =IF($A19="","",ROUND(H19/MAX(1,(Premissas!$B$35/12)*VLOOKUP(C19,Premissas!$A$14:$K$19,11,0)),2))
H20: =IF($A20="","",ROUND(E20*(1+F20/100),2)) | I20: =IF($A20="","",ROUND(H20/MAX(1,(Premissas!$B$35/12)*VLOOKUP(C20,Premissas!$A$14:$K$19,11,0)),2))
H21: =IF($A21="","",ROUND(E21*(1+F21/100),2)) | I21: =IF($A21="","",ROUND(H21/MAX(1,(Premissas!$B$35/12)*VLOOKUP(C21,Premissas!$A$14:$K$19,11,0)),2))
H22: =IF($A22="","",ROUND(E22*(1+F22/100),2)) | I22: =IF($A22="","",ROUND(H22/MAX(1,(Premissas!$B$35/12)*VLOOKUP(C22,Premissas!$A$14:$K$19,11,0)),2))
H23: =IF($A23="","",ROUND(E23*(1+F23/100),2)) | I23: =IF($A23="","",ROUND(H23/MAX(1,(Premissas!$B$35/12)*VLOOKUP(C23,Premissas!$A$14:$K$19,11,0)),2))
H24: =IF($A24="","",ROUND(E24*(1+F24/100),2)) | I24: =IF($A24="","",ROUND(H24/MAX(1,(Premissas!$B$35/12)*VLOOKUP(C24,Premissas!$A$14:$K$19,11,0)),2))
H25: =IF($A25="","",ROUND(E25*(1+F25/100),2)) | I25: =IF($A25="","",ROUND(H25/MAX(1,(Premissas!$B$35/12)*VLOOKUP(C25,Premissas!$A$14:$K$19,11,0)),2))
H26: =IF($A26="","",ROUND(E26*(1+F26/100),2)) | I26: =IF($A26="","",ROUND(H26/MAX(1,(Premissas!$B$35/12)*VLOOKUP(C26,Premissas!$A$14:$K$19,11,0)),2))
H27: =IF($A27="","",ROUND(E27*(1+F27/100),2)) | I27: =IF($A27="","",ROUND(H27/MAX(1,(Premissas!$B$35/12)*VLOOKUP(C27,Premissas!$A$14:$K$19,11,0)),2))
H28: =IF($A28="","",ROUND(E28*(1+F28/100),2)) | I28: =IF($A28="","",ROUND(H28/MAX(1,(Premissas!$B$35/12)*VLOOKUP(C28,Premissas!$A$14:$K$19,11,0)),2))
H29: =IF($A29="","",ROUND(E29*(1+F29/100),2)) | I29: =IF($A29="","",ROUND(H29/MAX(1,(Premissas!$B$35/12)*VLOOKUP(C29,Premissas!$A$14:$K$19,11,0)),2))
... H44: =IF($A44="","",ROUND(E44*(1+F44/100),2)) | I44: =IF($A44="","",ROUND(H44/MAX(1,(Premissas!$B$35/12)*VLOOKUP(C44,Premissas!$A$14:$K$19,11,0)),2))

Sheet Checklist
A1: CHECKLIST — atividades por classe × tipo de preventiva (HH alimenta o cronograma com herança cumulativa)
A4: Checklist | B4: Tipo Prev | C4: Classe | D4: Oficina | E4: Atividade | F4: Cargo | G4: Tipo Ativ | H4: HH | I4: Insumo | J4: Qtd Insumo | K4: Un | L4: Peça | M4: Qtd Peça
A5: Rev. S — Colhedora (250h) | B5: S | C5: Colhedora | D5: Mec. Oficina | E5: Troca de óleo do motor | F5: Mecânico Sr. | G5: Troca | H5: 1.5 | I5: Óleo Motor 15W40 | J5: 20 | K5: L | L5: Filtro de óleo | M5: 1
A6: Rev. S — Colhedora (250h) | B6: S | C6: Colhedora | D6: Mec. Oficina | E6: Troca filtro de combustível | F6: Mecânico Pleno | G6: Troca | H6: 0.5 | J6: 0 | L6: Filtro combustível | M6: 1
A7: Rev. S — Colhedora (250h) | B7: S | C7: Colhedora | D7: Mec. Oficina | E7: Inspeção sistema hidráulico | F7: Mecânico Sr. | G7: Inspeção | H7: 1 | J7: 0 | M7: 0
A8: Rev. S — Colhedora (250h) | B8: S | C8: Colhedora | D8: Mec. Oficina | E8: Verificação tensão correntes/correias | F8: Mecânico Pleno | G8: Verificação | H8: 0.75 | J8: 0 | M8: 0
A9: Rev. S — Colhedora (250h) | B9: S | C9: Colhedora | D9: Lubrificação | E9: Lubrificação de pontos fixos | F9: Lubrificador | G9: Lubrificação | H9: 0.75 | I9: Graxa EP2 | J9: 0.5 | K9: kg | M9: 0
A10: Rev. S — Colhedora (250h) | B10: S | C10: Colhedora | D10: Elétrica | E10: Inspeção elétrica geral | F10: Eletricista | G10: Inspeção | H10: 1 | J10: 0 | M10: 0
A11: Rev. A — Colhedora (500h) | B11: A | C11: Colhedora | D11: Mec. Oficina | E11: Troca óleo motor + hidráulico + filtros | F11: Mecânico Sr. | G11: Troca | H11: 3 | I11: Óleo Motor 15W40 | J11: 20 | K11: L | L11: Kit filtros (3 un) | M11: 3
A12: Rev. A — Colhedora (500h) | B12: A | C12: Colhedora | D12: Mec. Oficina | E12: Regulagem sistema de corte | F12: Mecânico Sr. | G12: Regulagem | H12: 2 | J12: 0 | M12: 0
A13: Rev. A — Colhedora (500h) | B13: A | C13: Colhedora | D13: Mec. Oficina | E13: Inspeção e ajuste caixa de câmbio | F13: Mecânico Sr. | G13: Ajuste | H13: 1.5 | I13: Óleo câmbio SAE 90 | J13: 5 | K13: L | M13: 0
A14: Rev. A — Colhedora (500h) | B14: A | C14: Colhedora | D14: Elétrica | E14: Verificação sistema elétrico completo | F14: Eletricista Sr. | G14: Verificação | H14: 2 | J14: 0 | M14: 0
A15: Rev. A — Colhedora (500h) | B15: A | C15: Colhedora | D15: Lubrificação | E15: Lubrificação e troca graxa pivôs | F15: Lubrificador | G15: Lubrificação | H15: 1 | I15: Graxa EP2 | J15: 1 | K15: kg | M15: 0
A16: Rev. S — Trator (250h) | B16: S | C16: Trator | D16: Mec. Oficina | E16: Troca óleo motor | F16: Mecânico Pleno | G16: Troca | H16: 1 | I16: Óleo Motor 10W40 | J16: 12 | K16: L | L16: Filtro de óleo | M16: 1
A17: Rev. S — Trator (250h) | B17: S | C17: Trator | D17: Mec. Oficina | E17: Verificação freios e embreagem | F17: Mecânico Pleno | G17: Verificação | H17: 0.5 | J17: 0 | M17: 0
A18: Rev. S — Trator (250h) | B18: S | C18: Trator | D18: Lubrificação | E18: Lubrificação pontos fixos | F18: Lubrificador | G18: Lubrificação | H18: 0.5 | I18: Graxa EP2 | J18: 0.3 | K18: kg | M18: 0
A19: Rev. S — Caminhão (10Kkm) | B19: S | C19: Caminhão | D19: Mec. Oficina | E19: Troca óleo motor + filtro | F19: Mecânico Pleno | G19: Troca | H19: 1.5 | I19: Óleo Motor 15W40 | J19: 25 | K19: L | L19: Filtro de óleo | M19: 1
A20: Rev. S — Caminhão (10Kkm) | B20: S | C20: Caminhão | D20: Mec. Oficina | E20: Inspeção sistema de freios | F20: Mecânico Pleno | G20: Inspeção | H20: 0.75 | J20: 0 | M20: 0
A21: Rev. S — Caminhão (10Kkm) | B21: S | C21: Caminhão | D21: Borracharia | E21: Calibragem e inspeção de pneus | F21: Borracheiro | G21: Calibragem | H21: 0.5 | J21: 0 | M21: 0
A22: Rev. S — Caminhão (10Kkm) | B22: S | C22: Caminhão | D22: Lubrificação | E22: Lubrificação chassi e 5ª roda | F22: Lubrificador | G22: Lubrificação | H22: 0.5 | I22: Graxa EP2 | J22: 0.5 | K22: kg | M22: 0
A23: Rev. A — Caminhão (20Kkm) | B23: A | C23: Caminhão | D23: Mec. Oficina | E23: Troca óleo + filtros + filtro ar | F23: Mecânico Sr. | G23: Troca | H23: 2.5 | I23: Óleo Motor 15W40 | J23: 25 | K23: L | L23: Kit filtros (2un) | M23: 2
A24: Rev. A — Caminhão (20Kkm) | B24: A | C24: Caminhão | D24: Mec. Oficina | E24: Regulagem freios e embreagem | F24: Mecânico Sr. | G24: Regulagem | H24: 1.5 | I24: Fluido de freio | J24: 0.5 | K24: L | M24: 0
A25: Rev. A — Caminhão (20Kkm) | B25: A | C25: Caminhão | D25: Elétrica | E25: Verificação sistema elétrico + bateria | F25: Eletricista | G25: Verificação | H25: 1 | J25: 0 | M25: 0
A26: Rev. S — Implemento (300h) | B26: S | C26: Implemento | D26: Caldeiraria | E26: Inspeção estrutural e solda | F26: Soldador Sr. | G26: Inspeção | H26: 1.5 | J26: 0 | M26: 0
A27: Rev. S — Implemento (300h) | B27: S | C27: Implemento | D27: Mec. Oficina | E27: Verificação sistema hidráulico | F27: Mecânico Pleno | G27: Verificação | H27: 0.75 | I27: Óleo hidráulico | J27: 2 | K27: L | M27: 0
A28: Rev. S — Implemento (300h) | B28: S | C28: Implemento | D28: Lubrificação | E28: Lubrificação rolamentos e articulações | F28: Lubrificador | G28: Lubrificação | H28: 0.5 | I28: Graxa EP2 | J28: 0.3 | K28: kg | M28: 0

Sheet Semanas
A1: AUXILIAR — 52 semanas a partir do início da safra
A2: Semana | B2: Data início | C2: Data fim | D2: Safra (1/0) | E2: Mês (1-12)
A3: 1 | B3: =DATE(VALUE(LEFT(Premissas!$G$21,4)),VALUE(MID(Premissas!$G$21,6,2)),VALUE(RIGHT(Premissas!$G$21,2))) -> 45748 | C3: =B3+6 -> 45754 | D3: =IF(AND(B3>=$B$3,B3<=DATE(VALUE(LEFT(Premissas!$G$22,4)),VALUE(MID(Premissas!$G$22,6,2)),VALUE(RIGHT(Premissas!$G$22,2)))),1,0) -> 1 | E3: =MONTH(B3) -> 4
A4: 2 | B4: =B3+7 -> 45755 | C4: =B4+6 -> 45761 | D4: =IF(AND(B4>=$B$3,B4<=DATE(VALUE(LEFT(Premissas!$G$22,4)),VALUE(MID(Premissas!$G$22,6,2)),VALUE(RIGHT(Premissas!$G$22,2)))),1,0) -> 1 | E4: =MONTH(B4) -> 4
A5: 3 | B5: =B4+7 -> 45762 | C5: =B5+6 -> 45768 | D5: =IF(AND(B5>=$B$3,B5<=DATE(VALUE(LEFT(Premissas!$G$22,4)),VALUE(MID(Premissas!$G$22,6,2)),VALUE(RIGHT(Premissas!$G$22,2)))),1,0) -> 1 | E5: =MONTH(B5) -> 4
A6: 4 | B6: =B5+7 -> 45769 | C6: =B6+6 -> 45775 | D6: =IF(AND(B6>=$B$3,B6<=DATE(VALUE(LEFT(Premissas!$G$22,4)),VALUE(MID(Premissas!$G$22,6,2)),VALUE(RIGHT(Premissas!$G$22,2)))),1,0) -> 1 | E6: =MONTH(B6) -> 4
A7: 5 | B7: =B6+7 -> 45776 | C7: =B7+6 -> 45782 | D7: =IF(AND(B7>=$B$3,B7<=DATE(VALUE(LEFT(Premissas!$G$22,4)),VALUE(MID(Premissas!$G$22,6,2)),VALUE(RIGHT(Premissas!$G$22,2)))),1,0) -> 1 | E7: =MONTH(B7) -> 4
A8: 6 | B8: =B7+7 -> 45783 | C8: =B8+6 -> 45789 | D8: =IF(AND(B8>=$B$3,B8<=DATE(VALUE(LEFT(Premissas!$G$22,4)),VALUE(MID(Premissas!$G$22,6,2)),VALUE(RIGHT(Premissas!$G$22,2)))),1,0) -> 1 | E8: =MONTH(B8) -> 5
A9: 7 | B9: =B8+7 -> 45790 | C9: =B9+6 -> 45796 | D9: =IF(AND(B9>=$B$3,B9<=DATE(VALUE(LEFT(Premissas!$G$22,4)),VALUE(MID(Premissas!$G$22,6,2)),VALUE(RIGHT(Premissas!$G$22,2)))),1,0) -> 1 | E9: =MONTH(B9) -> 5
A10: 8 | B10: =B9+7 -> 45797 | C10: =B10+6 -> 45803 | D10: =IF(AND(B10>=$B$3,B10<=DATE(VALUE(LEFT(Premissas!$G$22,4)),VALUE(MID(Premissas!$G$22,6,2)),VALUE(RIGHT(Premissas!$G$22,2)))),1,0) -> 1 | E10: =MONTH(B10) -> 5
A11: 9 | B11: =B10+7 -> 45804 | C11: =B11+6 -> 45810 | D11: =IF(AND(B11>=$B$3,B11<=DATE(VALUE(LEFT(Premissas!$G$22,4)),VALUE(MID(Premissas!$G$22,6,2)),VALUE(RIGHT(Premissas!$G$22,2)))),1,0) -> 1 | E11: =MONTH(B11) -> 5
A12: 10 | B12: =B11+7 -> 45811 | C12: =B12+6 -> 45817 | D12: =IF(AND(B12>=$B$3,B12<=DATE(VALUE(LEFT(Premissas!$G$22,4)),VALUE(MID(Premissas!$G$22,6,2)),VALUE(RIGHT(Premissas!$G$22,2)))),1,0) -> 1 | E12: =MONTH(B12) -> 6
A13: 11 | B13: =B12+7 -> 45818 | C13: =B13+6 -> 45824 | D13: =IF(AND(B13>=$B$3,B13<=DATE(VALUE(LEFT(Premissas!$G$22,4)),VALUE(MID(Premissas!$G$22,6,2)),VALUE(RIGHT(Premissas!$G$22,2)))),1,0) -> 1 | E13: =MONTH(B13) -> 6
A14: 12 | B14: =B13+7 -> 45825 | C14: =B14+6 -> 45831 | D14: =IF(AND(B14>=$B$3,B14<=DATE(VALUE(LEFT(Premissas!$G$22,4)),VALUE(MID(Premissas!$G$22,6,2)),VALUE(RIGHT(Premissas!$G$22,2)))),1,0) -> 1 | E14: =MONTH(B14) -> 6
A15: 13 | B15: =B14+7 -> 45832 | C15: =B15+6 -> 45838 | D15: =IF(AND(B15>=$B$3,B15<=DATE(VALUE(LEFT(Premissas!$G$22,4)),VALUE(MID(Premissas!$G$22,6,2)),VALUE(RIGHT(Premissas!$G$22,2)))),1,0) -> 1 | E15: =MONTH(B15) -> 6
... A54: 52 | B54: =B53+7 -> 46105 | C54: =B54+6 -> 46111 | D54: =IF(AND(B54>=$B$3,B54<=DATE(VALUE(LEFT(Premissas!$G$22,4)),VALUE(MID(Premissas!$G$22,6,2)),VALUE(RIGHT(Premissas!$G$22,2)))),1,0) -> 0 | E54: =MONTH(B54) -> 3

Sheet Cron_Uso
A1: AUXILIAR — uso acumulado por ativo × semana (fim da semana)
A2: Mês → | B2: =INDEX(Semanas!$E$3:$E$54,1) -> 4 | C2: =INDEX(Semanas!$E$3:$E$54,2) -> 4 | D2: =INDEX(Semanas!$E$3:$E$54,3) -> 4 | E2: =INDEX(Semanas!$E$3:$E$54,4) -> 4 | F2: =INDEX(Semanas!$E$3:$E$54,5) -> 4 | G2: =INDEX(Semanas!$E$3:$E$54,6) -> 5 | H2: =INDEX(Semanas!$E$3:$E$54,7) -> 5 | I2: =INDEX(Semanas!$E$3:$E$54,8) -> 5 | J2: =INDEX(Semanas!$E$3:$E$54,9) -> 5 | K2: =INDEX(Semanas!$E$3:$E$54,10) -> 6 | L2: =INDEX(Semanas!$E$3:$E$54,11) -> 6 | M2: =INDEX(Semanas!$E$3:$E$54,12) -> 6 | N2: =INDEX(Semanas!$E$3:$E$54,13) -> 6 | O2: =INDEX(Semanas!$E$3:$E$54,14) -> 7 | P2: =INDEX(Semanas!$E$3:$E$54,15) -> 7 | Q2: =INDEX(Semanas!$E$3:$E$54,16) -> 7 | R2: =INDEX(Semanas!$E$3:$E$54,17) -> 7 | S2: =INDEX(Semanas!$E$3:$E$54,18) -> 7 | T2: =INDEX(Semanas!$E$3:$E$54,19) -> 8 | U2: =INDEX(Semanas!$E$3:$E$54,20) -> 8 | V2: =INDEX(Semanas!$E$3:$E$54,21) -> 8 | W2: =INDEX(Semanas!$E$3:$E$54,22) -> 8 | X2: =INDEX(Semanas!$E$3:$E$54,23) -> 9 | Y2: =INDEX(Semanas!$E$3:$E$54,24) -> 9 | Z2: =INDEX(Semanas!$E$3:$E$54,25) -> 9 | AA2: =INDEX(Semanas!$E$3:$E$54,26) -> 9 | AB2: =INDEX(Semanas!$E$3:$E$54,27) -> 9 | AC2: =INDEX(Semanas!$E$3:$E$54,28) -> 10 | AD2: =INDEX(Semanas!$E$3:$E$54,29) -> 10 | AE2: =INDEX(Semanas!$E$3:$E$54,30) -> 10 | AF2: =INDEX(Semanas!$E$3:$E$54,31) -> 10 | AG2: =INDEX(Semanas!$E$3:$E$54,32) -> 11 | AH2: =INDEX(Semanas!$E$3:$E$54,33) -> 11 | AI2: =INDEX(Semanas!$E$3:$E$54,34) -> 11 | AJ2: =INDEX(Semanas!$E$3:$E$54,35) -> 11 | AK2: =INDEX(Semanas!$E$3:$E$54,36) -> 12 | AL2: =INDEX(Semanas!$E$3:$E$54,37) -> 12 | AM2: =INDEX(Semanas!$E$3:$E$54,38) -> 12 | AN2: =INDEX(Semanas!$E$3:$E$54,39) -> 12 | AO2: =INDEX(Semanas!$E$3:$E$54,40) -> 12 | AP2: =INDEX(Semanas!$E$3:$E$54,41) -> 1 | AQ2: =INDEX(Semanas!$E$3:$E$54,42) -> 1 | AR2: =INDEX(Semanas!$E$3:$E$54,43) -> 1 | AS2: =INDEX(Semanas!$E$3:$E$54,44) -> 1 | AT2: =INDEX(Semanas!$E$3:$E$54,45) -> 2 | AU2: =INDEX(Semanas!$E$3:$E$54,46) -> 2 | AV2: =INDEX(Semanas!$E$3:$E$54,47) -> 2 | AW2: =INDEX(Semanas!$E$3:$E$54,48) -> 2 | AX2: =INDEX(Semanas!$E$3:$E$54,49) -> 3 | AY2: =INDEX(Semanas!$E$3:$E$54,50) -> 3 | AZ2: =INDEX(Semanas!$E$3:$E$54,51) -> 3 | BA2: =INDEX(Semanas!$E$3:$E$54,52) -> 3
A3: Safra → | B3: =INDEX(Semanas!$D$3:$D$54,1) -> 1 | C3: =INDEX(Semanas!$D$3:$D$54,2) -> 1 | D3: =INDEX(Semanas!$D$3:$D$54,3) -> 1 | E3: =INDEX(Semanas!$D$3:$D$54,4) -> 1 | F3: =INDEX(Semanas!$D$3:$D$54,5) -> 1 | G3: =INDEX(Semanas!$D$3:$D$54,6) -> 1 | H3: =INDEX(Semanas!$D$3:$D$54,7) -> 1 | I3: =INDEX(Semanas!$D$3:$D$54,8) -> 1 | J3: =INDEX(Semanas!$D$3:$D$54,9) -> 1 | K3: =INDEX(Semanas!$D$3:$D$54,10) -> 1 | L3: =INDEX(Semanas!$D$3:$D$54,11) -> 1 | M3: =INDEX(Semanas!$D$3:$D$54,12) -> 1 | N3: =INDEX(Semanas!$D$3:$D$54,13) -> 1 | O3: =INDEX(Semanas!$D$3:$D$54,14) -> 1 | P3: =INDEX(Semanas!$D$3:$D$54,15) -> 1 | Q3: =INDEX(Semanas!$D$3:$D$54,16) -> 1 | R3: =INDEX(Semanas!$D$3:$D$54,17) -> 1 | S3: =INDEX(Semanas!$D$3:$D$54,18) -> 1 | T3: =INDEX(Semanas!$D$3:$D$54,19) -> 1 | U3: =INDEX(Semanas!$D$3:$D$54,20) -> 1 | V3: =INDEX(Semanas!$D$3:$D$54,21) -> 1 | W3: =INDEX(Semanas!$D$3:$D$54,22) -> 1 | X3: =INDEX(Semanas!$D$3:$D$54,23) -> 1 | Y3: =INDEX(Semanas!$D$3:$D$54,24) -> 1 | Z3: =INDEX(Semanas!$D$3:$D$54,25) -> 1 | AA3: =INDEX(Semanas!$D$3:$D$54,26) -> 1 | AB3: =INDEX(Semanas!$D$3:$D$54,27) -> 1 | AC3: =INDEX(Semanas!$D$3:$D$54,28) -> 1 | AD3: =INDEX(Semanas!$D$3:$D$54,29) -> 1 | AE3: =INDEX(Semanas!$D$3:$D$54,30) -> 1 | AF3: =INDEX(Semanas!$D$3:$D$54,31) -> 1 | AG3: =INDEX(Semanas!$D$3:$D$54,32) -> 1 | AH3: =INDEX(Semanas!$D$3:$D$54,33) -> 1 | AI3: =INDEX(Semanas!$D$3:$D$54,34) -> 1 | AJ3: =INDEX(Semanas!$D$3:$D$54,35) -> 1 | AK3: =INDEX(Semanas!$D$3:$D$54,36) -> 0 | AL3: =INDEX(Semanas!$D$3:$D$54,37) -> 0 | AM3: =INDEX(Semanas!$D$3:$D$54,38) -> 0 | AN3: =INDEX(Semanas!$D$3:$D$54,39) -> 0 | AO3: =INDEX(Semanas!$D$3:$D$54,40) -> 0 | AP3: =INDEX(Semanas!$D$3:$D$54,41) -> 0 | AQ3: =INDEX(Semanas!$D$3:$D$54,42) -> 0 | AR3: =INDEX(Semanas!$D$3:$D$54,43) -> 0 | AS3: =INDEX(Semanas!$D$3:$D$54,44) -> 0 | AT3: =INDEX(Semanas!$D$3:$D$54,45) -> 0 | AU3: =INDEX(Semanas!$D$3:$D$54,46) -> 0 | AV3: =INDEX(Semanas!$D$3:$D$54,47) -> 0 | AW3: =INDEX(Semanas!$D$3:$D$54,48) -> 0 | AX3: =INDEX(Semanas!$D$3:$D$54,49) -> 0 | AY3: =INDEX(Semanas!$D$3:$D$54,50) -> 0 | AZ3: =INDEX(Semanas!$D$3:$D$54,51) -> 0 | BA3: =INDEX(Semanas!$D$3:$D$54,52) -> 0
A4: Ativo | B4: S01 | C4: S02 | D4: S03 | E4: S04 | F4: S05 | G4: S06 | H4: S07 | I4: S08 | J4: S09 | K4: S10 | L4: S11 | M4: S12 | N4: S13 | O4: S14 | P4: S15 | Q4: S16 | R4: S17 | S4: S18 | T4: S19 | U4: S20 | V4: S21 | W4: S22 | X4: S23 | Y4: S24 | Z4: S25 | AA4: S26 | AB4: S27 | AC4: S28 | AD4: S29 | AE4: S30 | AF4: S31 | AG4: S32 | AH4: S33 | AI4: S34 | AJ4: S35 | AK4: S36 | AL4: S37 | AM4: S38 | AN4: S39 | AO4: S40 | AP4: S41 | AQ4: S42 | AR4: S43 | AS4: S44 | AT4: S45 | AU4: S46 | AV4: S47 | AW4: S48 | AX4: S49 | AY4: S50 | AZ4: S51 | BA4: S52
A5: =IF(Frota!$A5="","",Frota!$A5) -> Colhedora CASE A8810 — 1035 | B5: =IF(OR(Frota!$A5="",Frota!$G5<>"Ativo",N(Frota!$L5)=0),"",ROUND(Frota!$I5+IF(B$3=1,N(Frota!$J5),N(Frota!$K5)),2)) -> 5825 | C5: =IF(B5="","",ROUND(B5+IF(C$3=1,N(Frota!$J5),N(Frota!$K5)),2)) -> 5870 | D5: =IF(C5="","",ROUND(C5+IF(D$3=1,N(Frota!$J5),N(Frota!$K5)),2)) -> 5915 | E5: =IF(D5="","",ROUND(D5+IF(E$3=1,N(Frota!$J5),N(Frota!$K5)),2)) -> 5960 | F5: =IF(E5="","",ROUND(E5+IF(F$3=1,N(Frota!$J5),N(Frota!$K5)),2)) -> 6005 | G5: =IF(F5="","",ROUND(F5+IF(G$3=1,N(Frota!$J5),N(Frota!$K5)),2)) -> 6050 | H5: =IF(G5="","",ROUND(G5+IF(H$3=1,N(Frota!$J5),N(Frota!$K5)),2)) -> 6095 | I5: =IF(H5="","",ROUND(H5+IF(I$3=1,N(Frota!$J5),N(Frota!$K5)),2)) -> 6140 | J5: =IF(I5="","",ROUND(I5+IF(J$3=1,N(Frota!$J5),N(Frota!$K5)),2)) -> 6185 | ... BA5: =IF(AZ5="","",ROUND(AZ5+IF(BA$3=1,N(Frota!$J5),N(Frota!$K5)),2)) -> 7491
A6: =IF(Frota!$A6="","",Frota!$A6) -> Colhedora CASE A8810 — 1036 | B6: =IF(OR(Frota!$A6="",Frota!$G6<>"Ativo",N(Frota!$L6)=0),"",ROUND(Frota!$I6+IF(B$3=1,N(Frota!$J6),N(Frota!$K6)),2)) -> 4534 | C6: =IF(B6="","",ROUND(B6+IF(C$3=1,N(Frota!$J6),N(Frota!$K6)),2)) -> 4578 | D6: =IF(C6="","",ROUND(C6+IF(D$3=1,N(Frota!$J6),N(Frota!$K6)),2)) -> 4622 | E6: =IF(D6="","",ROUND(D6+IF(E$3=1,N(Frota!$J6),N(Frota!$K6)),2)) -> 4666 | F6: =IF(E6="","",ROUND(E6+IF(F$3=1,N(Frota!$J6),N(Frota!$K6)),2)) -> 4710 | G6: =IF(F6="","",ROUND(F6+IF(G$3=1,N(Frota!$J6),N(Frota!$K6)),2)) -> 4754 | H6: =IF(G6="","",ROUND(G6+IF(H$3=1,N(Frota!$J6),N(Frota!$K6)),2)) -> 4798 | I6: =IF(H6="","",ROUND(H6+IF(I$3=1,N(Frota!$J6),N(Frota!$K6)),2)) -> 4842 | J6: =IF(I6="","",ROUND(I6+IF(J$3=1,N(Frota!$J6),N(Frota!$K6)),2)) -> 4886 | ... BA6: =IF(AZ6="","",ROUND(AZ6+IF(BA$3=1,N(Frota!$J6),N(Frota!$K6)),2)) -> 6166
A7: =IF(Frota!$A7="","",Frota!$A7) -> Colhedora JD CH570 — 1027 | B7: =IF(OR(Frota!$A7="",Frota!$G7<>"Ativo",N(Frota!$L7)=0),"",ROUND(Frota!$I7+IF(B$3=1,N(Frota!$J7),N(Frota!$K7)),2)) -> 8901 | C7: =IF(B7="","",ROUND(B7+IF(C$3=1,N(Frota!$J7),N(Frota!$K7)),2)) -> 8942 | D7: =IF(C7="","",ROUND(C7+IF(D$3=1,N(Frota!$J7),N(Frota!$K7)),2)) -> 8983 | E7: =IF(D7="","",ROUND(D7+IF(E$3=1,N(Frota!$J7),N(Frota!$K7)),2)) -> 9024 | F7: =IF(E7="","",ROUND(E7+IF(F$3=1,N(Frota!$J7),N(Frota!$K7)),2)) -> 9065 | G7: =IF(F7="","",ROUND(F7+IF(G$3=1,N(Frota!$J7),N(Frota!$K7)),2)) -> 9106 | H7: =IF(G7="","",ROUND(G7+IF(H$3=1,N(Frota!$J7),N(Frota!$K7)),2)) -> 9147 | I7: =IF(H7="","",ROUND(H7+IF(I$3=1,N(Frota!$J7),N(Frota!$K7)),2)) -> 9188 | J7: =IF(I7="","",ROUND(I7+IF(J$3=1,N(Frota!$J7),N(Frota!$K7)),2)) -> 9229 | ... BA7: =IF(AZ7="","",ROUND(AZ7+IF(BA$3=1,N(Frota!$J7),N(Frota!$K7)),2)) -> 10431
A8: =IF(Frota!$A8="","",Frota!$A8) -> Colhedora CASE A9000 — 1043 | B8: =IF(OR(Frota!$A8="",Frota!$G8<>"Ativo",N(Frota!$L8)=0),"",ROUND(Frota!$I8+IF(B$3=1,N(Frota!$J8),N(Frota!$K8)),2)) -> 1248 | C8: =IF(B8="","",ROUND(B8+IF(C$3=1,N(Frota!$J8),N(Frota!$K8)),2)) -> 1296 | D8: =IF(C8="","",ROUND(C8+IF(D$3=1,N(Frota!$J8),N(Frota!$K8)),2)) -> 1344 | E8: =IF(D8="","",ROUND(D8+IF(E$3=1,N(Frota!$J8),N(Frota!$K8)),2)) -> 1392 | F8: =IF(E8="","",ROUND(E8+IF(F$3=1,N(Frota!$J8),N(Frota!$K8)),2)) -> 1440 | G8: =IF(F8="","",ROUND(F8+IF(G$3=1,N(Frota!$J8),N(Frota!$K8)),2)) -> 1488 | H8: =IF(G8="","",ROUND(G8+IF(H$3=1,N(Frota!$J8),N(Frota!$K8)),2)) -> 1536 | I8: =IF(H8="","",ROUND(H8+IF(I$3=1,N(Frota!$J8),N(Frota!$K8)),2)) -> 1584 | J8: =IF(I8="","",ROUND(I8+IF(J$3=1,N(Frota!$J8),N(Frota!$K8)),2)) -> 1632 | ... BA8: =IF(AZ8="","",ROUND(AZ8+IF(BA$3=1,N(Frota!$J8),N(Frota!$K8)),2)) -> 3016
A9: =IF(Frota!$A9="","",Frota!$A9) -> Trator NH T7.315 — 401 | B9: =IF(OR(Frota!$A9="",Frota!$G9<>"Ativo",N(Frota!$L9)=0),"",ROUND(Frota!$I9+IF(B$3=1,N(Frota!$J9),N(Frota!$K9)),2)) -> 3250 | C9: =IF(B9="","",ROUND(B9+IF(C$3=1,N(Frota!$J9),N(Frota!$K9)),2)) -> 3300 | D9: =IF(C9="","",ROUND(C9+IF(D$3=1,N(Frota!$J9),N(Frota!$K9)),2)) -> 3350 | E9: =IF(D9="","",ROUND(D9+IF(E$3=1,N(Frota!$J9),N(Frota!$K9)),2)) -> 3400 | F9: =IF(E9="","",ROUND(E9+IF(F$3=1,N(Frota!$J9),N(Frota!$K9)),2)) -> 3450 | G9: =IF(F9="","",ROUND(F9+IF(G$3=1,N(Frota!$J9),N(Frota!$K9)),2)) -> 3500 | H9: =IF(G9="","",ROUND(G9+IF(H$3=1,N(Frota!$J9),N(Frota!$K9)),2)) -> 3550 | I9: =IF(H9="","",ROUND(H9+IF(I$3=1,N(Frota!$J9),N(Frota!$K9)),2)) -> 3600 | J9: =IF(I9="","",ROUND(I9+IF(J$3=1,N(Frota!$J9),N(Frota!$K9)),2)) -> 3650 | ... BA9: =IF(AZ9="","",ROUND(AZ9+IF(BA$3=1,N(Frota!$J9),N(Frota!$K9)),2)) -> 5154
A10: =IF(Frota!$A10="","",Frota!$A10) -> Trator NH T7.315 — 402 | B10: =IF(OR(Frota!$A10="",Frota!$G10<>"Ativo",N(Frota!$L10)=0),"",ROUND(Frota!$I10+IF(B$3=1,N(Frota!$J10),N(Frota!$K10)),2)) -> 2149 | C10: =IF(B10="","",ROUND(B10+IF(C$3=1,N(Frota!$J10),N(Frota!$K10)),2)) -> 2198 | D10: =IF(C10="","",ROUND(C10+IF(D$3=1,N(Frota!$J10),N(Frota!$K10)),2)) -> 2247 | E10: =IF(D10="","",ROUND(D10+IF(E$3=1,N(Frota!$J10),N(Frota!$K10)),2)) -> 2296 | F10: =IF(E10="","",ROUND(E10+IF(F$3=1,N(Frota!$J10),N(Frota!$K10)),2)) -> 2345 | G10: =IF(F10="","",ROUND(F10+IF(G$3=1,N(Frota!$J10),N(Frota!$K10)),2)) -> 2394 | H10: =IF(G10="","",ROUND(G10+IF(H$3=1,N(Frota!$J10),N(Frota!$K10)),2)) -> 2443 | I10: =IF(H10="","",ROUND(H10+IF(I$3=1,N(Frota!$J10),N(Frota!$K10)),2)) -> 2492 | J10: =IF(I10="","",ROUND(I10+IF(J$3=1,N(Frota!$J10),N(Frota!$K10)),2)) -> 2541 | ... BA10: =IF(AZ10="","",ROUND(AZ10+IF(BA$3=1,N(Frota!$J10),N(Frota!$K10)),2)) -> 4019
A11: =IF(Frota!$A11="","",Frota!$A11) -> Trator Case Puma 175 — 403 | B11: =IF(OR(Frota!$A11="",Frota!$G11<>"Ativo",N(Frota!$L11)=0),"",ROUND(Frota!$I11+IF(B$3=1,N(Frota!$J11),N(Frota!$K11)),2)) -> 4146 | C11: =IF(B11="","",ROUND(B11+IF(C$3=1,N(Frota!$J11),N(Frota!$K11)),2)) -> 4192 | D11: =IF(C11="","",ROUND(C11+IF(D$3=1,N(Frota!$J11),N(Frota!$K11)),2)) -> 4238 | E11: =IF(D11="","",ROUND(D11+IF(E$3=1,N(Frota!$J11),N(Frota!$K11)),2)) -> 4284 | F11: =IF(E11="","",ROUND(E11+IF(F$3=1,N(Frota!$J11),N(Frota!$K11)),2)) -> 4330 | G11: =IF(F11="","",ROUND(F11+IF(G$3=1,N(Frota!$J11),N(Frota!$K11)),2)) -> 4376 | H11: =IF(G11="","",ROUND(G11+IF(H$3=1,N(Frota!$J11),N(Frota!$K11)),2)) -> 4422 | I11: =IF(H11="","",ROUND(H11+IF(I$3=1,N(Frota!$J11),N(Frota!$K11)),2)) -> 4468 | J11: =IF(I11="","",ROUND(I11+IF(J$3=1,N(Frota!$J11),N(Frota!$K11)),2)) -> 4514 | ... BA11: =IF(AZ11="","",ROUND(AZ11+IF(BA$3=1,N(Frota!$J11),N(Frota!$K11)),2)) -> 5914
A12: =IF(Frota!$A12="","",Frota!$A12) -> Caminhão Scania G480 — 2748 | B12: =IF(OR(Frota!$A12="",Frota!$G12<>"Ativo",N(Frota!$L12)=0),"",ROUND(Frota!$I12+IF(B$3=1,N(Frota!$J12),N(Frota!$K12)),2)) -> 305400 | C12: =IF(B12="","",ROUND(B12+IF(C$3=1,N(Frota!$J12),N(Frota!$K12)),2)) -> 306800 | D12: =IF(C12="","",ROUND(C12+IF(D$3=1,N(Frota!$J12),N(Frota!$K12)),2)) -> 308200 | E12: =IF(D12="","",ROUND(D12+IF(E$3=1,N(Frota!$J12),N(Frota!$K12)),2)) -> 309600 | F12: =IF(E12="","",ROUND(E12+IF(F$3=1,N(Frota!$J12),N(Frota!$K12)),2)) -> 311000 | G12: =IF(F12="","",ROUND(F12+IF(G$3=1,N(Frota!$J12),N(Frota!$K12)),2)) -> 312400 | H12: =IF(G12="","",ROUND(G12+IF(H$3=1,N(Frota!$J12),N(Frota!$K12)),2)) -> 313800 | I12: =IF(H12="","",ROUND(H12+IF(I$3=1,N(Frota!$J12),N(Frota!$K12)),2)) -> 315200 | J12: =IF(I12="","",ROUND(I12+IF(J$3=1,N(Frota!$J12),N(Frota!$K12)),2)) -> 316600 | ... BA12: =IF(AZ12="","",ROUND(AZ12+IF(BA$3=1,N(Frota!$J12),N(Frota!$K12)),2)) -> 361500
A13: =IF(Frota!$A13="","",Frota!$A13) -> Caminhão Scania G540 — 2763 | B13: =IF(OR(Frota!$A13="",Frota!$G13<>"Ativo",N(Frota!$L13)=0),"",ROUND(Frota!$I13+IF(B$3=1,N(Frota!$J13),N(Frota!$K13)),2)) -> 86350 | C13: =IF(B13="","",ROUND(B13+IF(C$3=1,N(Frota!$J13),N(Frota!$K13)),2)) -> 87700 | D13: =IF(C13="","",ROUND(C13+IF(D$3=1,N(Frota!$J13),N(Frota!$K13)),2)) -> 89050 | E13: =IF(D13="","",ROUND(D13+IF(E$3=1,N(Frota!$J13),N(Frota!$K13)),2)) -> 90400 | F13: =IF(E13="","",ROUND(E13+IF(F$3=1,N(Frota!$J13),N(Frota!$K13)),2)) -> 91750 | G13: =IF(F13="","",ROUND(F13+IF(G$3=1,N(Frota!$J13),N(Frota!$K13)),2)) -> 93100 | H13: =IF(G13="","",ROUND(G13+IF(H$3=1,N(Frota!$J13),N(Frota!$K13)),2)) -> 94450 | I13: =IF(H13="","",ROUND(H13+IF(I$3=1,N(Frota!$J13),N(Frota!$K13)),2)) -> 95800 | J13: =IF(I13="","",ROUND(I13+IF(J$3=1,N(Frota!$J13),N(Frota!$K13)),2)) -> 97150 | ... BA13: =IF(AZ13="","",ROUND(AZ13+IF(BA$3=1,N(Frota!$J13),N(Frota!$K13)),2)) -> 140410
A14: =IF(Frota!$A14="","",Frota!$A14) -> Transbordo Mambra 20t — 801 | B14: =IF(OR(Frota!$A14="",Frota!$G14<>"Ativo",N(Frota!$L14)=0),"",ROUND(Frota!$I14+IF(B$3=1,N(Frota!$J14),N(Frota!$K14)),2)) -> 4240 | C14: =IF(B14="","",ROUND(B14+IF(C$3=1,N(Frota!$J14),N(Frota!$K14)),2)) -> 4280 | D14: =IF(C14="","",ROUND(C14+IF(D$3=1,N(Frota!$J14),N(Frota!$K14)),2)) -> 4320 | E14: =IF(D14="","",ROUND(D14+IF(E$3=1,N(Frota!$J14),N(Frota!$K14)),2)) -> 4360 | F14: =IF(E14="","",ROUND(E14+IF(F$3=1,N(Frota!$J14),N(Frota!$K14)),2)) -> 4400 | G14: =IF(F14="","",ROUND(F14+IF(G$3=1,N(Frota!$J14),N(Frota!$K14)),2)) -> 4440 | H14: =IF(G14="","",ROUND(G14+IF(H$3=1,N(Frota!$J14),N(Frota!$K14)),2)) -> 4480 | I14: =IF(H14="","",ROUND(H14+IF(I$3=1,N(Frota!$J14),N(Frota!$K14)),2)) -> 4520 | J14: =IF(I14="","",ROUND(I14+IF(J$3=1,N(Frota!$J14),N(Frota!$K14)),2)) -> 4560 | ... BA14: =IF(AZ14="","",ROUND(AZ14+IF(BA$3=1,N(Frota!$J14),N(Frota!$K14)),2)) -> 5736
A15: =IF(Frota!$A15="","",Frota!$A15) -> Implemento Distribuidor — 802 | B15: =IF(OR(Frota!$A15="",Frota!$G15<>"Ativo",N(Frota!$L15)=0),"",ROUND(Frota!$I15+IF(B$3=1,N(Frota!$J15),N(Frota!$K15)),2)) -> 2832 | C15: =IF(B15="","",ROUND(B15+IF(C$3=1,N(Frota!$J15),N(Frota!$K15)),2)) -> 2864 | D15: =IF(C15="","",ROUND(C15+IF(D$3=1,N(Frota!$J15),N(Frota!$K15)),2)) -> 2896 | E15: =IF(D15="","",ROUND(D15+IF(E$3=1,N(Frota!$J15),N(Frota!$K15)),2)) -> 2928 | F15: =IF(E15="","",ROUND(E15+IF(F$3=1,N(Frota!$J15),N(Frota!$K15)),2)) -> 2960 | G15: =IF(F15="","",ROUND(F15+IF(G$3=1,N(Frota!$J15),N(Frota!$K15)),2)) -> 2992 | H15: =IF(G15="","",ROUND(G15+IF(H$3=1,N(Frota!$J15),N(Frota!$K15)),2)) -> 3024 | I15: =IF(H15="","",ROUND(H15+IF(I$3=1,N(Frota!$J15),N(Frota!$K15)),2)) -> 3056 | J15: =IF(I15="","",ROUND(I15+IF(J$3=1,N(Frota!$J15),N(Frota!$K15)),2)) -> 3088 | ... BA15: =IF(AZ15="","",ROUND(AZ15+IF(BA$3=1,N(Frota!$J15),N(Frota!$K15)),2)) -> 4022
A16: =IF(Frota!$A16="","",Frota!$A16) -> Fiat Toro — 5001 | B16: =IF(OR(Frota!$A16="",Frota!$G16<>"Ativo",N(Frota!$L16)=0),"",ROUND(Frota!$I16+IF(B$3=1,N(Frota!$J16),N(Frota!$K16)),2)) -> 32700 | C16: =IF(B16="","",ROUND(B16+IF(C$3=1,N(Frota!$J16),N(Frota!$K16)),2)) -> 33400 | D16: =IF(C16="","",ROUND(C16+IF(D$3=1,N(Frota!$J16),N(Frota!$K16)),2)) -> 34100 | E16: =IF(D16="","",ROUND(D16+IF(E$3=1,N(Frota!$J16),N(Frota!$K16)),2)) -> 34800 | F16: =IF(E16="","",ROUND(E16+IF(F$3=1,N(Frota!$J16),N(Frota!$K16)),2)) -> 35500 | G16: =IF(F16="","",ROUND(F16+IF(G$3=1,N(Frota!$J16),N(Frota!$K16)),2)) -> 36200 | H16: =IF(G16="","",ROUND(G16+IF(H$3=1,N(Frota!$J16),N(Frota!$K16)),2)) -> 36900 | I16: =IF(H16="","",ROUND(H16+IF(I$3=1,N(Frota!$J16),N(Frota!$K16)),2)) -> 37600 | J16: =IF(I16="","",ROUND(I16+IF(J$3=1,N(Frota!$J16),N(Frota!$K16)),2)) -> 38300 | ... BA16: =IF(AZ16="","",ROUND(AZ16+IF(BA$3=1,N(Frota!$J16),N(Frota!$K16)),2)) -> 63300
... A34: =IF(Frota!$A34="","",Frota!$A34) | B34: =IF(OR(Frota!$A34="",Frota!$G34<>"Ativo",N(Frota!$L34)=0),"",ROUND(Frota!$I34+IF(B$3=1,N(Frota!$J34),N(Frota!$K34)),2)) | C34: =IF(B34="","",ROUND(B34+IF(C$3=1,N(Frota!$J34),N(Frota!$K34)),2)) | D34: =IF(C34="","",ROUND(C34+IF(D$3=1,N(Frota!$J34),N(Frota!$K34)),2)) | E34: =IF(D34="","",ROUND(D34+IF(E$3=1,N(Frota!$J34),N(Frota!$K34)),2)) | F34: =IF(E34="","",ROUND(E34+IF(F$3=1,N(Frota!$J34),N(Frota!$K34)),2)) | G34: =IF(F34="","",ROUND(F34+IF(G$3=1,N(Frota!$J34),N(Frota!$K34)),2)) | H34: =IF(G34="","",ROUND(G34+IF(H$3=1,N(Frota!$J34),N(Frota!$K34)),2)) | I34: =IF(H34="","",ROUND(H34+IF(I$3=1,N(Frota!$J34),N(Frota!$K34)),2)) | J34: =IF(I34="","",ROUND(I34+IF(J$3=1,N(Frota!$J34),N(Frota!$K34)),2)) | ... BA34: =IF(AZ34="","",ROUND(AZ34+IF(BA$3=1,N(Frota!$J34),N(Frota!$K34)),2))

Sheet Cronograma
A1: CRONOGRAMA — grade Ativo × 52 Semanas (tipo de preventiva disparada; herança cumulativa aplicada no HH)
A2: S = verde · A = amarelo · B = vermelho (cores Fabio). Semana com fundo escuro no cabeçalho = safra. Gerado automaticamente do uso acumulado × gatilhos.
A4: Ativo | B4: S01 | C4: S02 | D4: S03 | E4: S04 | F4: S05 | G4: S06 | H4: S07 | I4: S08 | J4: S09 | K4: S10 | L4: S11 | M4: S12 | N4: S13 | O4: S14 | P4: S15 | Q4: S16 | R4: S17 | S4: S18 | T4: S19 | U4: S20 | V4: S21 | W4: S22 | X4: S23 | Y4: S24 | Z4: S25 | AA4: S26 | AB4: S27 | AC4: S28 | AD4: S29 | AE4: S30 | AF4: S31 | AG4: S32 | AH4: S33 | AI4: S34 | AJ4: S35 | AK4: S36 | AL4: S37 | AM4: S38 | AN4: S39 | AO4: S40 | AP4: S41 | AQ4: S42 | AR4: S43 | AS4: S44 | AT4: S45 | AU4: S46 | AV4: S47 | AW4: S48 | AX4: S49 | AY4: S50 | AZ4: S51 | BA4: S52
A5: =IF(Frota!$A5="","",Frota!$A5) -> Colhedora CASE A8810 — 1035 | B5: =IF(Cron_Uso!B5="","",IF(INT(Cron_Uso!B5/Frota!$L5)>INT(Frota!$I5/Frota!$L5),IF(N(VLOOKUP(Frota!$B5,Premissas!$A$39:$E$43,5,0))>0,IF(MOD(INT(Cron_Uso!B5/Frota!$L5)*Frota!$L5,N(VLOOKUP(Frota!$B5,Premissas!$A$39:$E$43,5,0)))=0,"B",IF(N(VLOOKUP(Frota!$B5,Premissas!$A$39:$E$43,4,0))>0,IF(MOD(INT(Cron_Uso!B5/Frota!$L5)*Frota!$L5,N(VLOOKUP(Frota!$B5,Premissas!$A$39:$E$43,4,0)))=0,"A","S"),"S")),IF(N(VLOOKUP(Frota!$B5,Premissas!$A$39:$E$43,4,0))>0,IF(MOD(INT(Cron_Uso!B5/Frota!$L5)*Frota!$L5,N(VLOOKUP(Frota!$B5,Premissas!$A$39:$E$43,4,0)))=0,"A","S"),"S")),"")) | C5: =IF(Cron_Uso!C5="","",IF(INT(Cron_Uso!C5/Frota!$L5)>INT(Cron_Uso!B5/Frota!$L5),IF(N(VLOOKUP(Frota!$B5,Premissas!$A$39:$E$43,5,0))>0,IF(MOD(INT(Cron_Uso!C5/Frota!$L5)*Frota!$L5,N(VLOOKUP(Frota!$B5,Premissas!$A$39:$E$43,5,0)))=0,"B",IF(N(VLOOKUP(Frota!$B5,Premissas!$A$39:$E$43,4,0))>0,IF(MOD(INT(Cron_Uso!C5/Frota!$L5)*Frota!$L5,N(VLOOKUP(Frota!$B5,Premissas!$A$39:$E$43,4,0)))=0,"A","S"),"S")),IF(N(VLOOKUP(Frota!$B5,Premissas!$A$39:$E$43,4,0))>0,IF(MOD(INT(Cron_Uso!C5/Frota!$L5)*Frota!$L5,N(VLOOKUP(Frota!$B5,Premissas!$A$39:$E$43,4,0)))=0,"A","S"),"S")),"")) | D5: =IF(Cron_Uso!D5="","",IF(INT(Cron_Uso!D5/Frota!$L5)>INT(Cron_Uso!C5/Frota!$L5),IF(N(VLOOKUP(Frota!$B5,Premissas!$A$39:$E$43,5,0))>0,IF(MOD(INT(Cron_Uso!D5/Frota!$L5)*Frota!$L5,N(VLOOKUP(Frota!$B5,Premissas!$A$39:$E$43,5,0)))=0,"B",IF(N(VLOOKUP(Frota!$B5,Premissas!$A$39:$E$43,4,0))>0,IF(MOD(INT(Cron_Uso!D5/Frota!$L5)*Frota!$L5,N(VLOOKUP(Frota!$B5,Premissas!$A$39:$E$43,4,0)))=0,"A","S"),"S")),IF(N(VLOOKUP(Frota!$B5,Premissas!$A$39:$E$43,4,0))>0,IF(MOD(INT(Cron_Uso!D5/Frota!$L5)*Frota!$L5,N(VLOOKUP(Frota!$B5,Premissas!$A$39:$E$43,4,0)))=0,"A","S"),"S")),"")) | E5: =IF(Cron_Uso!E5="","",IF(INT(Cron_Uso!E5/Frota!$L5)>INT(Cron_Uso!D5/Frota!$L5),IF(N(VLOOKUP(Frota!$B5,Premissas!$A$39:$E$43,5,0))>0,IF(MOD(INT(Cron_Uso!E5/Frota!$L5)*Frota!$L5,N(VLOOKUP(Frota!$B5,Premissas!$A$39:$E$43,5,0)))=0,"B",IF(N(VLOOKUP(Frota!$B5,Premissas!$A$39:$E$43,4,0))>0,IF(MOD(INT(Cron_Uso!E5/Frota!$L5)*Frota!$L5,N(VLOOKUP(Frota!$B5,Premissas!$A$39:$E$43,4,0)))=0,"A","S"),"S")),IF(N(VLOOKUP(Frota!$B5,Premissas!$A$39:$E$43,4,0))>0,IF(MOD(INT(Cron_Uso!E5/Frota!$L5)*Frota!$L5,N(VLOOKUP(Frota!$B5,Premissas!$A$39:$E$43,4,0)))=0,"A","S"),"S")),"")) | F5: =IF(Cron_Uso!F5="","",IF(INT(Cron_Uso!F5/Frota!$L5)>INT(Cron_Uso!E5/Frota!$L5),IF(N(VLOOKUP(Frota!$B5,Premissas!$A$39:$E$43,5,0))>0,IF(MOD(INT(Cron_Uso!F5/Frota!$L5)*Frota!$L5,N(VLOOKUP(Frota!$B5,Premissas!$A$39:$E$43,5,0)))=0,"B",IF(N(VLOOKUP(Frota!$B5,Premissas!$A$39:$E$43,4,0))>0,IF(MOD(INT(Cron_Uso!F5/Frota!$L5)*Frota!$L5,N(VLOOKUP(Frota!$B5,Premissas!$A$39:$E$43,4,0)))=0,"A","S"),"S")),IF(N(VLOOKUP(Frota!$B5,Premissas!$A$39:$E$43,4,0))>0,IF(MOD(INT(Cron_Uso!F5/Frota!$L5)*Frota!$L5,N(VLOOKUP(Frota!$B5,Premissas!$A$39:$E$43,4,0)))=0,"A","S"),"S")),"")) -> B | G5: =IF(Cron_Uso!G5="","",IF(INT(Cron_Uso!G5/Frota!$L5)>INT(Cron_Uso!F5/Frota!$L5),IF(N(VLOOKUP(Frota!$B5,Premissas!$A$39:$E$43,5,0))>0,IF(MOD(INT(Cron_Uso!G5/Frota!$L5)*Frota!$L5,N(VLOOKUP(Frota!$B5,Premissas!$A$39:$E$43,5,0)))=0,"B",IF(N(VLOOKUP(Frota!$B5,Premissas!$A$39:$E$43,4,0))>0,IF(MOD(INT(Cron_Uso!G5/Frota!$L5)*Frota!$L5,N(VLOOKUP(Frota!$B5,Premissas!$A$39:$E$43,4,0)))=0,"A","S"),"S")),IF(N(VLOOKUP(Frota!$B5,Premissas!$A$39:$E$43,4,0))>0,IF(MOD(INT(Cron_Uso!G5/Frota!$L5)*Frota!$L5,N(VLOOKUP(Frota!$B5,Premissas!$A$39:$E$43,4,0)))=0,"A","S"),"S")),"")) | H5: =IF(Cron_Uso!H5="","",IF(INT(Cron_Uso!H5/Frota!$L5)>INT(Cron_Uso!G5/Frota!$L5),IF(N(VLOOKUP(Frota!$B5,Premissas!$A$39:$E$43,5,0))>0,IF(MOD(INT(Cron_Uso!H5/Frota!$L5)*Frota!$L5,N(VLOOKUP(Frota!$B5,Premissas!$A$39:$E$43,5,0)))=0,"B",IF(N(VLOOKUP(Frota!$B5,Premissas!$A$39:$E$43,4,0))>0,IF(MOD(INT(Cron_Uso!H5/Frota!$L5)*Frota!$L5,N(VLOOKUP(Frota!$B5,Premissas!$A$39:$E$43,4,0)))=0,"A","S"),"S")),IF(N(VLOOKUP(Frota!$B5,Premissas!$A$39:$E$43,4,0))>0,IF(MOD(INT(Cron_Uso!H5/Frota!$L5)*Frota!$L5,N(VLOOKUP(Frota!$B5,Premissas!$A$39:$E$43,4,0)))=0,"A","S"),"S")),"")) | I5: =IF(Cron_Uso!I5="","",IF(INT(Cron_Uso!I5/Frota!$L5)>INT(Cron_Uso!H5/Frota!$L5),IF(N(VLOOKUP(Frota!$B5,Premissas!$A$39:$E$43,5,0))>0,IF(MOD(INT(Cron_Uso!I5/Frota!$L5)*Frota!$L5,N(VLOOKUP(Frota!$B5,Premissas!$A$39:$E$43,5,0)))=0,"B",IF(N(VLOOKUP(Frota!$B5,Premissas!$A$39:$E$43,4,0))>0,IF(MOD(INT(Cron_Uso!I5/Frota!$L5)*Frota!$L5,N(VLOOKUP(Frota!$B5,Premissas!$A$39:$E$43,4,0)))=0,"A","S"),"S")),IF(N(VLOOKUP(Frota!$B5,Premissas!$A$39:$E$43,4,0))>0,IF(MOD(INT(Cron_Uso!I5/Frota!$L5)*Frota!$L5,N(VLOOKUP(Frota!$B5,Premissas!$A$39:$E$43,4,0)))=0,"A","S"),"S")),"")) | J5: =IF(Cron_Uso!J5="","",IF(INT(Cron_Uso!J5/Frota!$L5)>INT(Cron_Uso!I5/Frota!$L5),IF(N(VLOOKUP(Frota!$B5,Premissas!$A$39:$E$43,5,0))>0,IF(MOD(INT(Cron_Uso!J5/Frota!$L5)*Frota!$L5,N(VLOOKUP(Frota!$B5,Premissas!$A$39:$E$43,5,0)))=0,"B",IF(N(VLOOKUP(Frota!$B5,Premissas!$A$39:$E$43,4,0))>0,IF(MOD(INT(Cron_Uso!J5/Frota!$L5)*Frota!$L5,N(VLOOKUP(Frota!$B5,Premissas!$A$39:$E$43,4,0)))=0,"A","S"),"S")),IF(N(VLOOKUP(Frota!$B5,Premissas!$A$39:$E$43,4,0))>0,IF(MOD(INT(Cron_Uso!J5/Frota!$L5)*Frota!$L5,N(VLOOKUP(Frota!$B5,Premissas!$A$39:$E$43,4,0)))=0,"A","S"),"S")),"")) | ... BA5: =IF(Cron_Uso!BA5="","",IF(INT(Cron_Uso!BA5/Frota!$L5)>INT(Cron_Uso!AZ5/Frota!$L5),IF(N(VLOOKUP(Frota!$B5,Premissas!$A$39:$E$43,5,0))>0,IF(MOD(INT(Cron_Uso!BA5/Frota!$L5)*Frota!$L5,N(VLOOKUP(Frota!$B5,Premissas!$A$39:$E$43,5,0)))=0,"B",IF(N(VLOOKUP(Frota!$B5,Premissas!$A$39:$E$43,4,0))>0,IF(MOD(INT(Cron_Uso!BA5/Frota!$L5)*Frota!$L5,N(VLOOKUP(Frota!$B5,Premissas!$A$39:$E$43,4,0)))=0,"A","S"),"S")),IF(N(VLOOKUP(Frota!$B5,Premissas!$A$39:$E$43,4,0))>0,IF(MOD(INT(Cron_Uso!BA5/Frota!$L5)*Frota!$L5,N(VLOOKUP(Frota!$B5,Premissas!$A$39:$E$43,4,0)))=0,"A","S"),"S")),""))
A6: =IF(Frota!$A6="","",Frota!$A6) -> Colhedora CASE A8810 — 1036 | B6: =IF(Cron_Uso!B6="","",IF(INT(Cron_Uso!B6/Frota!$L6)>INT(Frota!$I6/Frota!$L6),IF(N(VLOOKUP(Frota!$B6,Premissas!$A$39:$E$43,5,0))>0,IF(MOD(INT(Cron_Uso!B6/Frota!$L6)*Frota!$L6,N(VLOOKUP(Frota!$B6,Premissas!$A$39:$E$43,5,0)))=0,"B",IF(N(VLOOKUP(Frota!$B6,Premissas!$A$39:$E$43,4,0))>0,IF(MOD(INT(Cron_Uso!B6/Frota!$L6)*Frota!$L6,N(VLOOKUP(Frota!$B6,Premissas!$A$39:$E$43,4,0)))=0,"A","S"),"S")),IF(N(VLOOKUP(Frota!$B6,Premissas!$A$39:$E$43,4,0))>0,IF(MOD(INT(Cron_Uso!B6/Frota!$L6)*Frota!$L6,N(VLOOKUP(Frota!$B6,Premissas!$A$39:$E$43,4,0)))=0,"A","S"),"S")),"")) -> A | C6: =IF(Cron_Uso!C6="","",IF(INT(Cron_Uso!C6/Frota!$L6)>INT(Cron_Uso!B6/Frota!$L6),IF(N(VLOOKUP(Frota!$B6,Premissas!$A$39:$E$43,5,0))>0,IF(MOD(INT(Cron_Uso!C6/Frota!$L6)*Frota!$L6,N(VLOOKUP(Frota!$B6,Premissas!$A$39:$E$43,5,0)))=0,"B",IF(N(VLOOKUP(Frota!$B6,Premissas!$A$39:$E$43,4,0))>0,IF(MOD(INT(Cron_Uso!C6/Frota!$L6)*Frota!$L6,N(VLOOKUP(Frota!$B6,Premissas!$A$39:$E$43,4,0)))=0,"A","S"),"S")),IF(N(VLOOKUP(Frota!$B6,Premissas!$A$39:$E$43,4,0))>0,IF(MOD(INT(Cron_Uso!C6/Frota!$L6)*Frota!$L6,N(VLOOKUP(Frota!$B6,Premissas!$A$39:$E$43,4,0)))=0,"A","S"),"S")),"")) | D6: =IF(Cron_Uso!D6="","",IF(INT(Cron_Uso!D6/Frota!$L6)>INT(Cron_Uso!C6/Frota!$L6),IF(N(VLOOKUP(Frota!$B6,Premissas!$A$39:$E$43,5,0))>0,IF(MOD(INT(Cron_Uso!D6/Frota!$L6)*Frota!$L6,N(VLOOKUP(Frota!$B6,Premissas!$A$39:$E$43,5,0)))=0,"B",IF(N(VLOOKUP(Frota!$B6,Premissas!$A$39:$E$43,4,0))>0,IF(MOD(INT(Cron_Uso!D6/Frota!$L6)*Frota!$L6,N(VLOOKUP(Frota!$B6,Premissas!$A$39:$E$43,4,0)))=0,"A","S"),"S")),IF(N(VLOOKUP(Frota!$B6,Premissas!$A$39:$E$43,4,0))>0,IF(MOD(INT(Cron_Uso!D6/Frota!$L6)*Frota!$L6,N(VLOOKUP(Frota!$B6,Premissas!$A$39:$E$43,4,0)))=0,"A","S"),"S")),"")) | E6: =IF(Cron_Uso!E6="","",IF(INT(Cron_Uso!E6/Frota!$L6)>INT(Cron_Uso!D6/Frota!$L6),IF(N(VLOOKUP(Frota!$B6,Premissas!$A$39:$E$43,5,0))>0,IF(MOD(INT(Cron_Uso!E6/Frota!$L6)*Frota!$L6,N(VLOOKUP(Frota!$B6,Premissas!$A$39:$E$43,5,0)))=0,"B",IF(N(VLOOKUP(Frota!$B6,Premissas!$A$39:$E$43,4,0))>0,IF(MOD(INT(Cron_Uso!E6/Frota!$L6)*Frota!$L6,N(VLOOKUP(Frota!$B6,Premissas!$A$39:$E$43,4,0)))=0,"A","S"),"S")),IF(N(VLOOKUP(Frota!$B6,Premissas!$A$39:$E$43,4,0))>0,IF(MOD(INT(Cron_Uso!E6/Frota!$L6)*Frota!$L6,N(VLOOKUP(Frota!$B6,Premissas!$A$39:$E$43,4,0)))=0,"A","S"),"S")),"")) | F6: =IF(Cron_Uso!F6="","",IF(INT(Cron_Uso!F6/Frota!$L6)>INT(Cron_Uso!E6/Frota!$L6),IF(N(VLOOKUP(Frota!$B6,Premissas!$A$39:$E$43,5,0))>0,IF(MOD(INT(Cron_Uso!F6/Frota!$L6)*Frota!$L6,N(VLOOKUP(Frota!$B6,Premissas!$A$39:$E$43,5,0)))=0,"B",IF(N(VLOOKUP(Frota!$B6,Premissas!$A$39:$E$43,4,0))>0,IF(MOD(INT(Cron_Uso!F6/Frota!$L6)*Frota!$L6,N(VLOOKUP(Frota!$B6,Premissas!$A$39:$E$43,4,0)))=0,"A","S"),"S")),IF(N(VLOOKUP(Frota!$B6,Premissas!$A$39:$E$43,4,0))>0,IF(MOD(INT(Cron_Uso!F6/Frota!$L6)*Frota!$L6,N(VLOOKUP(Frota!$B6,Premissas!$A$39:$E$43,4,0)))=0,"A","S"),"S")),"")) | G6: =IF(Cron_Uso!G6="","",IF(INT(Cron_Uso!G6/Frota!$L6)>INT(Cron_Uso!F6/Frota!$L6),IF(N(VLOOKUP(Frota!$B6,Premissas!$A$39:$E$43,5,0))>0,IF(MOD(INT(Cron_Uso!G6/Frota!$L6)*Frota!$L6,N(VLOOKUP(Frota!$B6,Premissas!$A$39:$E$43,5,0)))=0,"B",IF(N(VLOOKUP(Frota!$B6,Premissas!$A$39:$E$43,4,0))>0,IF(MOD(INT(Cron_Uso!G6/Frota!$L6)*Frota!$L6,N(VLOOKUP(Frota!$B6,Premissas!$A$39:$E$43,4,0)))=0,"A","S"),"S")),IF(N(VLOOKUP(Frota!$B6,Premissas!$A$39:$E$43,4,0))>0,IF(MOD(INT(Cron_Uso!G6/Frota!$L6)*Frota!$L6,N(VLOOKUP(Frota!$B6,Premissas!$A$39:$E$43,4,0)))=0,"A","S"),"S")),"")) -> S | H6: =IF(Cron_Uso!H6="","",IF(INT(Cron_Uso!H6/Frota!$L6)>INT(Cron_Uso!G6/Frota!$L6),IF(N(VLOOKUP(Frota!$B6,Premissas!$A$39:$E$43,5,0))>0,IF(MOD(INT(Cron_Uso!H6/Frota!$L6)*Frota!$L6,N(VLOOKUP(Frota!$B6,Premissas!$A$39:$E$43,5,0)))=0,"B",IF(N(VLOOKUP(Frota!$B6,Premissas!$A$39:$E$43,4,0))>0,IF(MOD(INT(Cron_Uso!H6/Frota!$L6)*Frota!$L6,N(VLOOKUP(Frota!$B6,Premissas!$A$39:$E$43,4,0)))=0,"A","S"),"S")),IF(N(VLOOKUP(Frota!$B6,Premissas!$A$39:$E$43,4,0))>0,IF(MOD(INT(Cron_Uso!H6/Frota!$L6)*Frota!$L6,N(VLOOKUP(Frota!$B6,Premissas!$A$39:$E$43,4,0)))=0,"A","S"),"S")),"")) | I6: =IF(Cron_Uso!I6="","",IF(INT(Cron_Uso!I6/Frota!$L6)>INT(Cron_Uso!H6/Frota!$L6),IF(N(VLOOKUP(Frota!$B6,Premissas!$A$39:$E$43,5,0))>0,IF(MOD(INT(Cron_Uso!I6/Frota!$L6)*Frota!$L6,N(VLOOKUP(Frota!$B6,Premissas!$A$39:$E$43,5,0)))=0,"B",IF(N(VLOOKUP(Frota!$B6,Premissas!$A$39:$E$43,4,0))>0,IF(MOD(INT(Cron_Uso!I6/Frota!$L6)*Frota!$L6,N(VLOOKUP(Frota!$B6,Premissas!$A$39:$E$43,4,0)))=0,"A","S"),"S")),IF(N(VLOOKUP(Frota!$B6,Premissas!$A$39:$E$43,4,0))>0,IF(MOD(INT(Cron_Uso!I6/Frota!$L6)*Frota!$L6,N(VLOOKUP(Frota!$B6,Premissas!$A$39:$E$43,4,0)))=0,"A","S"),"S")),"")) | J6: =IF(Cron_Uso!J6="","",IF(INT(Cron_Uso!J6/Frota!$L6)>INT(Cron_Uso!I6/Frota!$L6),IF(N(VLOOKUP(Frota!$B6,Premissas!$A$39:$E$43,5,0))>0,IF(MOD(INT(Cron_Uso!J6/Frota!$L6)*Frota!$L6,N(VLOOKUP(Frota!$B6,Premissas!$A$39:$E$43,5,0)))=0,"B",IF(N(VLOOKUP(Frota!$B6,Premissas!$A$39:$E$43,4,0))>0,IF(MOD(INT(Cron_Uso!J6/Frota!$L6)*Frota!$L6,N(VLOOKUP(Frota!$B6,Premissas!$A$39:$E$43,4,0)))=0,"A","S"),"S")),IF(N(VLOOKUP(Frota!$B6,Premissas!$A$39:$E$43,4,0))>0,IF(MOD(INT(Cron_Uso!J6/Frota!$L6)*Frota!$L6,N(VLOOKUP(Frota!$B6,Premissas!$A$39:$E$43,4,0)))=0,"A","S"),"S")),"")) | ... BA6: =IF(Cron_Uso!BA6="","",IF(INT(Cron_Uso!BA6/Frota!$L6)>INT(Cron_Uso!AZ6/Frota!$L6),IF(N(VLOOKUP(Frota!$B6,Premissas!$A$39:$E$43,5,0))>0,IF(MOD(INT(Cron_Uso!BA6/Frota!$L6)*Frota!$L6,N(VLOOKUP(Frota!$B6,Premissas!$A$39:$E$43,5,0)))=0,"B",IF(N(VLOOKUP(Frota!$B6,Premissas!$A$39:$E$43,4,0))>0,IF(MOD(INT(Cron_Uso!BA6/Frota!$L6)*Frota!$L6,N(VLOOKUP(Frota!$B6,Premissas!$A$39:$E$43,4,0)))=0,"A","S"),"S")),IF(N(VLOOKUP(Frota!$B6,Premissas!$A$39:$E$43,4,0))>0,IF(MOD(INT(Cron_Uso!BA6/Frota!$L6)*Frota!$L6,N(VLOOKUP(Frota!$B6,Premissas!$A$39:$E$43,4,0)))=0,"A","S"),"S")),""))
A7: =IF(Frota!$A7="","",Frota!$A7) -> Colhedora JD CH570 — 1027 | B7: =IF(Cron_Uso!B7="","",IF(INT(Cron_Uso!B7/Frota!$L7)>INT(Frota!$I7/Frota!$L7),IF(N(VLOOKUP(Frota!$B7,Premissas!$A$39:$E$43,5,0))>0,IF(MOD(INT(Cron_Uso!B7/Frota!$L7)*Frota!$L7,N(VLOOKUP(Frota!$B7,Premissas!$A$39:$E$43,5,0)))=0,"B",IF(N(VLOOKUP(Frota!$B7,Premissas!$A$39:$E$43,4,0))>0,IF(MOD(INT(Cron_Uso!B7/Frota!$L7)*Frota!$L7,N(VLOOKUP(Frota!$B7,Premissas!$A$39:$E$43,4,0)))=0,"A","S"),"S")),IF(N(VLOOKUP(Frota!$B7,Premissas!$A$39:$E$43,4,0))>0,IF(MOD(INT(Cron_Uso!B7/Frota!$L7)*Frota!$L7,N(VLOOKUP(Frota!$B7,Premissas!$A$39:$E$43,4,0)))=0,"A","S"),"S")),"")) | C7: =IF(Cron_Uso!C7="","",IF(INT(Cron_Uso!C7/Frota!$L7)>INT(Cron_Uso!B7/Frota!$L7),IF(N(VLOOKUP(Frota!$B7,Premissas!$A$39:$E$43,5,0))>0,IF(MOD(INT(Cron_Uso!C7/Frota!$L7)*Frota!$L7,N(VLOOKUP(Frota!$B7,Premissas!$A$39:$E$43,5,0)))=0,"B",IF(N(VLOOKUP(Frota!$B7,Premissas!$A$39:$E$43,4,0))>0,IF(MOD(INT(Cron_Uso!C7/Frota!$L7)*Frota!$L7,N(VLOOKUP(Frota!$B7,Premissas!$A$39:$E$43,4,0)))=0,"A","S"),"S")),IF(N(VLOOKUP(Frota!$B7,Premissas!$A$39:$E$43,4,0))>0,IF(MOD(INT(Cron_Uso!C7/Frota!$L7)*Frota!$L7,N(VLOOKUP(Frota!$B7,Premissas!$A$39:$E$43,4,0)))=0,"A","S"),"S")),"")) | D7: =IF(Cron_Uso!D7="","",IF(INT(Cron_Uso!D7/Frota!$L7)>INT(Cron_Uso!C7/Frota!$L7),IF(N(VLOOKUP(Frota!$B7,Premissas!$A$39:$E$43,5,0))>0,IF(MOD(INT(Cron_Uso!D7/Frota!$L7)*Frota!$L7,N(VLOOKUP(Frota!$B7,Premissas!$A$39:$E$43,5,0)))=0,"B",IF(N(VLOOKUP(Frota!$B7,Premissas!$A$39:$E$43,4,0))>0,IF(MOD(INT(Cron_Uso!D7/Frota!$L7)*Frota!$L7,N(VLOOKUP(Frota!$B7,Premissas!$A$39:$E$43,4,0)))=0,"A","S"),"S")),IF(N(VLOOKUP(Frota!$B7,Premissas!$A$39:$E$43,4,0))>0,IF(MOD(INT(Cron_Uso!D7/Frota!$L7)*Frota!$L7,N(VLOOKUP(Frota!$B7,Premissas!$A$39:$E$43,4,0)))=0,"A","S"),"S")),"")) | E7: =IF(Cron_Uso!E7="","",IF(INT(Cron_Uso!E7/Frota!$L7)>INT(Cron_Uso!D7/Frota!$L7),IF(N(VLOOKUP(Frota!$B7,Premissas!$A$39:$E$43,5,0))>0,IF(MOD(INT(Cron_Uso!E7/Frota!$L7)*Frota!$L7,N(VLOOKUP(Frota!$B7,Premissas!$A$39:$E$43,5,0)))=0,"B",IF(N(VLOOKUP(Frota!$B7,Premissas!$A$39:$E$43,4,0))>0,IF(MOD(INT(Cron_Uso!E7/Frota!$L7)*Frota!$L7,N(VLOOKUP(Frota!$B7,Premissas!$A$39:$E$43,4,0)))=0,"A","S"),"S")),IF(N(VLOOKUP(Frota!$B7,Premissas!$A$39:$E$43,4,0))>0,IF(MOD(INT(Cron_Uso!E7/Frota!$L7)*Frota!$L7,N(VLOOKUP(Frota!$B7,Premissas!$A$39:$E$43,4,0)))=0,"A","S"),"S")),"")) -> B | F7: =IF(Cron_Uso!F7="","",IF(INT(Cron_Uso!F7/Frota!$L7)>INT(Cron_Uso!E7/Frota!$L7),IF(N(VLOOKUP(Frota!$B7,Premissas!$A$39:$E$43,5,0))>0,IF(MOD(INT(Cron_Uso!F7/Frota!$L7)*Frota!$L7,N(VLOOKUP(Frota!$B7,Premissas!$A$39:$E$43,5,0)))=0,"B",IF(N(VLOOKUP(Frota!$B7,Premissas!$A$39:$E$43,4,0))>0,IF(MOD(INT(Cron_Uso!F7/Frota!$L7)*Frota!$L7,N(VLOOKUP(Frota!$B7,Premissas!$A$39:$E$43,4,0)))=0,"A","S"),"S")),IF(N(VLOOKUP(Frota!$B7,Premissas!$A$39:$E$43,4,0))>0,IF(MOD(INT(Cron_Uso!F7/Frota!$L7)*Frota!$L7,N(VLOOKUP(Frota!$B7,Premissas!$A$39:$E$43,4,0)))=0,"A","S"),"S")),"")) | G7: =IF(Cron_Uso!G7="","",IF(INT(Cron_Uso!G7/Frota!$L7)>INT(Cron_Uso!F7/Frota!$L7),IF(N(VLOOKUP(Frota!$B7,Premissas!$A$39:$E$43,5,0))>0,IF(MOD(INT(Cron_Uso!G7/Frota!$L7)*Frota!$L7,N(VLOOKUP(Frota!$B7,Premissas!$A$39:$E$43,5,0)))=0,"B",IF(N(VLOOKUP(Frota!$B7,Premissas!$A$39:$E$43,4,0))>0,IF(MOD(INT(Cron_Uso!G7/Frota!$L7)*Frota!$L7,N(VLOOKUP(Frota!$B7,Premissas!$A$39:$E$43,4,0)))=0,"A","S"),"S")),IF(N(VLOOKUP(Frota!$B7,Premissas!$A$39:$E$43,4,0))>0,IF(MOD(INT(Cron_Uso!G7/Frota!$L7)*Frota!$L7,N(VLOOKUP(Frota!$B7,Premissas!$A$39:$E$43,4,0)))=0,"A","S"),"S")),"")) | H7: =IF(Cron_Uso!H7="","",IF(INT(Cron_Uso!H7/Frota!$L7)>INT(Cron_Uso!G7/Frota!$L7),IF(N(VLOOKUP(Frota!$B7,Premissas!$A$39:$E$43,5,0))>0,IF(MOD(INT(Cron_Uso!H7/Frota!$L7)*Frota!$L7,N(VLOOKUP(Frota!$B7,Premissas!$A$39:$E$43,5,0)))=0,"B",IF(N(VLOOKUP(Frota!$B7,Premissas!$A$39:$E$43,4,0))>0,IF(MOD(INT(Cron_Uso!H7/Frota!$L7)*Frota!$L7,N(VLOOKUP(Frota!$B7,Premissas!$A$39:$E$43,4,0)))=0,"A","S"),"S")),IF(N(VLOOKUP(Frota!$B7,Premissas!$A$39:$E$43,4,0))>0,IF(MOD(INT(Cron_Uso!H7/Frota!$L7)*Frota!$L7,N(VLOOKUP(Frota!$B7,Premissas!$A$39:$E$43,4,0)))=0,"A","S"),"S")),"")) | I7: =IF(Cron_Uso!I7="","",IF(INT(Cron_Uso!I7/Frota!$L7)>INT(Cron_Uso!H7/Frota!$L7),IF(N(VLOOKUP(Frota!$B7,Premissas!$A$39:$E$43,5,0))>0,IF(MOD(INT(Cron_Uso!I7/Frota!$L7)*Frota!$L7,N(VLOOKUP(Frota!$B7,Premissas!$A$39:$E$43,5,0)))=0,"B",IF(N(VLOOKUP(Frota!$B7,Premissas!$A$39:$E$43,4,0))>0,IF(MOD(INT(Cron_Uso!I7/Frota!$L7)*Frota!$L7,N(VLOOKUP(Frota!$B7,Premissas!$A$39:$E$43,4,0)))=0,"A","S"),"S")),IF(N(VLOOKUP(Frota!$B7,Premissas!$A$39:$E$43,4,0))>0,IF(MOD(INT(Cron_Uso!I7/Frota!$L7)*Frota!$L7,N(VLOOKUP(Frota!$B7,Premissas!$A$39:$E$43,4,0)))=0,"A","S"),"S")),"")) | J7: =IF(Cron_Uso!J7="","",IF(INT(Cron_Uso!J7/Frota!$L7)>INT(Cron_Uso!I7/Frota!$L7),IF(N(VLOOKUP(Frota!$B7,Premissas!$A$39:$E$43,5,0))>0,IF(MOD(INT(Cron_Uso!J7/Frota!$L7)*Frota!$L7,N(VLOOKUP(Frota!$B7,Premissas!$A$39:$E$43,5,0)))=0,"B",IF(N(VLOOKUP(Frota!$B7,Premissas!$A$39:$E$43,4,0))>0,IF(MOD(INT(Cron_Uso!J7/Frota!$L7)*Frota!$L7,N(VLOOKUP(Frota!$B7,Premissas!$A$39:$E$43,4,0)))=0,"A","S"),"S")),IF(N(VLOOKUP(Frota!$B7,Premissas!$A$39:$E$43,4,0))>0,IF(MOD(INT(Cron_Uso!J7/Frota!$L7)*Frota!$L7,N(VLOOKUP(Frota!$B7,Premissas!$A$39:$E$43,4,0)))=0,"A","S"),"S")),"")) | ... BA7: =IF(Cron_Uso!BA7="","",IF(INT(Cron_Uso!BA7/Frota!$L7)>INT(Cron_Uso!AZ7/Frota!$L7),IF(N(VLOOKUP(Frota!$B7,Premissas!$A$39:$E$43,5,0))>0,IF(MOD(INT(Cron_Uso!BA7/Frota!$L7)*Frota!$L7,N(VLOOKUP(Frota!$B7,Premissas!$A$39:$E$43,5,0)))=0,"B",IF(N(VLOOKUP(Frota!$B7,Premissas!$A$39:$E$43,4,0))>0,IF(MOD(INT(Cron_Uso!BA7/Frota!$L7)*Frota!$L7,N(VLOOKUP(Frota!$B7,Premissas!$A$39:$E$43,4,0)))=0,"A","S"),"S")),IF(N(VLOOKUP(Frota!$B7,Premissas!$A$39:$E$43,4,0))>0,IF(MOD(INT(Cron_Uso!BA7/Frota!$L7)*Frota!$L7,N(VLOOKUP(Frota!$B7,Premissas!$A$39:$E$43,4,0)))=0,"A","S"),"S")),""))
